Workbook
Name APT_CONTR: '06. APONTAMENTO DIÁRIO'!$D$5:$D$504
Name APT_DATA: '06. APONTAMENTO DIÁRIO'!$A$5:$A$504
Name APT_EQUIPE: '06. APONTAMENTO DIÁRIO'!$E$5:$E$504
Name APT_HH: '06. APONTAMENTO DIÁRIO'!$I$5:$I$504
Name APT_KM: '06. APONTAMENTO DIÁRIO'!$P$5:$P$504
Name APT_PARADA: '06. APONTAMENTO DIÁRIO'!$AA$5:$AA$504
Name APT_PESSOAS: '06. APONTAMENTO DIÁRIO'!$F$5:$F$504
Name APT_RETRO: '06. APONTAMENTO DIÁRIO'!$J$5:$J$504
Name ATA_CONTR: '15. ATAS DE REUNIÃO'!$E$5:$E$204
Name ATA_DATA: '15. ATAS DE REUNIÃO'!$B$5:$B$304
Name ATA_NUM: '15. ATAS DE REUNIÃO'!$A$5:$A$304
Name ATA_PEND: '15. ATAS DE REUNIÃO'!$L$5:$L$304
Name ATA_PRAZO: '15. ATAS DE REUNIÃO'!$N$5:$N$304
Name ATA_PRIO: '15. ATAS DE REUNIÃO'!$O$5:$O$304
Name ATA_RESP: '15. ATAS DE REUNIÃO'!$M$5:$M$304
Name ATA_STATUS: '15. ATAS DE REUNIÃO'!$P$5:$P$304
Name ATA_TIPO: '15. ATAS DE REUNIÃO'!$D$5:$D$204
Name BEN_PESSOA: '01A. BANCO DE CUSTOS'!$C$35
Name CAD_BAIRRO: '03. CADASTRO DE SERVIÇOS'!$K$5:$K$604
Name CAD_CONTR: '03. CADASTRO DE SERVIÇOS'!$B$5:$B$604
Name CAD_DTEXEC: '03. CADASTRO DE SERVIÇOS'!$R$5:$R$604
Name CAD_DTSOL: '03. CADASTRO DE SERVIÇOS'!$D$5:$D$604
Name CAD_ID: '03. CADASTRO DE SERVIÇOS'!$A$5:$A$604
Name CAD_SITPZ: '03. CADASTRO DE SERVIÇOS'!$U$5:$U$604
Name CAD_STATUS: '03. CADASTRO DE SERVIÇOS'!$S$5:$S$604
Name CAD_TAB: '03. CADASTRO DE SERVIÇOS'!$A$5:$X$604
Name CAD_TIPO: '03. CADASTRO DE SERVIÇOS'!$H$5:$H$604
Name CAD_VLR: '03. CADASTRO DE SERVIÇOS'!$V$5:$V$604
Name ENC_FATOR: '01A. BANCO DE CUSTOS'!$C$34
Name EQP_ATIVO: '08. EQUIPE'!$U$5:$U$60
Name EQP_CONTR: '08. EQUIPE'!$B$5:$B$60
Name EQP_CUSTOMES: '08. EQUIPE'!$J$5:$J$60
Name EQP_EQUIPE: '08. EQUIPE'!$C$5:$C$60
Name EQP_NOMES: '08. EQUIPE'!$D$5:$D$60
Name FAT_BRUTO: '12. FATURAMENTO'!$C$5:$C$52
Name FAT_CONTR: '12. FATURAMENTO'!$B$5:$B$52
Name FAT_MES: '12. FATURAMENTO'!$A$5:$A$52
Name FAT_RESULT: '12. FATURAMENTO'!$R$5:$R$52
Name LK_ID: '16. LOOKAHEAD E RESTRIÇÕES'!$C$5:$C$404
Name LK_PEND: '16. LOOKAHEAD E RESTRIÇÕES'!$M$5:$M$404
Name LK_SEM: '16. LOOKAHEAD E RESTRIÇÕES'!$A$5:$A$404
Name LK_SIT: '16. LOOKAHEAD E RESTRIÇÕES'!$N$5:$N$404
Name LST_BAIRRO: '01. CONFIGURAÇÕES'!$M$44:$M$85
Name LST_CAUSA_NC: '01. CONFIGURAÇÕES'!$Z$44:$Z$70
Name LST_CLIMA: '01. CONFIGURAÇÕES'!$T$44:$T$60
Name LST_CONTRATO: '01. CONFIGURAÇÕES'!$A$44:$A$57
Name LST_DIA: '01. CONFIGURAÇÕES'!$Y$44:$Y$61
Name LST_EQUIPAMENTO: '01. CONFIGURAÇÕES'!$O$44:$O$69
Name LST_EQUIPE: '01. CONFIGURAÇÕES'!$B$44:$B$65
Name LST_FUNCAO: '01. CONFIGURAÇÕES'!$N$44:$N$68
Name LST_GRAVIDADE: '01. CONFIGURAÇÕES'!$W$44:$W$59
Name LST_MATERIAL: '01. CONFIGURAÇÕES'!$P$44:$P$84
Name LST_MOTIVO_NE: '01. CONFIGURAÇÕES'!$J$44:$J$70
Name LST_MOTIVO_PARADA: '01. CONFIGURAÇÕES'!$K$44:$K$65
Name LST_MOVIMENTO: '01. CONFIGURAÇÕES'!$Q$44:$Q$60
Name LST_PAVIMENTO: '01. CONFIGURAÇÕES'!$L$44:$L$62
Name LST_PRIORIDADE: '01. CONFIGURAÇÕES'!$C$44:$C$59
Name LST_RESTRICAO: '01. CONFIGURAÇÕES'!$AA$44:$AA$70
Name LST_SN: '01. CONFIGURAÇÕES'!$R$44:$R$57
Name LST_SNP: '01. CONFIGURAÇÕES'!$S$44:$S$59

Sheet GUIA RÁPIDO
B1: GUIA RÁPIDO — COMO PREENCHER CADA ABA
B2: A esteira: 03 CADASTRO > 04 PROGRAMAÇÃO > 05 ORDENS DE SERVIÇO > 09 MEDIÇÃO > 12 FATURAMENTO. O resto é apoio e registro.
B4: 00. LEIA-ME
B5: Aqui não se digita NADA. É só leitura.
B6: É o manual do arquivo.
B7: Esqueceu como preenche alguma aba?
B8: Lê a caixa amarela no canto de cada aba.
B10: 01. CONFIGURAÇÕES
B11: Mexe uma vez, no começo. Não é do dia a dia.
B12: C5 a C11 = nomes: empresa, responsável, os 2 contratos
B13: C12 = dia em que a operação começou
B14: C13 = mês que você quer ver nos relatórios
... B305: K da aba 04 nunca foi preenchida.

Sheet 00. LEIA-ME
A1: CONTROLE OPERACIONAL E FINANCEIRO — CONTRATO GLOBAL SABESP · WCR SANEAMENTO | H1: COMO PREENCHER ESTA ABA
A2: Bertioga / Guarujá e Santos · versão 2.0 · setembro de 2026 · leia o bloco A e o bloco C — o resto é consulta | H2: Aqui não se digita NADA. É só leitura.
H3: É o manual do arquivo.
B4: A · COMECE POR AQUI — EM UM MINUTO | H4: Esqueceu como preenche alguma aba?
B5: O que é isto | C5: Um controle que liga o chamado da SABESP ao dinheiro na conta. Uma linha por serviço, do cadastro até a nota fiscal paga. Nada é digitado duas vezes: o ID amarra tudo. | H5: Lê a caixa amarela no canto de cada aba.
B6: O que você digita | C6: Só o AZUL e os filtros AMARELOS. São 8 abas de digitação (03 a 12) e 3 de implantação (01, 01A, 01B). As outras se calculam sozinhas.
B7: O que ela faz sozinha | C7: ID do serviço, data-limite, status, aderência, homem-hora, custo da equipe, valor da OS, medição, imposto, previsão de recebimento, resultado, margem e todos os gráficos.
B8: A rota mínima do dia | C8: 03 CADASTRO → 04 PROGRAMAÇÃO → (campo) → 06 APONTAMENTO → 05 ORDENS DE SERVIÇO → 09 MEDIÇÃO. Fazendo só isso, o resumo, o faturamento e o dashboard aparecem prontos.
B9: A única regra | C9: Não digite em cima de célula PRETA ou VERDE e não apague linha. Fórmula apagada não volta sozinha — e ninguém percebe até o fechamento.
B11: B · CONVENÇÃO DE CORES — VALE PARA A PLANILHA INTEIRA
B12: AZUL | C12: Você digita. É campo de entrada.
B13: PRETO | C13: Fórmula da própria aba. Não apague.
B14: VERDE | C14: Vem de outra aba pelo ID. Não digite por cima.
B15: AMARELO | C15: Filtro ou parâmetro. Muda o que a aba mostra ou calcula.
B16: Na dúvida | C16: Clique na célula e olhe a barra de fórmulas. Se começar com "=", ela não é sua.
B18: C · MAPA DE PREENCHIMENTO — COLUNA POR COLUNA, ABA POR ABA
B19: ABA | C19: O QUE VOCÊ DIGITA — SÓ AS CÉLULAS AZUIS | D19: O QUE APARECE SOZINHO | E19: QUEM · QUANDO
B20: 01. CONFIGURAÇÕES | C20: C5 a C13 nomes, contratos e datas · C17 desconto do consórcio · C18 dia de fechamento · C19 defasagem do recebimento · C20 dias úteis · C21 jornada · C22 prazo padrão SABESP · C23 alerta de prazo · C33 margem-alvo | D20: Todas as listas suspensas que o sistema inteiro usa (contrato, equipe, tipo, bairro, pavimento, motivo, material, função). | E20: Gestão · implantação e reajuste
B21: 01A. BANCO DE CUSTOS | C21: Quantidade e valor unitário de cada item de estrutura (engenheiro, kits, carros, caminhões, alojamento, indiretos) e a fonte de cada um. | D21: Custo mensal por contrato, que vira a meta diária de cada equipe na aba 06. | E21: Gestão · implantação e reajuste
B22: 01B. CARTEIRA E TICKET | C22: Coluna E: o CÓD. PREÇO de cada tipo de serviço. Nada mais. | D22: Mix contado na aba 03, descrição e preço da aba 02, ticket apurado da carteira. | E22: Programação · uma vez, ao confirmar os códigos
B23: 02. TABELA DE PREÇOS | C23: Só a busca amarela no alto da aba. Digite uma palavra e a coluna BUSCA marca os itens. | D23: Os 511 itens contratuais das duas cidades. Aba de consulta. | E23: Ninguém edita
B24: 03. CADASTRO DE SERVIÇOS | C24: B contrato · C nº da OS SABESP · D data da solicitação · E prazo · G prioridade · H tipo de serviço · I a N endereço, nº, bairro, cidade, referência e pavimento · O descrição · W tratativa · X observação | D24: A ID (nasce ao escolher o contrato) · F data-limite · P equipe · Q data programada · R data de execução · S status · T dias em aberto · U situação do prazo · V valor medido | E24: Programador · diário, até as 10h
B25: 04. PROGRAMAÇÃO DIÁRIA | C25: A data · C equipe · D sequência · E ID do serviço · K horas previstas. Na volta do campo: L executou? · M data de execução · N motivo da não execução · O reprogramar para · R observação | D25: B contrato · F tipo · G endereço · H bairro · I prioridade · J data-limite · P status do item · Q aderência | E25: Programador 16h · Encarregado fim do turno
B26: 05. ORDENS DE SERVIÇO | C26: A ID do serviço · G equipe · H encarregado · I início · J conclusão · L profundidade · M extensão · N pavimento reposto · O foto antes · P foto depois · Q nº do RDO · V pendência | D26: B a F contrato, nº da OS, endereço, bairro e tipo · K dias · R nº de itens medidos · S valor da OS · T mês de medição · U status da OS | E26: Apontador · no dia da conclusão
B27: 06. APONTAMENTO DIÁRIO | C27: A data · D contrato · E equipe · F nº de pessoas · G e H horas normais e extras · J a O horas de retro, munck, caminhão HR, compressor, rompedor e bomba · P km · Z status do dia · AA motivo de parada · AB observação | D27: I homem-hora · Q e R serviços programados e executados · S aderência · T valor produzido · U meta do dia · V atingimento · W custo da equipe · X resultado · Y R$ por HH | E27: Encarregado · até as 8h do dia seguinte
B28: 07. MATERIAIS | C28: A data · B contrato · C movimento · D ID do serviço · E material · F unidade · G quantidade · J custo unitário · L responsável · M fornecedor · N NF · O material da SABESP? · P observação | D28: H entrada · I saída · K custo total · e o saldo por material no quadro ao lado. | E28: Almoxarife · a cada movimento
B29: 08. EQUIPE | C29: A matrícula · B contrato · C equipe · D nome · E função · F admissão · G salário · M a S validades de ASO, NR-06, NR-10, NR-18, NR-33, NR-35 e CNH · U ativo? | D29: H encargos · I benefícios · J, K e L custo por mês, por dia e por hora · T alerta de vencimento (vermelho vencido, amarelo a 30 dias) | E29: Administrativo + Segurança · admissão e reciclagem
B30: 09. MEDIÇÃO | C30: A nº do boletim · C ID do serviço · H CÓD. PREÇO · K quantidade · N status · O data de apresentação · P valor glosado · Q motivo da glosa · S reapresentar? · T observação | D30: B mês · D a G contrato, nº da OS, equipe e data · I descrição · J unidade · L preço unitário · M valor · R valor aprovado | E30: Técnico de medição · semanal
... B34: 13. RESUMO e 14. DASHBOARD | C34: Nada. São abas de leitura. | D34: KPIs do mês, série mensal, ranking de equipes, Pareto de motivos e os gráficos do contrato. | E34: Gestão · leitura
B36: D · AS QUATRO ABAS DE PARTIDA — VOCÊ MEXE UMA VEZ E VALE PARA O CONTRATO INTEIRO
B37: Estas quatro não são do dia a dia: são a base que faz todas as outras calcularem certo. Errou aqui, erra em tudo — e em silêncio.
B38: 01. CONFIGURAÇÕES — o painel de partida: quem é o contrato, com que regras ele corre e quais palavras a planilha aceita
B39: O que é | C39: Três coisas em uma aba: a identificação dos dois contratos (bloco A), os parâmetros que regem prazo, medição e caixa (bloco B), e as listas padronizadas (bloco D) que abastecem TODAS as caixas de seleção do arquivo.
B40: O que ela decide | C40: Dia de fechamento + defasagem = a data prevista de recebimento na aba 12. Prazo padrão SABESP = a data-limite e o alerta VENCIDO na aba 03. Dias úteis e jornada = o custo por dia e por hora na aba 08 e a meta diária na aba 06. Desconto do consórcio = o valor líquido na aba 12.
B41: O bloco C não se digita | C41: Custo mensal e ticket aparecem em verde: vêm das abas 01A e 01B. Digitar por cima quebra a rastreabilidade — é justamente o que essa versão tirou da planilha.
B42: Onde se erra | C42: Equipe, bairro, material, função ou motivo que não estiver na lista do bloco D simplesmente não aparece na caixa de seleção das outras abas. Para incluir, escreva na PRIMEIRA linha vazia da lista — a faixa nomeada já tem folga reservada.
B43: Quando mexer | C43: Na implantação; quando entra equipe, bairro ou material novo; e em reajuste de contrato.
B44: 01A. BANCO DE CUSTOS — a memória de cálculo do custo mensal — de onde sai a meta de cada equipe
B45: O que é | C45: O custo do contrato desmontado item a item: engenheiro, kits de equipe, carros, caminhões, alojamento e indiretos, cada linha com quantidade, valor unitário e a fonte declarada. Mais três blocos de base: encargos (58% sobre o salário), benefícios por pessoa e tributos sobre a medição (22%).
B46: O que ela decide | C46: O total desta aba é o custo mensal que aparece na aba 01, e é ele que gera a META R$ DO DIA de cada equipe na aba 06 e o CUSTO DO MÊS na aba 12 — ou seja, a margem do contrato sai daqui.
...

Sheet 01. CONFIGURAÇÕES
A1: CONFIGURAÇÕES — PARÂMETROS E LISTAS PADRONIZADAS | AB1: COMO PREENCHER ESTA ABA
A2: Painel de partida do contrato: identificação (A), os parâmetros que regem prazo, medição e caixa (B), e as listas que alimentam TODAS as caixas de seleção do arquivo (D). O bloco C não se digita — custo vem da aba 01A e ticket da 01B. Item novo em lista: escreva na PRIMEIRA linha vazia. AZUL = você edita · PRETO e VERDE = não edite. | AB2: Mexe uma vez, no começo. Não é do dia a dia.
AB3: C5 a C11 = nomes: empresa, responsável, os 2 contratos
A4: A · IDENTIFICAÇÃO | AB4: C12 = dia em que a operação começou
B5: Empresa executante | C5: WCR SANEAMENTO | AB5: C13 = mês que você quer ver nos relatórios
B6: Responsável pelo contrato | C6: Felipe Nery | AB6: C17 = % que o consórcio desconta (0 se não desconta)
B7: Coordenador de operações | C7: Ícaro Atila | AB7: C18 = dia que fecha a medição (30)
B8: Contrato 1 — nome curto | C8: BERTIOGA | AB8: C19 = dias que a SABESP demora pra pagar (20)
B9: Contrato 1 — descrição | C9: Manutenção Global GJ B — Bertioga / Guarujá (Consórcio) | AB9: C20 = dias úteis no mês (22)
B10: Contrato 2 — nome curto | C10: SANTOS | AB10: C21 = horas por dia (8,8)
B11: Contrato 2 — descrição | C11: Manutenção Global SA — Santos (Consórcio Global SA) | AB11: C22 = prazo padrão da SABESP em dias (5)
B12: Início da operação | C12: 46265 | AB12: C23 = dias antes de acender o alerta (2)
B13: Mês de referência atual | C13: 46266 | AB13: C33 e D33 = margem que você quer ganhar (0,20 = 20%)
AB14: Da linha 44 pra baixo = as listas dos menus.
A15: B · PARÂMETROS FINANCEIROS E DE MEDIÇÃO | AB15: Item novo: escreve na 1a linha vazia da coluna.
B16: Imposto sobre a nota (%) | C16: ='01A. BANCO DE CUSTOS'!$C$47 -> 0.22 | D16: Fórmula — vem da aba 01A, bloco D, tributo a tributo. | AB16: Só o que está AZUL é seu. Preto e verde é fórmula.
B17: Desconto do consórcio (%) | C17: 0 | D17: Se o consórcio retiver percentual da medição. 0 = não retém.
B18: Dia de fechamento da medição | C18: 30 | D18: Último dia do mês. Depois desta data o serviço entra no mês seguinte.
B19: Defasagem de recebimento (dias) | C19: 20 | D19: Da data de fechamento até o crédito em conta.
B20: Dias úteis por mês | C20: 22 | D20: Base do custo/dia e das metas diárias.
B21: Jornada normal (h/dia) | C21: 8.8 | D21: Base do cálculo de produtividade R$/hh.
B22: Prazo padrão SABESP (dias) | C22: 5 | D22: Usado quando o prazo não vem informado na solicitação.
B23: Alerta de prazo — dias antes | C23: 2 | D23: A partir de quantos dias do vencimento o serviço fica AMARELO.
B24: Nº de equipes — BERTIOGA | C24: =SUMPRODUCT((COUNTIFS(EQP_CONTR,"BERTIOGA",EQP_ATIVO,"SIM",EQP_EQUIPE,{"BER-A";"BER-B";"BER-C";"BER-D"})>0)*1) -> 4 | D24: Fórmula — conta quantas equipes têm pelo menos uma pessoa ativa na aba 08.
B25: Nº de equipes — SANTOS | C25: =SUMPRODUCT((COUNTIFS(EQP_CONTR,"SANTOS",EQP_ATIVO,"SIM",EQP_EQUIPE,{"SAN-A";"SAN-B";"SAN-C";"SAN-D"})>0)*1) -> 4 | D25: Fórmula — conta quantas equipes têm pelo menos uma pessoa ativa na aba 08.
A27: C · CUSTOS E METAS POR CONTRATO (custos vindos de FLUXO_CAIXA_PROJETADO_BERTIOGA_SANTOS_v4)
B28: PARÂMETRO | C28: BERTIOGA | D28: SANTOS | E28: UN | F28: OBSERVAÇÃO
B29: Custo mensal total do contrato | C29: ='01A. BANCO DE CUSTOS'!$E$16 -> 230982.81 | D29: ='01A. BANCO DE CUSTOS'!$E$30 -> 273163.84 | E29: R$/mês | F29: Fórmula — vem da aba 01A, item a item (estrutura + quadro nominal ativo da aba 08).
B30: Custo por dia útil | C30: =C29/$C$20 -> 10499.219 | D30: =D29/$C$20 -> 12416.538 | E30: R$/dia | F30: Fórmula: custo mensal ÷ dias úteis.
B31: Custo por equipe por dia | C31: =C30/$C$24 -> 2624.8047 | D31: =D30/$C$25 -> 3104.1345 | E31: R$/dia | F31: Fórmula: custo/dia ÷ nº de equipes.
B32: Ticket médio por serviço | C32: ='01B. CARTEIRA E TICKET'!$H$34 -> 317.49648 | D32: ='01B. CARTEIRA E TICKET'!$H$66 -> 1338.83 | E32: R$/serviço | F32: Fórmula — vem da aba 01B, apurado do mix real da carteira ou, na falta dos códigos, do ticket de referência do fluxo de caixa.
B33: Margem-alvo do cenário adotado | C33: 0.2 | D33: 0.2 | E33: % | F33: Cenário ÓTIMA do fluxo de caixa (aba PREMISSAS). É decisão comercial — por isso continua azul.
B34: Meta de medição bruta no mês | C34: =C29*(1+C33)/(1-$C$16) -> 355358.17 | D34: =D29*(1+D33)/(1-$C$16) -> 420252.06 | E34: R$/mês | F34: Fórmula: custo × (1+margem) ÷ (1−imposto).
B35: Meta de serviços no mês | C35: =C34/C32 -> 1119.2507 | D35: =D34/D32 -> 313.89501 | E35: serv./mês | F35: Fórmula: meta R$ ÷ ticket médio.
B36: Meta de serviços por dia útil | C36: =C35/$C$20 -> 50.875033 | D36: =D35/$C$20 -> 14.267955 | E36: serv./dia | F36: Base: dias ÚTEIS (22). No fluxo de caixa a base é 30 dias corridos — por isso lá aparece 13,8 e 10,3.
B37: Meta de serviços por equipe/dia | C37: =C36/$C$24 -> 12.718758 | D37: =D36/$C$25 -> 3.5669888 | E37: serv./dia | F37: É a meta que o encarregado cobra em campo.
B38: Meta de R$ por equipe/dia | C38: =C34/$C$20/$C$24 -> 4038.161 | D38: =D34/$C$20/$C$25 -> 4775.5916 | E38: R$/dia | F38: É a meta que a gestão cobra na reunião semanal.
B39: Produção mínima de equilíbrio (serv./dia) | C39: =C29/(1-$C$16)/C32/$C$20 -> 42.395861 | D39: =D29/(1-$C$16)/D32/$C$20 -> 11.889963 | E39: serv./dia | F39: Abaixo disso o contrato dá prejuízo.
A41: D · LISTAS PADRONIZADAS (alimentam todas as caixas de seleção — acrescente na primeira linha vazia)
A43: CONTRATO | B43: EQUIPE | C43: PRIORIDADE | D43: TIPO | E43: STATUS_CAD | F43: STATUS_PROG | G43: STATUS_OS | H43: STATUS_MED | I43: STATUS_FAT | J43: MOTIVO_NE | K43: MOTIVO_PARADA | L43: PAVIMENTO | M43: BAIRRO | N43: FUNCAO | O43: EQUIPAMENTO | P43: MATERIAL | Q43: MOVIMENTO | R43: SN | S43: SNP | T43: CLIMA | U43: SOLO | V43: TIPO_OCOR | W43: GRAVIDADE | X43: STATUS_OC | Y43: DIA | Z43: CAUSA_NC | AA43: RESTRICAO
...

Sheet 01A. BANCO DE CUSTOS
A1: BANCO DE CUSTOS, ENCARGOS E TRIBUTOS — ITEM A ITEM | K1: COMO PREENCHER ESTA ABA
A2: É daqui que sai o custo mensal de cada contrato — e, por consequência, a meta diária de cada equipe (aba 06) e a margem (aba 12). Cada linha tem quantidade, valor unitário e fonte declarada. A folha não é digitada: vem somada da aba 08, pessoa a pessoa. Nada é digitado na aba 01 — o total daqui é que alimenta o bloco C de lá. AZUL = quantidade e preço contratados · VERDE = vem da aba 08. | K2: Daqui sai o custo do mês e a meta de cada equipe.
K3: Mexe só quando o preço de verdade mudar.
A4: CUSTO MENSAL — BERTIOGA | K4: C = quantos você tem (2 caminhões, escreve 2)
B5: ITEM | C5: QTD | D5: VALOR UNIT. | E5: TOTAL / MÊS | F5: FONTE | K5: D = quanto custa CADA UM por mês
B6: Engenheiro residente | C6: 1 | D6: 13000 | E6: =C6*D6 -> 13000 | F6: Salário + encargos — praticado pela WCR nos dois contratos | K6: F = de onde saiu o preço (contrato, cotação, aluguel)
B7: Kit de ferramentas por equipe | C7: 4 | D7: 7200 | E7: =C7*D7 -> 28800 | F7: Locação mensal — 1 kit por equipe | K7: C34 = fator de encargos sobre o salário (0,58)
B8: Carro do engenheiro | C8: 1 | D8: 3400 | E8: =C8*D8 -> 3400 | F8: Locação mensal | K8: C35 = benefícios por pessoa por mês
B9: Carro do encarregado | C9: 1 | D9: 3500 | E9: =C9*D9 -> 3500 | F9: Locação mensal | K9: C40 a C46 = as alíquotas dos impostos
B10: Caminhão 3/4 com munck | C10: 1 | D10: 25000 | E10: =C10*D10 -> 25000 | F10: Locação mensal com operador | K10: Linha 15 e 29 (folha) NÃO se digita:
B11: Caminhão tipo HR | C11: 3 | D11: 6500 | E11: =C11*D11 -> 19500 | F11: Locação mensal — 1 por equipe de campo | K11: vem somada da aba 08. EQUIPE, pessoa por pessoa.
B12: Alojamento | C12: 1 | D12: 13500 | E12: =C12*D12 -> 13500 | F12: Casa da equipe em Bertioga
B13: Equipamentos leves | C13: 1 | D13: 12900 | E13: =C13*D13 -> 12900 | F13: Compressor, rompedor, bombas, geofone, serra e sinalização
B14: Custos indiretos | C14: 1 | D14: 20000 | E14: =C14*D14 -> 20000 | F14: Administração de contrato, contabilidade, seguros, EPI e telefonia
B15: Equipe de campo — folha, encargos e benefícios | C15: =COUNTIFS(EQP_CONTR,"BERTIOGA",EQP_ATIVO,"SIM") -> 14 | D15: =IF(C15=0,0,E15/C15) -> 6527.3436 | E15: =SUMIFS(EQP_CUSTOMES,EQP_CONTR,"BERTIOGA",EQP_ATIVO,"SIM") -> 91382.81 | F15: Soma do quadro nominal ativo da aba 08. EQUIPE — salário + encargos + benefícios, pessoa a pessoa.
B16: TOTAL MENSAL — BERTIOGA | E16: =SUM(E6:E15) -> 230982.81 | F16: Fluxo Trimestral Obra · FLUXO_CAIXA_PROJETADO_BERTIOGA_SANTOS_v4 — abas CUSTOS BERTIOGA e CUSTOS SANTOS
A18: CUSTO MENSAL — SANTOS
B19: ITEM | C19: QTD | D19: VALOR UNIT. | E19: TOTAL / MÊS | F19: FONTE
B20: Engenheiro residente | C20: 1 | D20: 13000 | E20: =C20*D20 -> 13000 | F20: Salário + encargos — praticado pela WCR nos dois contratos
B21: Kit de ferramentas por equipe | C21: 4 | D21: 7200 | E21: =C21*D21 -> 28800 | F21: Locação mensal — 1 kit por equipe
B22: Carro do engenheiro | C22: 1 | D22: 3400 | E22: =C22*D22 -> 3400 | F22: Locação mensal
B23: Carro do encarregado | C23: 1 | D23: 3400 | E23: =C23*D23 -> 3400 | F23: Locação mensal
B24: Caminhão 3/4 com munck | C24: 2 | D24: 25000 | E24: =C24*D24 -> 50000 | F24: Locação mensal com operador
B25: Caminhão tipo HR | C25: 2 | D25: 6000 | E25: =C25*D25 -> 12000 | F25: Locação mensal
B26: Alojamento | C26: 1 | D26: 6000 | E26: =C26*D26 -> 6000 | F26: Casa da equipe em Santos
B27: Equipamentos leves | C27: 1 | D27: 12900 | E27: =C27*D27 -> 12900 | F27: Compressor, rompedor, bombas, geofone, serra e sinalização
B28: Custos indiretos | C28: 1 | D28: 20000 | E28: =C28*D28 -> 20000 | F28: Administração de contrato, contabilidade, seguros, EPI e telefonia
B29: Equipe de campo — folha, encargos e benefícios | C29: =COUNTIFS(EQP_CONTR,"SANTOS",EQP_ATIVO,"SIM") -> 16 | D29: =IF(C29=0,0,E29/C29) -> 7728.99 | E29: =SUMIFS(EQP_CUSTOMES,EQP_CONTR,"SANTOS",EQP_ATIVO,"SIM") -> 123663.84 | F29: Soma do quadro nominal ativo da aba 08. EQUIPE — salário + encargos + benefícios, pessoa a pessoa.
B30: TOTAL MENSAL — SANTOS | E30: =SUM(E20:E29) -> 273163.84 | F30: Fluxo Trimestral Obra · FLUXO_CAIXA_PROJETADO_BERTIOGA_SANTOS_v4 — abas CUSTOS BERTIOGA e CUSTOS SANTOS
A32: C · ENCARGOS E BENEFÍCIOS — BASE DA FOLHA
B33: PARÂMETRO | C33: VALOR | D33: UN | E33: MEMÓRIA DE CÁLCULO | F33: FONTE
B34: Fator de encargos sobre o salário | C34: 0.58 | D34: % | E34: INSS patronal, RAT, FGTS, 13º, férias + 1/3, rescisão e repouso. Apurado da própria folha: encargos ÷ salário dá 58,0% para todos os 31 colaboradores das duas cidades. | F34: Folha real — CUSTOS BERTIOGA e CUSTOS SANTOS do FLUXO_CAIXA v4
B35: Benefícios por pessoa | C35: 1904.32 | D35: R$/mês | E35: Vale-refeição + vale-alimentação + vale-transporte. Valor único na folha das duas cidades. | F35: Folha real — CUSTOS BERTIOGA e CUSTOS SANTOS do FLUXO_CAIXA v4
B36: Conferência — folha original das duas cidades | C36: 226754.32 | D36: R$/mês | E36: =IF(ABS(C36-(SUMIFS(EQP_CUSTOMES,EQP_ATIVO,"SIM")))<50,"Confere — diferença só de arredondamento por pessoa","⚠ divergência: revise o fator de encargos") -> ⚠ divergência: revise o fator de encargos | F36: Soma de folha + encargos + benefícios das 31 pessoas, como estava no fluxo de caixa
A38: D · TRIBUTOS SOBRE A MEDIÇÃO — Lucro Presumido, serviço
B39: TRIBUTO | C39: ALÍQUOTA | D39: UN | E39: MEMÓRIA DE CÁLCULO | F39: FONTE
B40: PIS | C40: 0.0065 | D40: % | E40: Regime cumulativo do Lucro Presumido | F40: Lei 9.718/98
B41: COFINS | C41: 0.03 | D41: % | E41: Regime cumulativo do Lucro Presumido | F41: Lei 9.718/98
B42: IRPJ | C42: 0.048 | D42: % | E42: 15% sobre a presunção de 32% para serviço | F42: RIR/2018
B43: Adicional de IRPJ | C43: 0.01 | D43: % | E43: 10% sobre o excedente de R$ 20 mil/mês — provisão | F43: RIR/2018
...

Sheet 01B. CARTEIRA E TICKET
A1: CARTEIRA E TICKET MÉDIO — DE ONDE SAI O R$ POR SERVIÇO | L1: COMO PREENCHER ESTA ABA
A2: O mix não é chutado: cada linha conta, na aba 03, quantos serviços daquele tipo existem hoje. Você preenche só a coluna E — o CÓD. PREÇO que representa o tipo — e o ticket passa a ser apurado da tabela do contrato em vez de herdado do fluxo de caixa. O código tem que ser do mesmo contrato da linha: Bertioga não tem SUPR nem RELIG. Tipo sem item equivalente no contrato fica sem preço, e é para ficar mesmo. | L2: Só a coluna E é sua. O resto é fórmula.
L3: E = o CÓD. PREÇO daquele tipo de serviço
A4: MIX DA CARTEIRA — BERTIOGA | L4: exemplo: BER-72000053
B5: TIPO DE SERVIÇO | C5: Nº NA CARTEIRA | D5: % DO MIX | E5: CÓD. PREÇO (CHAVE) | F5: DESCRIÇÃO DO ITEM | G5: PREÇO UNIT. | H5: CONTRIBUIÇÃO | I5: MEMÓRIA DE CÁLCULO | L5: Pega o código na aba 02. TABELA DE PREÇOS.
B6: Vazamento de água não visível — rede | C6: =COUNTIFS(CAD_TIPO,$B6,CAD_CONTR,"BERTIOGA") -> 8 | D6: =IF(COUNTIFS(CAD_CONTR,"BERTIOGA")=0,"",C6/COUNTIFS(CAD_CONTR,"BERTIOGA")) -> 0.14814815 | E6: BER-72000053 | F6: =IFERROR(IF($E6="","",VLOOKUP($E6,PRE_TAB,5,FALSE)),"CÓDIGO NÃO ENCONTRADO") -> LAG ATE 32MM TA AVUL S/REP SF | G6: =IFERROR(IF($E6="","",VLOOKUP($E6,PRE_TAB,8,FALSE)),"") -> 787.5 | H6: =IF(OR($D6="",$G6=""),0,$D6*$G6) -> 116.66667 | I6: nº deste tipo ÷ total do contrato, na aba 03 · preço do item na aba 02 | L6: O código tem que ser do MESMO contrato da linha:
B7: Vazamento de água não visível — ramal | C7: =COUNTIFS(CAD_TIPO,$B7,CAD_CONTR,"BERTIOGA") -> 5 | D7: =IF(COUNTIFS(CAD_CONTR,"BERTIOGA")=0,"",C7/COUNTIFS(CAD_CONTR,"BERTIOGA")) -> 0.092592593 | E7: BER-72000053 | F7: =IFERROR(IF($E7="","",VLOOKUP($E7,PRE_TAB,5,FALSE)),"CÓDIGO NÃO ENCONTRADO") -> LAG ATE 32MM TA AVUL S/REP SF | G7: =IFERROR(IF($E7="","",VLOOKUP($E7,PRE_TAB,8,FALSE)),"") -> 787.5 | H7: =IF(OR($D7="",$G7=""),0,$D7*$G7) -> 72.916667 | I7: nº deste tipo ÷ total do contrato, na aba 03 · preço do item na aba 02 | L7: BER- com BER-, SAN- com SAN-.
B8: Vazamento de água visível — rede | C8: =COUNTIFS(CAD_TIPO,$B8,CAD_CONTR,"BERTIOGA") -> 0 | D8: =IF(COUNTIFS(CAD_CONTR,"BERTIOGA")=0,"",C8/COUNTIFS(CAD_CONTR,"BERTIOGA")) -> 0 | F8: =IFERROR(IF($E8="","",VLOOKUP($E8,PRE_TAB,5,FALSE)),"CÓDIGO NÃO ENCONTRADO") | G8: =IFERROR(IF($E8="","",VLOOKUP($E8,PRE_TAB,8,FALSE)),"") | H8: =IF(OR($D8="",$G8=""),0,$D8*$G8) -> 0 | I8: nº deste tipo ÷ total do contrato, na aba 03 · preço do item na aba 02 | L8: Tipo que não existe no contrato fica sem preço mesmo.
B9: Vazamento de água visível — ramal | C9: =COUNTIFS(CAD_TIPO,$B9,CAD_CONTR,"BERTIOGA") -> 0 | D9: =IF(COUNTIFS(CAD_CONTR,"BERTIOGA")=0,"",C9/COUNTIFS(CAD_CONTR,"BERTIOGA")) -> 0 | F9: =IFERROR(IF($E9="","",VLOOKUP($E9,PRE_TAB,5,FALSE)),"CÓDIGO NÃO ENCONTRADO") | G9: =IFERROR(IF($E9="","",VLOOKUP($E9,PRE_TAB,8,FALSE)),"") | H9: =IF(OR($D9="",$G9=""),0,$D9*$G9) -> 0 | I9: nº deste tipo ÷ total do contrato, na aba 03 · preço do item na aba 02
B10: Vazamento pé do cavalete | C10: =COUNTIFS(CAD_TIPO,$B10,CAD_CONTR,"BERTIOGA") -> 7 | D10: =IF(COUNTIFS(CAD_CONTR,"BERTIOGA")=0,"",C10/COUNTIFS(CAD_CONTR,"BERTIOGA")) -> 0.12962963 | E10: BER-72000226 | F10: =IFERROR(IF($E10="","",VLOOKUP($E10,PRE_TAB,5,FALSE)),"CÓDIGO NÃO ENCONTRADO") -> TCV SF | G10: =IFERROR(IF($E10="","",VLOOKUP($E10,PRE_TAB,8,FALSE)),"") -> 301.47 | H10: =IF(OR($D10="",$G10=""),0,$D10*$G10) -> 39.079444 | I10: nº deste tipo ÷ total do contrato, na aba 03 · preço do item na aba 02
B11: Vazamento no ferrule | C11: =COUNTIFS(CAD_TIPO,$B11,CAD_CONTR,"BERTIOGA") -> 2 | D11: =IF(COUNTIFS(CAD_CONTR,"BERTIOGA")=0,"",C11/COUNTIFS(CAD_CONTR,"BERTIOGA")) -> 0.037037037 | E11: BER-72000897 | F11: =IFERROR(IF($E11="","",VLOOKUP($E11,PRE_TAB,5,FALSE)),"CÓDIGO NÃO ENCONTRADO") -> ADC SUBST TMD AG SF | G11: =IFERROR(IF($E11="","",VLOOKUP($E11,PRE_TAB,8,FALSE)),"") -> 43.3 | H11: =IF(OR($D11="",$G11=""),0,$D11*$G11) -> 1.6037037 | I11: nº deste tipo ÷ total do contrato, na aba 03 · preço do item na aba 02
B12: Troca de ramal de água | C12: =COUNTIFS(CAD_TIPO,$B12,CAD_CONTR,"BERTIOGA") -> 6 | D12: =IF(COUNTIFS(CAD_CONTR,"BERTIOGA")=0,"",C12/COUNTIFS(CAD_CONTR,"BERTIOGA")) -> 0.11111111 | E12: BER-72000044 | F12: =IFERROR(IF($E12="","",VLOOKUP($E12,PRE_TAB,5,FALSE)),"CÓDIGO NÃO ENCONTRADO") -> TRA ATE 32MM CORR TA S/REP SF | G12: =IFERROR(IF($E12="","",VLOOKUP($E12,PRE_TAB,8,FALSE)),"") -> 785.07 | H12: =IF(OR($D12="",$G12=""),0,$D12*$G12) -> 87.23 | I12: nº deste tipo ÷ total do contrato, na aba 03 · preço do item na aba 02
B13: Troca de cavalete | C13: =COUNTIFS(CAD_TIPO,$B13,CAD_CONTR,"BERTIOGA") -> 0 | D13: =IF(COUNTIFS(CAD_CONTR,"BERTIOGA")=0,"",C13/COUNTIFS(CAD_CONTR,"BERTIOGA")) -> 0 | F13: =IFERROR(IF($E13="","",VLOOKUP($E13,PRE_TAB,5,FALSE)),"CÓDIGO NÃO ENCONTRADO") | G13: =IFERROR(IF($E13="","",VLOOKUP($E13,PRE_TAB,8,FALSE)),"") | H13: =IF(OR($D13="",$G13=""),0,$D13*$G13) -> 0 | I13: nº deste tipo ÷ total do contrato, na aba 03 · preço do item na aba 02
B14: Execução de ligação de água | C14: =COUNTIFS(CAD_TIPO,$B14,CAD_CONTR,"BERTIOGA") -> 0 | D14: =IF(COUNTIFS(CAD_CONTR,"BERTIOGA")=0,"",C14/COUNTIFS(CAD_CONTR,"BERTIOGA")) -> 0 | F14: =IFERROR(IF($E14="","",VLOOKUP($E14,PRE_TAB,5,FALSE)),"CÓDIGO NÃO ENCONTRADO") | G14: =IFERROR(IF($E14="","",VLOOKUP($E14,PRE_TAB,8,FALSE)),"") | H14: =IF(OR($D14="",$G14=""),0,$D14*$G14) -> 0 | I14: nº deste tipo ÷ total do contrato, na aba 03 · preço do item na aba 02
B15: Supressão de ligação de água | C15: =COUNTIFS(CAD_TIPO,$B15,CAD_CONTR,"BERTIOGA") -> 0 | D15: =IF(COUNTIFS(CAD_CONTR,"BERTIOGA")=0,"",C15/COUNTIFS(CAD_CONTR,"BERTIOGA")) -> 0 | F15: =IFERROR(IF($E15="","",VLOOKUP($E15,PRE_TAB,5,FALSE)),"CÓDIGO NÃO ENCONTRADO") | G15: =IFERROR(IF($E15="","",VLOOKUP($E15,PRE_TAB,8,FALSE)),"") | H15: =IF(OR($D15="",$G15=""),0,$D15*$G15) -> 0 | I15: nº deste tipo ÷ total do contrato, na aba 03 · preço do item na aba 02
B16: Religação de água | C16: =COUNTIFS(CAD_TIPO,$B16,CAD_CONTR,"BERTIOGA") -> 0 | D16: =IF(COUNTIFS(CAD_CONTR,"BERTIOGA")=0,"",C16/COUNTIFS(CAD_CONTR,"BERTIOGA")) -> 0 | F16: =IFERROR(IF($E16="","",VLOOKUP($E16,PRE_TAB,5,FALSE)),"CÓDIGO NÃO ENCONTRADO") | G16: =IFERROR(IF($E16="","",VLOOKUP($E16,PRE_TAB,8,FALSE)),"") | H16: =IF(OR($D16="",$G16=""),0,$D16*$G16) -> 0 | I16: nº deste tipo ÷ total do contrato, na aba 03 · preço do item na aba 02
B17: Substituição de hidrômetro | C17: =COUNTIFS(CAD_TIPO,$B17,CAD_CONTR,"BERTIOGA") -> 0 | D17: =IF(COUNTIFS(CAD_CONTR,"BERTIOGA")=0,"",C17/COUNTIFS(CAD_CONTR,"BERTIOGA")) -> 0 | F17: =IFERROR(IF($E17="","",VLOOKUP($E17,PRE_TAB,5,FALSE)),"CÓDIGO NÃO ENCONTRADO") | G17: =IFERROR(IF($E17="","",VLOOKUP($E17,PRE_TAB,8,FALSE)),"") | H17: =IF(OR($D17="",$G17=""),0,$D17*$G17) -> 0 | I17: nº deste tipo ÷ total do contrato, na aba 03 · preço do item na aba 02
B18: Troca de registro / TMD | C18: =COUNTIFS(CAD_TIPO,$B18,CAD_CONTR,"BERTIOGA") -> 0 | D18: =IF(COUNTIFS(CAD_CONTR,"BERTIOGA")=0,"",C18/COUNTIFS(CAD_CONTR,"BERTIOGA")) -> 0 | F18: =IFERROR(IF($E18="","",VLOOKUP($E18,PRE_TAB,5,FALSE)),"CÓDIGO NÃO ENCONTRADO") | G18: =IFERROR(IF($E18="","",VLOOKUP($E18,PRE_TAB,8,FALSE)),"") | H18: =IF(OR($D18="",$G18=""),0,$D18*$G18) -> 0 | I18: nº deste tipo ÷ total do contrato, na aba 03 · preço do item na aba 02
B19: Conserto de rede de água | C19: =COUNTIFS(CAD_TIPO,$B19,CAD_CONTR,"BERTIOGA") -> 0 | D19: =IF(COUNTIFS(CAD_CONTR,"BERTIOGA")=0,"",C19/COUNTIFS(CAD_CONTR,"BERTIOGA")) -> 0 | F19: =IFERROR(IF($E19="","",VLOOKUP($E19,PRE_TAB,5,FALSE)),"CÓDIGO NÃO ENCONTRADO") | G19: =IFERROR(IF($E19="","",VLOOKUP($E19,PRE_TAB,8,FALSE)),"") | H19: =IF(OR($D19="",$G19=""),0,$D19*$G19) -> 0 | I19: nº deste tipo ÷ total do contrato, na aba 03 · preço do item na aba 02
B20: Execução de ligação de esgoto | C20: =COUNTIFS(CAD_TIPO,$B20,CAD_CONTR,"BERTIOGA") -> 0 | D20: =IF(COUNTIFS(CAD_CONTR,"BERTIOGA")=0,"",C20/COUNTIFS(CAD_CONTR,"BERTIOGA")) -> 0 | F20: =IFERROR(IF($E20="","",VLOOKUP($E20,PRE_TAB,5,FALSE)),"CÓDIGO NÃO ENCONTRADO") | G20: =IFERROR(IF($E20="","",VLOOKUP($E20,PRE_TAB,8,FALSE)),"") | H20: =IF(OR($D20="",$G20=""),0,$D20*$G20) -> 0 | I20: nº deste tipo ÷ total do contrato, na aba 03 · preço do item na aba 02
B21: Troca de ramal de esgoto | C21: =COUNTIFS(CAD_TIPO,$B21,CAD_CONTR,"BERTIOGA") -> 0 | D21: =IF(COUNTIFS(CAD_CONTR,"BERTIOGA")=0,"",C21/COUNTIFS(CAD_CONTR,"BERTIOGA")) -> 0 | F21: =IFERROR(IF($E21="","",VLOOKUP($E21,PRE_TAB,5,FALSE)),"CÓDIGO NÃO ENCONTRADO") | G21: =IFERROR(IF($E21="","",VLOOKUP($E21,PRE_TAB,8,FALSE)),"") | H21: =IF(OR($D21="",$G21=""),0,$D21*$G21) -> 0 | I21: nº deste tipo ÷ total do contrato, na aba 03 · preço do item na aba 02
B22: Desobstrução de rede de esgoto | C22: =COUNTIFS(CAD_TIPO,$B22,CAD_CONTR,"BERTIOGA") -> 0 | D22: =IF(COUNTIFS(CAD_CONTR,"BERTIOGA")=0,"",C22/COUNTIFS(CAD_CONTR,"BERTIOGA")) -> 0 | F22: =IFERROR(IF($E22="","",VLOOKUP($E22,PRE_TAB,5,FALSE)),"CÓDIGO NÃO ENCONTRADO") | G22: =IFERROR(IF($E22="","",VLOOKUP($E22,PRE_TAB,8,FALSE)),"") | H22: =IF(OR($D22="",$G22=""),0,$D22*$G22) -> 0 | I22: nº deste tipo ÷ total do contrato, na aba 03 · preço do item na aba 02
B23: Conserto de rede de esgoto | C23: =COUNTIFS(CAD_TIPO,$B23,CAD_CONTR,"BERTIOGA") -> 0 | D23: =IF(COUNTIFS(CAD_CONTR,"BERTIOGA")=0,"",C23/COUNTIFS(CAD_CONTR,"BERTIOGA")) -> 0 | F23: =IFERROR(IF($E23="","",VLOOKUP($E23,PRE_TAB,5,FALSE)),"CÓDIGO NÃO ENCONTRADO") | G23: =IFERROR(IF($E23="","",VLOOKUP($E23,PRE_TAB,8,FALSE)),"") | H23: =IF(OR($D23="",$G23=""),0,$D23*$G23) -> 0 | I23: nº deste tipo ÷ total do contrato, na aba 03 · preço do item na aba 02
B24: Construção de PI / PV | C24: =COUNTIFS(CAD_TIPO,$B24,CAD_CONTR,"BERTIOGA") -> 0 | D24: =IF(COUNTIFS(CAD_CONTR,"BERTIOGA")=0,"",C24/COUNTIFS(CAD_CONTR,"BERTIOGA")) -> 0 | F24: =IFERROR(IF($E24="","",VLOOKUP($E24,PRE_TAB,5,FALSE)),"CÓDIGO NÃO ENCONTRADO") | G24: =IFERROR(IF($E24="","",VLOOKUP($E24,PRE_TAB,8,FALSE)),"") | H24: =IF(OR($D24="",$G24=""),0,$D24*$G24) -> 0 | I24: nº deste tipo ÷ total do contrato, na aba 03 · preço do item na aba 02
... B30: Outro | C30: =COUNTIFS(CAD_TIPO,$B30,CAD_CONTR,"BERTIOGA") -> 0 | D30: =IF(COUNTIFS(CAD_CONTR,"BERTIOGA")=0,"",C30/COUNTIFS(CAD_CONTR,"BERTIOGA")) -> 0 | F30: =IFERROR(IF($E30="","",VLOOKUP($E30,PRE_TAB,5,FALSE)),"CÓDIGO NÃO ENCONTRADO") | G30: =IFERROR(IF($E30="","",VLOOKUP($E30,PRE_TAB,8,FALSE)),"") | H30: =IF(OR($D30="",$G30=""),0,$D30*$G30) -> 0 | I30: nº deste tipo ÷ total do contrato, na aba 03 · preço do item na aba 02
B31: TOTAL DA CARTEIRA | C31: =SUM(C6:C30) -> 28 | D31: =SUM(D6:D30) -> 0.51851852 | H31: =SUM(H6:H30) -> 317.49648
B32: Ticket apurado da carteira | H32: =H31 -> 317.49648 | I32: Soma das contribuições: % do mix × preço do item. Fica zero enquanto os códigos de preço não forem preenchidos.
B33: Ticket de referência | H33: 881.2 | I33: Média adotada no Fluxo Trimestral Obra — aba PREMISSAS do FLUXO_CAIXA v4
B34: TICKET ADOTADO | H34: =IF(H32>0,H32,H33) -> 317.49648 | I34: Usa o apurado assim que houver códigos preenchidos; até lá, o de referência. É este valor que alimenta a aba 01.
A36: MIX DA CARTEIRA — SANTOS
B37: TIPO DE SERVIÇO | C37: Nº NA CARTEIRA | D37: % DO MIX | E37: CÓD. PREÇO (CHAVE) | F37: DESCRIÇÃO DO ITEM | G37: PREÇO UNIT. | H37: CONTRIBUIÇÃO | I37: MEMÓRIA DE CÁLCULO
B38: Vazamento de água não visível — rede | C38: =COUNTIFS(CAD_TIPO,$B38,CAD_CONTR,"SANTOS") -> 0 | D38: =IF(COUNTIFS(CAD_CONTR,"SANTOS")=0,"",C38/COUNTIFS(CAD_CONTR,"SANTOS")) | F38: =IFERROR(IF($E38="","",VLOOKUP($E38,PRE_TAB,5,FALSE)),"CÓDIGO NÃO ENCONTRADO") | G38: =IFERROR(IF($E38="","",VLOOKUP($E38,PRE_TAB,8,FALSE)),"") | H38: =IF(OR($D38="",$G38=""),0,$D38*$G38) -> 0 | I38: nº deste tipo ÷ total do contrato, na aba 03 · preço do item na aba 02
B39: Vazamento de água não visível — ramal | C39: =COUNTIFS(CAD_TIPO,$B39,CAD_CONTR,"SANTOS") -> 0 | D39: =IF(COUNTIFS(CAD_CONTR,"SANTOS")=0,"",C39/COUNTIFS(CAD_CONTR,"SANTOS")) | F39: =IFERROR(IF($E39="","",VLOOKUP($E39,PRE_TAB,5,FALSE)),"CÓDIGO NÃO ENCONTRADO") | G39: =IFERROR(IF($E39="","",VLOOKUP($E39,PRE_TAB,8,FALSE)),"") | H39: =IF(OR($D39="",$G39=""),0,$D39*$G39) -> 0 | I39: nº deste tipo ÷ total do contrato, na aba 03 · preço do item na aba 02
B40: Vazamento de água visível — rede | C40: =COUNTIFS(CAD_TIPO,$B40,CAD_CONTR,"SANTOS") -> 0 | D40: =IF(COUNTIFS(CAD_CONTR,"SANTOS")=0,"",C40/COUNTIFS(CAD_CONTR,"SANTOS")) | F40: =IFERROR(IF($E40="","",VLOOKUP($E40,PRE_TAB,5,FALSE)),"CÓDIGO NÃO ENCONTRADO") | G40: =IFERROR(IF($E40="","",VLOOKUP($E40,PRE_TAB,8,FALSE)),"") | H40: =IF(OR($D40="",$G40=""),0,$D40*$G40) -> 0 | I40: nº deste tipo ÷ total do contrato, na aba 03 · preço do item na aba 02
B41: Vazamento de água visível — ramal | C41: =COUNTIFS(CAD_TIPO,$B41,CAD_CONTR,"SANTOS") -> 0 | D41: =IF(COUNTIFS(CAD_CONTR,"SANTOS")=0,"",C41/COUNTIFS(CAD_CONTR,"SANTOS")) | F41: =IFERROR(IF($E41="","",VLOOKUP($E41,PRE_TAB,5,FALSE)),"CÓDIGO NÃO ENCONTRADO") | G41: =IFERROR(IF($E41="","",VLOOKUP($E41,PRE_TAB,8,FALSE)),"") | H41: =IF(OR($D41="",$G41=""),0,$D41*$G41) -> 0 | I41: nº deste tipo ÷ total do contrato, na aba 03 · preço do item na aba 02
B42: Vazamento pé do cavalete | C42: =COUNTIFS(CAD_TIPO,$B42,CAD_CONTR,"SANTOS") -> 0 | D42: =IF(COUNTIFS(CAD_CONTR,"SANTOS")=0,"",C42/COUNTIFS(CAD_CONTR,"SANTOS")) | F42: =IFERROR(IF($E42="","",VLOOKUP($E42,PRE_TAB,5,FALSE)),"CÓDIGO NÃO ENCONTRADO") | G42: =IFERROR(IF($E42="","",VLOOKUP($E42,PRE_TAB,8,FALSE)),"") | H42: =IF(OR($D42="",$G42=""),0,$D42*$G42) -> 0 | I42: nº deste tipo ÷ total do contrato, na aba 03 · preço do item na aba 02
B43: Vazamento no ferrule | C43: =COUNTIFS(CAD_TIPO,$B43,CAD_CONTR,"SANTOS") -> 0 | D43: =IF(COUNTIFS(CAD_CONTR,"SANTOS")=0,"",C43/COUNTIFS(CAD_CONTR,"SANTOS")) | F43: =IFERROR(IF($E43="","",VLOOKUP($E43,PRE_TAB,5,FALSE)),"CÓDIGO NÃO ENCONTRADO") | G43: =IFERROR(IF($E43="","",VLOOKUP($E43,PRE_TAB,8,FALSE)),"") | H43: =IF(OR($D43="",$G43=""),0,$D43*$G43) -> 0 | I43: nº deste tipo ÷ total do contrato, na aba 03 · preço do item na aba 02
B44: Troca de ramal de água | C44: =COUNTIFS(CAD_TIPO,$B44,CAD_CONTR,"SANTOS") -> 0 | D44: =IF(COUNTIFS(CAD_CONTR,"SANTOS")=0,"",C44/COUNTIFS(CAD_CONTR,"SANTOS")) | F44: =IFERROR(IF($E44="","",VLOOKUP($E44,PRE_TAB,5,FALSE)),"CÓDIGO NÃO ENCONTRADO") | G44: =IFERROR(IF($E44="","",VLOOKUP($E44,PRE_TAB,8,FALSE)),"") | H44: =IF(OR($D44="",$G44=""),0,$D44*$G44) -> 0 | I44: nº deste tipo ÷ total do contrato, na aba 03 · preço do item na aba 02
B45: Troca de cavalete | C45: =COUNTIFS(CAD_TIPO,$B45,CAD_CONTR,"SANTOS") -> 0 | D45: =IF(COUNTIFS(CAD_CONTR,"SANTOS")=0,"",C45/COUNTIFS(CAD_CONTR,"SANTOS")) | F45: =IFERROR(IF($E45="","",VLOOKUP($E45,PRE_TAB,5,FALSE)),"CÓDIGO NÃO ENCONTRADO") | G45: =IFERROR(IF($E45="","",VLOOKUP($E45,PRE_TAB,8,FALSE)),"") | H45: =IF(OR($D45="",$G45=""),0,$D45*$G45) -> 0 | I45: nº deste tipo ÷ total do contrato, na aba 03 · preço do item na aba 02
B46: Execução de ligação de água | C46: =COUNTIFS(CAD_TIPO,$B46,CAD_CONTR,"SANTOS") -> 0 | D46: =IF(COUNTIFS(CAD_CONTR,"SANTOS")=0,"",C46/COUNTIFS(CAD_CONTR,"SANTOS")) | F46: =IFERROR(IF($E46="","",VLOOKUP($E46,PRE_TAB,5,FALSE)),"CÓDIGO NÃO ENCONTRADO") | G46: =IFERROR(IF($E46="","",VLOOKUP($E46,PRE_TAB,8,FALSE)),"") | H46: =IF(OR($D46="",$G46=""),0,$D46*$G46) -> 0 | I46: nº deste tipo ÷ total do contrato, na aba 03 · preço do item na aba 02
...

Sheet 02. TABELA DE PREÇOS
A1: TABELA DE PREÇOS DOS CONTRATOS — BERTIOGA/GUARUJÁ E SANTOS | O1: COMO PREENCHER ESTA ABA
A2: 511 itens contratados — 212 de Bertioga/Guarujá e 299 de Santos. Aba de consulta: ninguém edita, preço só muda em reajuste oficial. A CHAVE (coluna A) = prefixo do contrato + nº do preço, e é ela que a aba 09 usa para trazer descrição, unidade e preço — por isso um código SAN- não vale numa OS de Bertioga. Busque por palavra na célula amarela; o dicionário dos códigos está no rodapé da aba. | J2: BUSCAR: | L2: ◀ digite parte da descrição ou o nº do preço e filtre a coluna BUSCA por "1" | O2: Aba de consulta. NÃO digita nada.
O3: São os 511 preços que a SABESP paga.
A4: CHAVE | B4: CONTRATO | C4: GRUPO | D4: ITEM SABESP | E4: DESCRIÇÃO DO SERVIÇO | F4: N. PREÇO | G4: UN | H4: R$ UNIT. | I4: BUSCA | O4: Só muda em reajuste oficial do contrato.
A5: BER-72000033 | B5: BERTIOGA | C5: EXECUÇÃO DE LIGAÇÃO DE ÁGUA SUCESSIVA | E5: LAG PA SUCES S/REP SF | F5: 72000033 | G5: un | H5: 60.95 | I5: =IF($K$2="","",IF(ISNUMBER(SEARCH($K$2,$E5&$F5)),1,"")) | O5: PARA ACHAR UM SERVIÇO:
A6: BER-72000034 | B6: BERTIOGA | C6: EXECUÇÃO DE LIGAÇÃO DE ÁGUA SUCESSIVA | E6: LAG TA SUCES S/REP SF | F6: 72000034 | G6: un | H6: 151.81 | I6: =IF($K$2="","",IF(ISNUMBER(SEARCH($K$2,$E6&$F6)),1,"")) | O6: 1) digite parte do nome na célula amarela (J2)
A7: BER-72000035 | B7: BERTIOGA | C7: EXECUÇÃO DE LIGAÇÃO DE ÁGUA SUCESSIVA | E7: LAG EX SUCES S/REP SF | F7: 72000035 | G7: un | H7: 202.39 | I7: =IF($K$2="","",IF(ISNUMBER(SEARCH($K$2,$E7&$F7)),1,"")) | O7: 2) filtre a coluna BUSCA por "1"
A8: BER-72000036 | B8: BERTIOGA | C8: EXECUÇÃO DE LIGAÇÃO DE ÁGUA SUCESSIVA | E8: LAG TO SUCES S/REP SF | F8: 72000036 | G8: un | H8: 282.67 | I8: =IF($K$2="","",IF(ISNUMBER(SEARCH($K$2,$E8&$F8)),1,"")) | O8: A CHAVE da coluna A é o que as outras abas usam.
A9: BER-72000037 | B9: BERTIOGA | C9: EXECUÇÃO DE LIGAÇÃO DE ÁGUA SUCESSIVA | E9: LAG PO SUCES S/REP SF | F9: 72000037 | G9: un | H9: 338.9 | I9: =IF($K$2="","",IF(ISNUMBER(SEARCH($K$2,$E9&$F9)),1,""))
A10: BER-72000229 | B10: BERTIOGA | C10: EXECUÇÃO DE LIGAÇÃO DE ÁGUA SUCESSIVA | E10: ADC INST CV SF | F10: 72000229 | G10: un | H10: 193.79 | I10: =IF($K$2="","",IF(ISNUMBER(SEARCH($K$2,$E10&$F10)),1,""))
A11: BER-72000057 | B11: BERTIOGA | C11: EXECUÇÃO DE LIGAÇÃO DE ÁGUA SUCESSIVA | E11: LAG PA SUCES S/REP | F11: 72000057 | G11: un | H11: 436.78 | I11: =IF($K$2="","",IF(ISNUMBER(SEARCH($K$2,$E11&$F11)),1,""))
A12: BER-72000058 | B12: BERTIOGA | C12: EXECUÇÃO DE LIGAÇÃO DE ÁGUA SUCESSIVA | E12: LAG TA SUCES S/REP | F12: 72000058 | G12: un | H12: 500.87 | I12: =IF($K$2="","",IF(ISNUMBER(SEARCH($K$2,$E12&$F12)),1,""))
A13: BER-72000059 | B13: BERTIOGA | C13: EXECUÇÃO DE LIGAÇÃO DE ÁGUA SUCESSIVA | E13: LAG EX SUCES S/REP | F13: 72000059 | G13: un | H13: 637.5 | I13: =IF($K$2="","",IF(ISNUMBER(SEARCH($K$2,$E13&$F13)),1,""))
A14: BER-72000060 | B14: BERTIOGA | C14: EXECUÇÃO DE LIGAÇÃO DE ÁGUA SUCESSIVA | E14: LAG TO SUCES S/REP | F14: 72000060 | G14: un | H14: 654.59 | I14: =IF($K$2="","",IF(ISNUMBER(SEARCH($K$2,$E14&$F14)),1,""))
A15: BER-72000061 | B15: BERTIOGA | C15: EXECUÇÃO DE LIGAÇÃO DE ÁGUA SUCESSIVA | E15: LAG PO SUCES S/REP | F15: 72000061 | G15: un | H15: 704.59 | I15: =IF($K$2="","",IF(ISNUMBER(SEARCH($K$2,$E15&$F15)),1,""))
A16: BER-72000224 | B16: BERTIOGA | C16: EXECUÇÃO DE LIGAÇÃO DE ÁGUA SUCESSIVA | E16: ADC INST CV | F16: 72000224 | G16: un | H16: 311.39 | I16: =IF($K$2="","",IF(ISNUMBER(SEARCH($K$2,$E16&$F16)),1,""))
A17: BER-72000101 | B17: BERTIOGA | C17: EXECUÇÃO DE LIGAÇÃO DE ÁGUA SUCESSIVA | E17: LRP CIM LAG SUCES | F17: 72000101 | G17: un | H17: 139.9 | I17: =IF($K$2="","",IF(ISNUMBER(SEARCH($K$2,$E17&$F17)),1,""))
A18: BER-72000102 | B18: BERTIOGA | C18: EXECUÇÃO DE LIGAÇÃO DE ÁGUA SUCESSIVA | E18: LRP ESP LAG SUCES | F18: 72000102 | G18: un | H18: 242.97 | I18: =IF($K$2="","",IF(ISNUMBER(SEARCH($K$2,$E18&$F18)),1,""))
A19: BER-72001180 | B19: BERTIOGA | C19: EXECUÇÃO DE LIGAÇÃO DE ÁGUA SUCESSIVA | E19: LPB TA LAG SUCES COMPX C | F19: 72001180 | G19: un | H19: 41.96 | I19: =IF($K$2="","",IF(ISNUMBER(SEARCH($K$2,$E19&$F19)),1,""))
A20: BER-72001082 | B20: BERTIOGA | C20: EXECUÇÃO DE LIGAÇÃO DE ÁGUA SUCESSIVA | E20: LPB EX LAG SUCES COMPX C | F20: 72001082 | G20: un | H20: 78.11 | I20: =IF($K$2="","",IF(ISNUMBER(SEARCH($K$2,$E20&$F20)),1,""))
... A216: BER-72001222 | B216: BERTIOGA | C216: EXECUÇÃO DE TROCA DE LIGAÇÃO DE ESGOTO | E216: LPB DE 3 A 4M TO TRE COMPX C | F216: 72001222 | G216: un | H216: 1365.8 | I216: =IF($K$2="","",IF(ISNUMBER(SEARCH($K$2,$E216&$F216)),1,""))
A217: SAN-72000759 | B217: SANTOS | C217: SERVIÇOS DE ESGOTO | D217: 2090501 | E217: CONST PI ATE 2M S/REP | F217: 72000759 | G217: un | H217: 1597.75 | I217: =IF($K$2="","",IF(ISNUMBER(SEARCH($K$2,$E217&$F217)),1,""))
A218: SAN-72000759 | B218: SANTOS | C218: SERVIÇOS DE ESGOTO | D218: 2220501 | E218: CONST PI ATE 2M S/REP | F218: 72000759 | G218: un | H218: 1597.75 | I218: =IF($K$2="","",IF(ISNUMBER(SEARCH($K$2,$E218&$F218)),1,""))
A219: SAN-72000760 | B219: SANTOS | C219: SERVIÇOS DE ESGOTO | D219: 2090502 | E219: CONST PI DE 2 A 3M S/REP | F219: 72000760 | G219: un | H219: 1762.75 | I219: =IF($K$2="","",IF(ISNUMBER(SEARCH($K$2,$E219&$F219)),1,""))
A220: SAN-72000760 | B220: SANTOS | C220: SERVIÇOS DE ESGOTO | D220: 2220502 | E220: CONST PI DE 2 A 3M S/REP | F220: 72000760 | G220: un | H220: 1762.75 | I220: =IF($K$2="","",IF(ISNUMBER(SEARCH($K$2,$E220&$F220)),1,""))
A221: SAN-72000748 | B221: SANTOS | C221: SERVIÇOS DE ESGOTO | D221: 2090508 | E221: CPV DIAM = 1,20M - DE 2 A 3M - S/REP | F221: 72000748 | G221: un | H221: 2992.75 | I221: =IF($K$2="","",IF(ISNUMBER(SEARCH($K$2,$E221&$F221)),1,""))
A222: SAN-72000748 | B222: SANTOS | C222: SERVIÇOS DE ESGOTO | D222: 2220508 | E222: CPV DIAM = 1,20M - DE 2 A 3M - S/REP | F222: 72000748 | G222: un | H222: 2992.75 | I222: =IF($K$2="","",IF(ISNUMBER(SEARCH($K$2,$E222&$F222)),1,""))
A223: SAN-72000749 | B223: SANTOS | C223: SERVIÇOS DE ESGOTO | D223: 2090509 | E223: CPV DIAM = 1,20M - DE 3 A 4M - S/REP | F223: 72000749 | G223: un | H223: 3712.75 | I223: =IF($K$2="","",IF(ISNUMBER(SEARCH($K$2,$E223&$F223)),1,""))
A224: SAN-72000749 | B224: SANTOS | C224: SERVIÇOS DE ESGOTO | D224: 2220509 | E224: CPV DIAM = 1,20M - DE 3 A 4M - S/REP | F224: 72000749 | G224: un | H224: 3712.75 | I224: =IF($K$2="","",IF(ISNUMBER(SEARCH($K$2,$E224&$F224)),1,""))
A225: SAN-72000750 | B225: SANTOS | C225: SERVIÇOS DE ESGOTO | D225: 2090510 | E225: CPV DIAM = 1,20M - DE 4 A 5M - S/REP | F225: 72000750 | G225: un | H225: 4297.75 | I225: =IF($K$2="","",IF(ISNUMBER(SEARCH($K$2,$E225&$F225)),1,""))
A226: SAN-72000750 | B226: SANTOS | C226: SERVIÇOS DE ESGOTO | D226: 2220510 | E226: CPV DIAM = 1,20M - DE 4 A 5M - S/REP | F226: 72000750 | G226: un | H226: 4297.75 | I226: =IF($K$2="","",IF(ISNUMBER(SEARCH($K$2,$E226&$F226)),1,""))
A227: SAN-72000747 | B227: SANTOS | C227: SERVIÇOS DE ESGOTO | D227: 2090507 | E227: CPV DIAM = 1,20M - PROF ATE 2M S/REP | F227: 72000747 | G227: un | H227: 2097.75 | I227: =IF($K$2="","",IF(ISNUMBER(SEARCH($K$2,$E227&$F227)),1,""))
A228: SAN-72000747 | B228: SANTOS | C228: SERVIÇOS DE ESGOTO | D228: 2220507 | E228: CPV DIAM = 1,20M - PROF ATE 2M S/REP | F228: 72000747 | G228: un | H228: 2097.75 | I228: =IF($K$2="","",IF(ISNUMBER(SEARCH($K$2,$E228&$F228)),1,""))
... A515: SAN-72000238 | B515: SANTOS | C515: SERVIÇOS DE ÁGUA | D515: 1030301 | E515: SUPR TMD AG S/REP SF | F515: 72000238 | G515: un | H515: 427.95 | I515: =IF($K$2="","",IF(ISNUMBER(SEARCH($K$2,$E515&$F515)),1,""))
A518: COMO ESCOLHER O ITEM — DICIONÁRIO DOS CÓDIGOS E O QUE CADA CONTRATO TEM
A519: SERVIÇO DE CAMPO | C519: ONDE PROCURAR NA TABELA | E519: COMO ESCOLHER O ITEM CERTO | G519: EXISTE EM
A520: Nova ligação de água | C520: Grupos EXECUÇÃO DE LIGAÇÃO DE ÁGUA AVULSA e SUCESSIVA — prefixo LAG | E520: AVULSA = endereço isolado. SUCESSIVA = várias na mesma rua no mesmo dia, e custa menos. Confira o diâmetro e o tipo de piso na descrição. | G520: Os dois contratos
A521: Troca de ramal de água | C521: EXECUÇÃO DE TROCA DE LIGAÇÃO DE ÁGUA — prefixo TRA | E521: CORR = corretiva (o vazamento já aconteceu). PREV = preventiva (programada). É este o item de vazamento no ramal: a SABESP paga a troca, não o diagnóstico. | G521: Os dois contratos
A522: Serviço no cavalete | C522: EXECUÇÃO DE SERVIÇOS GERAIS EM CAVALETE — TCV, SUBST CV, ADC TCV | E522: TCV = troca do cavalete. ADC = adicional por cavalete a mais no mesmo endereço. SUBST CV POR UMA = troca por caixa padrão. | G522: Os dois contratos
A523: Ligação e troca de esgoto | C523: LESG (ligação) e TRE (troca de ramal), avulsa ou sucessiva | E523: O preço muda por faixa de profundidade (até 2 m, de 2 a 3 m, de 3 a 4 m) e pelo material. Confira a profundidade anotada na OS. | G523: Os dois contratos
...

Sheet 03. CADASTRO DE SERVIÇOS
A1: CADASTRO DE SERVIÇOS — CARTEIRA DE DEMANDAS RECEBIDAS DA SABESP | AA1: COMO PREENCHER ESTA ABA
A2: Porta de entrada de TODO serviço. Nada é programado, executado ou medido sem estar aqui. AZUL = digite · PRETO = fórmula (não apague). | AA2: Chegou pedido da SABESP? Abre 1 linha aqui. SEMPRE.
AA3: Nada é programado nem medido sem estar aqui.
A4: ID | B4: CONTRATO | C4: Nº OS SABESP | D4: DATA DA SOLICITAÇÃO | E4: PRAZO (dias) | F4: DATA LIMITE | G4: PRIORIDADE | H4: TIPO DE SERVIÇO | I4: ENDEREÇO | J4: Nº | K4: BAIRRO | L4: CIDADE | M4: PONTO DE REFERÊNCIA | N4: PAVIMENTO | O4: DESCRIÇÃO DA SOLICITAÇÃO | P4: EQUIPE DESIGNADA | Q4: DATA PROGRAMADA | R4: DATA DE EXECUÇÃO | S4: STATUS | T4: DIAS EM ABERTO | U4: SITUAÇÃO DO PRAZO | V4: VALOR MEDIDO | W4: TRATATIVA MANUAL | X4: OBSERVAÇÃO | AA4: B = BERTIOGA ou SANTOS (menu)
A5: =IF($B5="","",LEFT($B5,3)&"-"&TEXT(ROW()-4,"0000")) -> BER-0001 | B5: BERTIOGA | D5: 46267 | E5: 5 | F5: =IF($D5="","",$D5+IF($E5="",'01. CONFIGURAÇÕES'!$C$22,$E5)) -> 46272 | G5: URGENTE | H5: Vazamento de água não visível — rede | I5: Alameda Maua | J5: 225 | K5: Boracéia | L5: Bertioga | M5: Sede | O5: Vazamento de água não visível rede | P5: =IFERROR(IF($A5="","",IF(COUNTIFS(OS_ID,$A5)>0,INDEX(OS_EQUIPE,MATCH($A5,OS_ID,0)),IF(COUNTIFS(PROG_ID,$A5)>0,INDEX(PROG_EQUIPE,MATCH($A5,PROG_ID,0)),""))),"") -> 0 | Q5: =IF($A5="","",IFERROR(IF(INDEX(PROG_DATA,MATCH($A5,PROG_ID,0))=0,"",INDEX(PROG_DATA,MATCH($A5,PROG_ID,0))),"")) -> 46273 | R5: =IF($A5="","",IFERROR(IF(INDEX(OS_FIM,MATCH($A5,OS_ID,0))=0,"",INDEX(OS_FIM,MATCH($A5,OS_ID,0))),"")) -> 46273 | S5: =IF($A5="","",IF($W5<>"",$W5,IF($V5>0,"MEDIDO",IF($R5<>"","EXECUTADO",IF(COUNTIFS(OS_ID,$A5)>0,"EM EXECUÇÃO",IF($Q5<>"","PROGRAMADO","CADASTRADO")))))) -> EXECUTADO | T5: =IF($A5="","",IF($R5<>"",$R5-$D5,TODAY()-$D5)) -> 6 | U5: =IF(OR($A5="",$F5=""),"",IF($R5<>"",IF($R5<=$F5,"NO PRAZO","FORA DO PRAZO"),IF(TODAY()>$F5,"VENCIDO",IF($F5-TODAY()<='01. CONFIGURAÇÕES'!$C$23,"VENCE EM BREVE","EM DIA")))) -> FORA DO PRAZO | V5: =IF($A5="","",SUMIFS(MED_VLR,MED_ID,$A5)) -> 0 | AA5: C = nº da OS que a SABESP passou
A6: =IF($B6="","",LEFT($B6,3)&"-"&TEXT(ROW()-4,"0000")) -> BER-0002 | B6: BERTIOGA | D6: 46267 | E6: 5 | F6: =IF($D6="","",$D6+IF($E6="",'01. CONFIGURAÇÕES'!$C$22,$E6)) -> 46272 | G6: URGENTE | H6: Vazamento de água não visível — rede | I6: Rua Francisco Chaves | J6: 2267 | K6: Jardim Vicente de Carvalho | L6: Bertioga | M6: B | O6: Vazamento de água não visível rede | P6: =IFERROR(IF($A6="","",IF(COUNTIFS(OS_ID,$A6)>0,INDEX(OS_EQUIPE,MATCH($A6,OS_ID,0)),IF(COUNTIFS(PROG_ID,$A6)>0,INDEX(PROG_EQUIPE,MATCH($A6,PROG_ID,0)),""))),"") -> 0 | Q6: =IF($A6="","",IFERROR(IF(INDEX(PROG_DATA,MATCH($A6,PROG_ID,0))=0,"",INDEX(PROG_DATA,MATCH($A6,PROG_ID,0))),"")) -> 46268 | R6: =IF($A6="","",IFERROR(IF(INDEX(OS_FIM,MATCH($A6,OS_ID,0))=0,"",INDEX(OS_FIM,MATCH($A6,OS_ID,0))),"")) -> 46268 | S6: =IF($A6="","",IF($W6<>"",$W6,IF($V6>0,"MEDIDO",IF($R6<>"","EXECUTADO",IF(COUNTIFS(OS_ID,$A6)>0,"EM EXECUÇÃO",IF($Q6<>"","PROGRAMADO","CADASTRADO")))))) -> MEDIDO | T6: =IF($A6="","",IF($R6<>"",$R6-$D6,TODAY()-$D6)) -> 1 | U6: =IF(OR($A6="",$F6=""),"",IF($R6<>"",IF($R6<=$F6,"NO PRAZO","FORA DO PRAZO"),IF(TODAY()>$F6,"VENCIDO",IF($F6-TODAY()<='01. CONFIGURAÇÕES'!$C$23,"VENCE EM BREVE","EM DIA")))) -> NO PRAZO | V6: =IF($A6="","",SUMIFS(MED_VLR,MED_ID,$A6)) -> 924.97 | AA6: D = data em que a SABESP pediu
A7: =IF($B7="","",LEFT($B7,3)&"-"&TEXT(ROW()-4,"0000")) -> BER-0003 | B7: BERTIOGA | D7: 46267 | E7: 5 | F7: =IF($D7="","",$D7+IF($E7="",'01. CONFIGURAÇÕES'!$C$22,$E7)) -> 46272 | G7: NORMAL | H7: Troca de ramal de água | I7: Alameda Agapanthos | J7: 66 | K7: Boracéia | L7: Bertioga | M7: L.10 Q.G | O7: Trocar ramal de água - vaz não visível | P7: =IFERROR(IF($A7="","",IF(COUNTIFS(OS_ID,$A7)>0,INDEX(OS_EQUIPE,MATCH($A7,OS_ID,0)),IF(COUNTIFS(PROG_ID,$A7)>0,INDEX(PROG_EQUIPE,MATCH($A7,PROG_ID,0)),""))),"") -> 0 | Q7: =IF($A7="","",IFERROR(IF(INDEX(PROG_DATA,MATCH($A7,PROG_ID,0))=0,"",INDEX(PROG_DATA,MATCH($A7,PROG_ID,0))),"")) -> 46268 | R7: =IF($A7="","",IFERROR(IF(INDEX(OS_FIM,MATCH($A7,OS_ID,0))=0,"",INDEX(OS_FIM,MATCH($A7,OS_ID,0))),"")) -> 46268 | S7: =IF($A7="","",IF($W7<>"",$W7,IF($V7>0,"MEDIDO",IF($R7<>"","EXECUTADO",IF(COUNTIFS(OS_ID,$A7)>0,"EM EXECUÇÃO",IF($Q7<>"","PROGRAMADO","CADASTRADO")))))) -> MEDIDO | T7: =IF($A7="","",IF($R7<>"",$R7-$D7,TODAY()-$D7)) -> 1 | U7: =IF(OR($A7="",$F7=""),"",IF($R7<>"",IF($R7<=$F7,"NO PRAZO","FORA DO PRAZO"),IF(TODAY()>$F7,"VENCIDO",IF($F7-TODAY()<='01. CONFIGURAÇÕES'!$C$23,"VENCE EM BREVE","EM DIA")))) -> NO PRAZO | V7: =IF($A7="","",SUMIFS(MED_VLR,MED_ID,$A7)) -> 785.07 | AA7: E = prazo em dias (5 se não falaram nada)
A8: =IF($B8="","",LEFT($B8,3)&"-"&TEXT(ROW()-4,"0000")) -> BER-0004 | B8: BERTIOGA | D8: 46267 | E8: 5 | F8: =IF($D8="","",$D8+IF($E8="",'01. CONFIGURAÇÕES'!$C$22,$E8)) -> 46272 | G8: URGENTE | H8: Vazamento de água não visível — ramal | I8: Alameda Paranapiacaba | J8: 600 | K8: Boracéia | L8: Bertioga | M8: Q.23 L.7 | O8: Vazamento de água não visível ramal | P8: =IFERROR(IF($A8="","",IF(COUNTIFS(OS_ID,$A8)>0,INDEX(OS_EQUIPE,MATCH($A8,OS_ID,0)),IF(COUNTIFS(PROG_ID,$A8)>0,INDEX(PROG_EQUIPE,MATCH($A8,PROG_ID,0)),""))),"") -> 0 | Q8: =IF($A8="","",IFERROR(IF(INDEX(PROG_DATA,MATCH($A8,PROG_ID,0))=0,"",INDEX(PROG_DATA,MATCH($A8,PROG_ID,0))),"")) -> 46268 | R8: =IF($A8="","",IFERROR(IF(INDEX(OS_FIM,MATCH($A8,OS_ID,0))=0,"",INDEX(OS_FIM,MATCH($A8,OS_ID,0))),"")) -> 46268 | S8: =IF($A8="","",IF($W8<>"",$W8,IF($V8>0,"MEDIDO",IF($R8<>"","EXECUTADO",IF(COUNTIFS(OS_ID,$A8)>0,"EM EXECUÇÃO",IF($Q8<>"","PROGRAMADO","CADASTRADO")))))) -> MEDIDO | T8: =IF($A8="","",IF($R8<>"",$R8-$D8,TODAY()-$D8)) -> 1 | U8: =IF(OR($A8="",$F8=""),"",IF($R8<>"",IF($R8<=$F8,"NO PRAZO","FORA DO PRAZO"),IF(TODAY()>$F8,"VENCIDO",IF($F8-TODAY()<='01. CONFIGURAÇÕES'!$C$23,"VENCE EM BREVE","EM DIA")))) -> NO PRAZO | V8: =IF($A8="","",SUMIFS(MED_VLR,MED_ID,$A8)) -> 785.07 | X8: Foi localizado um gato na mangueira da Sabesp, porem foi retirado | AA8: G = URGENTE ou NORMAL (menu)
A9: =IF($B9="","",LEFT($B9,3)&"-"&TEXT(ROW()-4,"0000")) -> BER-0005 | B9: BERTIOGA | D9: 46267 | E9: 5 | F9: =IF($D9="","",$D9+IF($E9="",'01. CONFIGURAÇÕES'!$C$22,$E9)) -> 46272 | G9: URGENTE | H9: Vazamento de água não visível — ramal | I9: Alameda Rio Grande da Serra | J9: 455 | K9: Boracéia | L9: Bertioga | M9: ANT N.687 | O9: Vazamento de água não visível ramal | P9: =IFERROR(IF($A9="","",IF(COUNTIFS(OS_ID,$A9)>0,INDEX(OS_EQUIPE,MATCH($A9,OS_ID,0)),IF(COUNTIFS(PROG_ID,$A9)>0,INDEX(PROG_EQUIPE,MATCH($A9,PROG_ID,0)),""))),"") -> 0 | Q9: =IF($A9="","",IFERROR(IF(INDEX(PROG_DATA,MATCH($A9,PROG_ID,0))=0,"",INDEX(PROG_DATA,MATCH($A9,PROG_ID,0))),"")) -> 46268 | R9: =IF($A9="","",IFERROR(IF(INDEX(OS_FIM,MATCH($A9,OS_ID,0))=0,"",INDEX(OS_FIM,MATCH($A9,OS_ID,0))),"")) -> 46268 | S9: =IF($A9="","",IF($W9<>"",$W9,IF($V9>0,"MEDIDO",IF($R9<>"","EXECUTADO",IF(COUNTIFS(OS_ID,$A9)>0,"EM EXECUÇÃO",IF($Q9<>"","PROGRAMADO","CADASTRADO")))))) -> MEDIDO | T9: =IF($A9="","",IF($R9<>"",$R9-$D9,TODAY()-$D9)) -> 1 | U9: =IF(OR($A9="",$F9=""),"",IF($R9<>"",IF($R9<=$F9,"NO PRAZO","FORA DO PRAZO"),IF(TODAY()>$F9,"VENCIDO",IF($F9-TODAY()<='01. CONFIGURAÇÕES'!$C$23,"VENCE EM BREVE","EM DIA")))) -> NO PRAZO | V9: =IF($A9="","",SUMIFS(MED_VLR,MED_ID,$A9)) -> 1086.54 | AA9: H = tipo de serviço (menu)
A10: =IF($B10="","",LEFT($B10,3)&"-"&TEXT(ROW()-4,"0000")) -> BER-0006 | B10: BERTIOGA | D10: 46267 | E10: 5 | F10: =IF($D10="","",$D10+IF($E10="",'01. CONFIGURAÇÕES'!$C$22,$E10)) -> 46272 | G10: NORMAL | H10: Troca de ramal de água | I10: Rua Prolongada Oswaldo Cruz | J10: 27 | K10: Jardim Vicente de Carvalho | L10: Bertioga | M10: Casa 2 | O10: Trocar ramal de água - vaz não visível | P10: =IFERROR(IF($A10="","",IF(COUNTIFS(OS_ID,$A10)>0,INDEX(OS_EQUIPE,MATCH($A10,OS_ID,0)),IF(COUNTIFS(PROG_ID,$A10)>0,INDEX(PROG_EQUIPE,MATCH($A10,PROG_ID,0)),""))),"") -> 0 | Q10: =IF($A10="","",IFERROR(IF(INDEX(PROG_DATA,MATCH($A10,PROG_ID,0))=0,"",INDEX(PROG_DATA,MATCH($A10,PROG_ID,0))),"")) -> 46268 | R10: =IF($A10="","",IFERROR(IF(INDEX(OS_FIM,MATCH($A10,OS_ID,0))=0,"",INDEX(OS_FIM,MATCH($A10,OS_ID,0))),"")) -> 46268 | S10: =IF($A10="","",IF($W10<>"",$W10,IF($V10>0,"MEDIDO",IF($R10<>"","EXECUTADO",IF(COUNTIFS(OS_ID,$A10)>0,"EM EXECUÇÃO",IF($Q10<>"","PROGRAMADO","CADASTRADO")))))) -> MEDIDO | T10: =IF($A10="","",IF($R10<>"",$R10-$D10,TODAY()-$D10)) -> 1 | U10: =IF(OR($A10="",$F10=""),"",IF($R10<>"",IF($R10<=$F10,"NO PRAZO","FORA DO PRAZO"),IF(TODAY()>$F10,"VENCIDO",IF($F10-TODAY()<='01. CONFIGURAÇÕES'!$C$23,"VENCE EM BREVE","EM DIA")))) -> NO PRAZO | V10: =IF($A10="","",SUMIFS(MED_VLR,MED_ID,$A10)) -> 924.97 | AA10: I = rua J = número K = bairro (menu)
A11: =IF($B11="","",LEFT($B11,3)&"-"&TEXT(ROW()-4,"0000")) -> BER-0007 | B11: BERTIOGA | D11: 46267 | E11: 5 | F11: =IF($D11="","",$D11+IF($E11="",'01. CONFIGURAÇÕES'!$C$22,$E11)) -> 46272 | G11: NORMAL | H11: Troca de ramal de água | I11: Rua Prolongada Oswaldo Cruz | J11: 391 | K11: Jardim Vicente de Carvalho | L11: Bertioga | M11: Q.F L.5 | O11: Trocar ramal de água - vaz não visível | P11: =IFERROR(IF($A11="","",IF(COUNTIFS(OS_ID,$A11)>0,INDEX(OS_EQUIPE,MATCH($A11,OS_ID,0)),IF(COUNTIFS(PROG_ID,$A11)>0,INDEX(PROG_EQUIPE,MATCH($A11,PROG_ID,0)),""))),"") -> 0 | Q11: =IF($A11="","",IFERROR(IF(INDEX(PROG_DATA,MATCH($A11,PROG_ID,0))=0,"",INDEX(PROG_DATA,MATCH($A11,PROG_ID,0))),"")) -> 46267 | R11: =IF($A11="","",IFERROR(IF(INDEX(OS_FIM,MATCH($A11,OS_ID,0))=0,"",INDEX(OS_FIM,MATCH($A11,OS_ID,0))),"")) -> 46268 | S11: =IF($A11="","",IF($W11<>"",$W11,IF($V11>0,"MEDIDO",IF($R11<>"","EXECUTADO",IF(COUNTIFS(OS_ID,$A11)>0,"EM EXECUÇÃO",IF($Q11<>"","PROGRAMADO","CADASTRADO")))))) -> MEDIDO | T11: =IF($A11="","",IF($R11<>"",$R11-$D11,TODAY()-$D11)) -> 1 | U11: =IF(OR($A11="",$F11=""),"",IF($R11<>"",IF($R11<=$F11,"NO PRAZO","FORA DO PRAZO"),IF(TODAY()>$F11,"VENCIDO",IF($F11-TODAY()<='01. CONFIGURAÇÕES'!$C$23,"VENCE EM BREVE","EM DIA")))) -> NO PRAZO | V11: =IF($A11="","",SUMIFS(MED_VLR,MED_ID,$A11)) -> 1871.61 | AA11: L = cidade M = ponto de referência
A12: =IF($B12="","",LEFT($B12,3)&"-"&TEXT(ROW()-4,"0000")) -> BER-0008 | B12: BERTIOGA | D12: 46267 | E12: 5 | F12: =IF($D12="","",$D12+IF($E12="",'01. CONFIGURAÇÕES'!$C$22,$E12)) -> 46272 | G12: URGENTE | H12: Vazamento de água não visível — ramal | I12: Alameda Paranapiacaba | J12: 930 | K12: Boracéia | L12: Bertioga | M12: ANT N.1128 | O12: Vazamento de água não visível ramal | P12: =IFERROR(IF($A12="","",IF(COUNTIFS(OS_ID,$A12)>0,INDEX(OS_EQUIPE,MATCH($A12,OS_ID,0)),IF(COUNTIFS(PROG_ID,$A12)>0,INDEX(PROG_EQUIPE,MATCH($A12,PROG_ID,0)),""))),"") -> 0 | Q12: =IF($A12="","",IFERROR(IF(INDEX(PROG_DATA,MATCH($A12,PROG_ID,0))=0,"",INDEX(PROG_DATA,MATCH($A12,PROG_ID,0))),"")) -> 46267 | R12: =IF($A12="","",IFERROR(IF(INDEX(OS_FIM,MATCH($A12,OS_ID,0))=0,"",INDEX(OS_FIM,MATCH($A12,OS_ID,0))),"")) -> 46268 | S12: =IF($A12="","",IF($W12<>"",$W12,IF($V12>0,"MEDIDO",IF($R12<>"","EXECUTADO",IF(COUNTIFS(OS_ID,$A12)>0,"EM EXECUÇÃO",IF($Q12<>"","PROGRAMADO","CADASTRADO")))))) -> MEDIDO | T12: =IF($A12="","",IF($R12<>"",$R12-$D12,TODAY()-$D12)) -> 1 | U12: =IF(OR($A12="",$F12=""),"",IF($R12<>"",IF($R12<=$F12,"NO PRAZO","FORA DO PRAZO"),IF(TODAY()>$F12,"VENCIDO",IF($F12-TODAY()<='01. CONFIGURAÇÕES'!$C$23,"VENCE EM BREVE","EM DIA")))) -> NO PRAZO | V12: =IF($A12="","",SUMIFS(MED_VLR,MED_ID,$A12)) -> 820.98 | AA12: N = piso: asfalto, calçada, terra (menu)
