Workbook

Sheet BASE MEDIÇÃO  
A1: BASE DE MEDIÇÃO – PREÇOS DO CONTRATO A 60% – CONSÓRCIO SANEAMENTO ZN
H2: FATOR: | I2: 0.6
A4: ITEM | B4: CÓDIGO | C4: DESCRIÇÃO DO SERVIÇO | D4: UN | E4: PREÇO CONTRATO (R$) | F4: PREÇO 60% (R$) | G4: QTD. MEDIDA SAKURA | H4: QTD. MEDIDA BOI MALHADO | I4: VALOR MEDIÇÃO (R$)
A5: PARTE 1 – ITENS DO CONTRATO (PLANILHA DE BALANCEAMENTO)
A6: CANTEIRO DE OBRAS
A7: 1 | B7: 01010101 | C7: IMPLANTAÇÃO DE CANTEIRO | D7: UND | E7: 369483.97 | F7: =ROUND(E7*$I$2,2) -> 221690.38 | I7: =ROUND(H7*F7,2) -> 0
A8: 2 | B8: 01010102 | C8: MANUTENÇÁO DO CANTEIRO | D8: MES | E8: 196421.07 | F8: =ROUND(E8*$I$2,2) -> 117852.64 | I8: =ROUND(H8*F8,2) -> 0
A9: PLANOS DE GESTÃO DE OBRAS
A10: 3 | B10: 02010101 | C10: PLANO DE COMERCIALIZAÇÃO DE LIGAÇÕES | D10: UN | E10: 62.66 | F10: =ROUND(E10*$I$2,2) -> 37.6 | I10: =ROUND(H10*F10,2) -> 0
A11: 4 | B11: 02010102 | C11: PLANO DE QUALIDADE TOTAL | D11: MES | E11: 89370.92 | F11: =ROUND(E11*$I$2,2) -> 53622.55 | I11: =ROUND(H11*F11,2) -> 0
A12: INSPEÇÃO EM LIGAÇÃO DE ESGOTO
A13: 5 | B13: 02010201 | C13: INSPEÇÃO EM LIGAÇÃO DE ESGOTO - VARREDUR | D13: UN | E13: 45.34 | F13: =ROUND(E13*$I$2,2) -> 27.2 | I13: =ROUND(H13*F13,2) -> 0
A14: ASSENTAMENTO DE REDE DE ESGOTO
A15: 6 | B15: 02020101 | C15: PRE MEC OU MAN PVC 150 ATE 2,0M S/REP | D15: M | E15: 291.35 | F15: =ROUND(E15*$I$2,2) -> 174.81 | I15: =ROUND(H15*F15,2) -> 0
A16: 7 | B16: 02020102 | C16: PRE PVC 150 ATE 2,7M S/REP | D16: M | E16: 408.68 | F16: =ROUND(E16*$I$2,2) -> 245.21 | I16: =ROUND(H16*F16,2) -> 0
A17: 8 | B17: 02020103 | C17: PRE PVC 150 ATE 3,5M S/REP | D17: M | E17: 732.23 | F17: =ROUND(E17*$I$2,2) -> 439.34 | I17: =ROUND(H17*F17,2) -> 0
A18: 9 | B18: 02020104 | C18: PRE MEC OU MAN PVC 200 ATE 2,0M S/REP | D18: M | E18: 384.35 | F18: =ROUND(E18*$I$2,2) -> 230.61 | H18: 396.03 | I18: =ROUND(H18*F18,2) -> 91328.48
A19: 10 | B19: 02020105 | C19: PRE PVC 200 ATE 2,7M S/REP | D19: M | E19: 500.32 | F19: =ROUND(E19*$I$2,2) -> 300.19 | I19: =ROUND(H19*F19,2) -> 0
A20: 11 | B20: 02020106 | C20: PRE PVC 200 ATE 3,5M S/REP | D20: M | E20: 1017.3 | F20: =ROUND(E20*$I$2,2) -> 610.38 | I20: =ROUND(H20*F20,2) -> 0
A21: 12 | B21: 02020107 | C21: PRE PVC 300 ATE 1,5M S/REP | D21: M | E21: 420.03 | F21: =ROUND(E21*$I$2,2) -> 252.02 | I21: =ROUND(H21*F21,2) -> 0
A22: 13 | B22: 02020108 | C22: PRE PVC 300 ATE 2M S/REP | D22: M | E22: 511.02 | F22: =ROUND(E22*$I$2,2) -> 306.61 | I22: =ROUND(H22*F22,2) -> 0
A23: 14 | B23: 02020109 | C23: PRE PVC 300 ATE 2,7M S/REP | D23: M | E23: 824.78 | F23: =ROUND(E23*$I$2,2) -> 494.87 | I23: =ROUND(H23*F23,2) -> 0
A24: 15 | B24: 02020110 | C24: PRE PVC 300 ATE 3,5M S/REP | D24: M | E24: 1593.27 | F24: =ROUND(E24*$I$2,2) -> 955.96 | I24: =ROUND(H24*F24,2) -> 0
A25: 16 | B25: 02020111 | C25: PRE PVC 400 ATE 1,5M S/REP | D25: M | E25: 1063.62 | F25: =ROUND(E25*$I$2,2) -> 638.17 | I25: =ROUND(H25*F25,2) -> 0
A26: 17 | B26: 02020112 | C26: PRE PVC 400 ATE 2M S/REP | D26: M | E26: 1161.93 | F26: =ROUND(E26*$I$2,2) -> 697.16 | I26: =ROUND(H26*F26,2) -> 0
A27: 18 | B27: 02020113 | C27: PRE PVC 400 ATE 2,7M S/REP | D27: M | E27: 1394.29 | F27: =ROUND(E27*$I$2,2) -> 836.57 | I27: =ROUND(H27*F27,2) -> 0
A28: 19 | B28: 02020114 | C28: PRE PVC 400 ATE 3,5M S/REP | D28: M | E28: 1990.98 | F28: =ROUND(E28*$I$2,2) -> 1194.59 | I28: =ROUND(H28*F28,2) -> 0
A29: 20 | B29: 02020115 | C29: ASSENTAMENTO DE REDE COLETORA ESGOTOS-BE | D29: M | E29: 583.83 | F29: =ROUND(E29*$I$2,2) -> 350.3 | I29: =ROUND(H29*F29,2) -> 0
A30: 21 | B30: 02020116 | C30: PV EM TUBO DE CONCRETO PBJE - PROFUNDIDA | D30: UN | E30: 2282.52 | F30: =ROUND(E30*$I$2,2) -> 1369.51 | I30: =ROUND(H30*F30,2) -> 0
... A41: 32 | B41: 02020127 | C41: COMPLEMENTO PARA ESCAVAÇÃO DE CAVAS DE 4 | D41: M3 | E41: 215.97 | F41: =ROUND(E41*$I$2,2) -> 129.58 | I41: =ROUND(H41*F41,2) -> 0
A42: RAMAL COLETIVO DE ESGOTO
A43: 33 | B43: 02030101 | C43: LIGAÇÃO INTRADOMICILIAR RAMAL COLETIVO | D43: UN | E43: 878.11 | F43: =ROUND(E43*$I$2,2) -> 526.87 | I43: =ROUND(H43*F43,2) -> 0
A44: 34 | B44: 02030102 | C44: RAMAL COLETIVO DE ESGOTO EM PVC DN 100 M | D44: M | E44: 183.95 | F44: =ROUND(E44*$I$2,2) -> 110.37 | I44: =ROUND(H44*F44,2) -> 0
A45: 35 | B45: 02030103 | C45: RAMAL COLETIVO DE ESGOTO EM PVC DN 150 M | D45: M | E45: 218.06 | F45: =ROUND(E45*$I$2,2) -> 130.84 | I45: =ROUND(H45*F45,2) -> 0
A46: 36 | B46: 02030104 | C46: RAMAL COLETIVO DE ESGOTO EM PVC DN 200 M | D46: M | E46: 247.67 | F46: =ROUND(E46*$I$2,2) -> 148.6 | I46: =ROUND(H46*F46,2) -> 0
A47: 37 | B47: 02030108 | C47: CAIXA DE INSPEÇÃO (60X60) ATÉ 1,25 M | D47: UN | E47: 923.32 | F47: =ROUND(E47*$I$2,2) -> 553.99 | I47: =ROUND(H47*F47,2) -> 0
A48: LIGAÇÕES INTRADOMICILIARES
A49: 38 | B49: 02040101 | C49: LIGACAO INTRADOMICILIAR TIPO 1 | D49: UN | E49: 1210.92 | F49: =ROUND(E49*$I$2,2) -> 726.55 | I49: =ROUND(H49*F49,2) -> 0
A50: 39 | B50: 02040102 | C50: LIGACAO INTRADOMICILIAR TIPO 2 | D50: UN | E50: 1457.44 | F50: =ROUND(E50*$I$2,2) -> 874.46 | I50: =ROUND(H50*F50,2) -> 0
A51: 40 | B51: 02040103 | C51: LIGACAO INTRADOMICILIAR TIPO 1 PARCIAL | D51: UN | E51: 263.55 | F51: =ROUND(E51*$I$2,2) -> 158.13 | H51: 227 | I51: =ROUND(H51*F51,2) -> 35895.51
...

Sheet MEDIÇÃO
A1: ITEM | B1: CÓDIGO | C1: DESCRIÇÃO DO SERVIÇO | D1: UN | E1: PREÇO 60% (R$) | F1: QTD. MEDIDA SAKURA | G1: QTD. MEDIDA BOI MALHADO | H1: VALOR MEDIÇÃO (R$)
A2: ASSENTAMENTO DE REDE DE ESGOTO
A3: 9 | B3: 02020104 | C3: PRE MEC OU MAN PVC 200 ATE 2,0M S/REP | D3: M | E3: 230.61 | G3: 396.03 | H3: 91328.48
A4: LIGAÇÕES DE ESGOTO
A5: 40 | B5: 02040103 | C5: LIGACAO INTRADOMICILIAR TIPO 1 PARCIAL | D5: UN | E5: 158.13 | G5: 227 | H5: 35895.51
A6: 43 | B6: 02040202 | C6: LESG PVC ATE 2M TA AVUL S/REP | D6: UN | E6: 769.06 | G6: 227 | H6: 174576.62
A7: LPB - PRE
A8: 61 | B8: 02050105 | C8: LPB- LEITO-ASSENT REDE COLET ATÉ 2M. | D8: M | E8: 113.32 | F8: 1079.3783 | G8: 1381.9326 | H8: 156600.6
A9: LRP-LPB- LIGAÇÃO DE ESGOTO
A10: 77 | B10: 02050401 | C10: LRP-PASSEIO CIM-LIG ESG AV ATÉ 2MTS | D10: UN | E10: 92.67 | G10: 227 | H10: 21036.09
A11: 85 | B11: 02050409 | C11: LPB-LEITO-EIXO-LIG ESG AV ACIMA 2M C | D11: UN | E11: 3655.93 | G11: 227 | H11: 829896.11
A12: ASSENTAMENTO REDE ÁGUA - PEAD
A13: 96 | B13: 02070102 | C13: PRA PEAD DE 63 A 125 MM S/REP | D13: M | E13: 90.13 | G13: 1370.31 | H13: 123506.04
A14: LIGAÇÃO DE ÁGUA
A15: 106 | B15: 02080205 | C15: LIG/SUBST LIG AV AGUA 32MM PO S/REPOS | D15: UN | E15: 535.38 | G15: 400 | H15: 214152
A16: INCLUSÕES DE LIGAÇÃO DE ÁGUA
A17: CAIXA UMA
A18: 111 | B18: 02080501 | C18: INSTALAÇÃO CAIXA P/UNID MEDIÇÃO ÁGUA | D18: UN | E18: 174.36 | G18: 400 | H18: 69744
A19: 113 | B19: 02080503 | C19: ADICIONAL P/INSTAL CAIXA UMA | D19: UN | E19: 128.44 | G19: 400 | H19: 51376
A20: SERVIÇOS GERAIS EM CAVALETE
A21: 114 | B21: 02080601 | C21: ADC INST CV | D21: UN | E21: 102.16 | G21: 400 | H21: 40864
A22: SERVIÇOS DE APOIO - LIGAÇÃO DE ÁGUA
A23: 116 | B23: 02090101 | C23: ADIC P/INST SELAS ELETROSSOLD 40 A 90MM. | D23: UN | E23: 14.54 | G23: 400 | H23: 5816
A24: 120 | B24: 02090103 | C24: CORREÇÃO IRREG"BY-PASS, LIG DIR E CLANDE | D24: UN | E24: 687.72 | G24: 400 | H24: 275088
A25: SERV. APOIO TÉCNICO - REDE DE ÁGUA
A26: 126 | B26: 02090204 | C26: ADC INST LUVA ELETR DE 20 A 32 | D26: UN | E26: 14.78 | G26: 800 | H26: 11824
A27: 127 | B27: 02090205 | C27: ADC INST LUVA ELETR DE 40 A 90 | D27: UN | E27: 24.11 | G27: 13 | H27: 313.43
A28: 131 | B28: 02090209 | C28: INTERL REDE EXIST PVC/PEAD/FF/FC 50/100M | D28: UN | E28: 998.6 | G28: 3 | H28: 2995.8
A29: 136 | B29: 02090214 | C29: INSTAL VALVULA PVC DN 50 A 100MM, S/REP | D29: UN | E29: 247.52 | G29: 3 | H29: 742.56
A30: 139 | B30: 02090217 | C30: VERIFICAÇÃO ESTANQ REDES ADUTORA ÁGUA | D30: EQD | E30: 1624.69 | G30: 3 | H30: 4874.07
A31: EXECUÇÃO DE PAVIMENTAÇÃO - PRA
A32: 142 | B32: 02100102 | C32: LRP - PASSEIO ESPECIAL - ASSENTAMENTO DE | D32: M | E32: 108.04 | G32: 1370.31 | H32: 148048.29
A33: 143 | B33: 02100103 | C33: LPB - LEITO - ASSENTAMENTO DE REDE DE AG | D33: M | E33: 106.26 | G33: 1370.31 | H33: 145609.14
A34: 144 | B34: 02100104 | C34: REPOSIÇÃO DE CAPA ASFÁLTICA CBUQ - ASSEN | D34: M | E34: 240.23 | G34: 1370.31 | H34: 329189.57
A35: LRP-LPB - LIGAÇÃO DE ÁGUA
A36: 152 | B36: 02100301 | C36: LRP - PASSEIO CIMENTADO - LIGACAO / SUBS | D36: UN | E36: 68.89 | G36: 400 | H36: 27556
A37: 156 | B37: 02100305 | C37: LPB - LEITO - TERCO OPOSTO - LIGACAO / S | D37: UN | E37: 411.16 | G37: 400 | H37: 164464

Sheet NOTAS E DIVERGÊNCIAS
A1: NOTAS DE MONTAGEM E DIVERGÊNCIAS DE PREÇO
A3: 1) Preço 60% = ROUND(preço contratual × fator da célula H2 da aba BASE, 2 casas). Fator editável (60%).
A4: 2) CONTRATO: a planilha de balanceamento repete cada item por região (9 agrupamentos: 01-Pirituba, 02-Freguesia, 03-Santana, 04-Guarulhos, 05-F. da Rocha, 06-F. Morato, 07-Caieiras, 08-Cajamar, 09-Mairiporã) e por ano (2025/26/27). Após deduplicação: 176 serviços únicos; o preço de cada serviço é IGUAL em todas as regiões onde existe. Código exibido = agrupamento 02 (Freguesia).
A5: 3) APOSTILAMENTO 01/26: o anexo lista os mesmos 108 itens novos 9 vezes (uma por agrupamento, códigos x140xxx). Foram deduplicados: cada serviço aparece 1 vez na BASE.
A6: 4) Preço adotado p/ itens novos = coluna "NOVOS ZN" do apostilamento (preço contratual após balanceamento; ≈ P.Unit × 0,985). A coluna "P. Unit." do PDF é a referência antes do balanceamento.
A7: 5) MAIRIPORÃ (09): 96 itens novos têm preço próprio (menor) na região 09 – tabela A abaixo. Nas regiões 01 a 08 os preços são idênticos entre si.
A8: 6) CAIEIRAS (07): no anexo do apostilamento, o bloco da região 07 (códigos 714xxxx) apresenta numeração/descrição deslocada em 7 itens (tabela B) – os preços não batem com as demais regiões e aparentam ERRO DE DIAGRAMAÇÃO no PDF. Conferir com a fiscalização antes de medir esses itens na região 07.
A9: 7) Itens do contrato com descrição SAP truncada (40 caracteres) podem ter 2 preços distintos por serem serviços diferentes (ex.: LPB/LRP/REPOSIÇÃO CBUQ). Ambos foram mantidos na BASE.
A10: 8) Itens de contrato disponíveis só em algumas regiões estão sinalizados na coluna OBS. da BASE (7 casos: canteiro, planos, preservação de interferências, radar, selas eletrofusão).
A12: TABELA A – APOSTILAMENTO: PREÇOS PRÓPRIOS DA REGIÃO 09-MAIRIPORÃ
A13: CÓD. 09 | B13: DESCRIÇÃO | C13: UN | D13: PREÇO ZN 09 (R$) | E13: PREÇO 60% (R$) | F13: PREÇO DEMAIS REGIÕES (R$)
A14: 9140101 | B14: EEE COMPACTA TIPO 1 | C14: GB | D14: 647652.9 | E14: =ROUND(D14*0.6,2) -> 388591.74 | F14: 664259.38
A15: 9140102 | B15: EEE COMPACTA TIPO 2 | C15: GB | D15: 866138.21 | E15: =ROUND(D15*0.6,2) -> 519682.93 | F15: 888346.88
A16: 9140103 | B16: EEE COMPACTA TIPO 3 | C16: GB | D16: 936365.63 | E16: =ROUND(D16*0.6,2) -> 561819.38 | F16: 960375
A17: 9140104 | B17: EPAT - MINI-BOOSTER, 4CV ATÉ 50MCA | C17: GB | D17: 150957.42 | E17: =ROUND(D17*0.6,2) -> 90574.45 | F17: 154828.12
A18: 9140105 | B18: EPAT - MINI-BOOSTER, 8CV ATÉ 50MCA | C18: GB | D18: 172932.77 | E18: =ROUND(D18*0.6,2) -> 103759.66 | F18: 177366.94
A19: 9140106 | B19: EPAT - MINI-BOOSTER, 12CV ATÉ 50MCA | C19: GB | D19: 183178.42 | E19: =ROUND(D19*0.6,2) -> 109907.05 | F19: 187875.3
A20: 9140107 | B20: EPAT - MINI-BOOSTER, 15CV ATÉ 50MCA | C20: GB | D20: 198221.14 | E20: =ROUND(D20*0.6,2) -> 118932.68 | F20: 203303.73
A21: 9140108 | B21: ARMACAO EM ACO CA-50 | C21: KG | D21: 16.47 | E21: =ROUND(D21*0.6,2) -> 9.88 | F21: 16.89
A22: 9140109 | B22: ARMACAO EM ACO CA-60 | C22: KG | D22: 17.03 | E22: =ROUND(D22*0.6,2) -> 10.22 | F22: 17.46
A23: 9140110 | B23: LOCACAO REDES DE ESGOTOS (ATE D = 500MM) | C23: M | D23: 1.39 | E23: =ROUND(D23*0.6,2) -> 0.83 | F23: 1.43
A24: 9140111 | B24: LOCACAO ADUT/COL.T/INTERC.(ATE D=500MM) | C24: M | D24: 1.8 | E24: =ROUND(D24*0.6,2) -> 1.08 | F24: 1.85
A25: 9140112 | B25: LOCACAO/ACOMPANH.TOPOGR. OBRAS ESPECIAIS | C25: EQD | D25: 1364.62 | E25: =ROUND(D25*0.6,2) -> 818.77 | F25: 1399.61
... A109: 9140208 | B109: PLANO DE FURO PARA HDD | C109: M | D109: 346.43 | E109: =ROUND(D109*0.6,2) -> 207.86 | F109: 355.32
A111: TABELA B – APOSTILAMENTO: BLOCO 07-CAIEIRAS COM PREÇOS DESLOCADOS NO PDF (CONFERIR!)
A112: CÓD. 07 | B112: DESCRIÇÃO | C112: UN | D112: PREÇO ZN 07 (R$) | E112: PREÇO DEMAIS REGIÕES (R$) | F112: N. PREÇO SAP
A113: 7140206 | B113: CONST PI DE 2 A 3M S/REP | C113: UN | D113: 5541.65 | E113: 912.53 | F113: 100011908
A114: 7140207 | B114: ASSENT REDE HDD PEAD 160MM-SOLO COMUM | C114: M | D114: 251.91 | E114: 1744.22 | F114: 100012152
A115: 7140208 | B115: ASSENT REDE HDD PEAD 200MM-SOLO COMUM | C115: M | D115: 355.32 | E115: 7804 | F115: 100012153
A116: 7140209 | B116: ADIC MOB/DESMOB HDD ATÉ 225 MM- > 50 KM | C116: KM | D116: 196.88 | E116: 9455.95 | F116: 100012161
A117: 7140210 | B117: MAPEAMENTO DE INTERFERÊNCIAS PARA MND | C117: M | D117: 21.51 | E117: 5541.65 | F117: 100012163
A118: 7140211 | B118: MOB/DESMOB P/ HDD-ATÉ 225MM ATÉ 50 KM | C118: UN | D118: 7876.08 | E118: 251.91 | F118: 100012165
A119: 7140212 | B119: PLANO DE FURO PARA HDD | C119: M | D119: 24.98 | E119: 355.32 | F119: 100012168

Sheet CÓDIGOS POR REGIÃO
A1: CÓDIGOS DE CADA SERVIÇO POR AGRUPAMENTO/REGIÃO (contrato + apostilamento)
A3: DESCRIÇÃO | B3: UN | C3: PREÇO ZN (R$) | D3: 01-Pirituba | E3: 02-Freguesia | F3: 03-Santana | G3: 04-Guarulhos | H3: 05-Franco da Rocha | I3: 06-Francisco Morato | J3: 07-Caieiras | K3: 08-Cajamar | L3: 09-Mairiporã
A4: IMPLANTAÇÃO DE CANTEIRO | B4: UND | C4: 369483.97 | D4: 01010101 | E4: — | F4: — | G4: 04010101 | H4: 05010101 | I4: — | J4: — | K4: — | L4: —
A5: MANUTENÇÁO DO CANTEIRO | B5: MES | C5: 196421.07 | D5: 01010102 | E5: — | F5: — | G5: — | H5: — | I5: — | J5: — | K5: — | L5: —
A6: PLANO DE COMERCIALIZAÇÃO DE LIGAÇÕES | B6: UN | C6: 62.66 | D6: 01020101 | E6: 02010101 | F6: 03010101 | G6: 04020101 | H6: 05020101 | I6: 06010101 | J6: 07010101 | K6: 08010101 | L6: 09010101
A7: PLANO DE QUALIDADE TOTAL | B7: MES | C7: 89370.92 | D7: 01020102 | E7: 02010102 | F7: 03010102 | G7: — | H7: — | I7: — | J7: — | K7: — | L7: —
A8: INSPEÇÃO EM LIGAÇÃO DE ESGOTO - VARREDUR | B8: UN | C8: 45.34 | D8: 01020201 | E8: 02010201 | F8: 03010201 | G8: 04020201 | H8: 05020201 | I8: 06010201 | J8: 07010201 | K8: 08010201 | L8: 09010201
A9: PRE MEC OU MAN PVC 150 ATE 2,0M S/REP | B9: M | C9: 291.35 | D9: 01030101 | E9: 02020101 | F9: 03020101 | G9: 04030101 | H9: 05030101 | I9: 06020101 | J9: 07020101 | K9: 08020101 | L9: 09020101
A10: PRE PVC 150 ATE 2,7M S/REP | B10: M | C10: 408.68 | D10: 01030102 | E10: 02020102 | F10: 03020102 | G10: 04030102 | H10: 05030102 | I10: 06020102 | J10: 07020102 | K10: 08020102 | L10: 09020102
A11: PRE PVC 150 ATE 3,5M S/REP | B11: M | C11: 732.23 | D11: 01030103 | E11: 02020103 | F11: 03020103 | G11: 04030103 | H11: 05030103 | I11: 06020103 | J11: 07020103 | K11: 08020103 | L11: 09020103
A12: PRE MEC OU MAN PVC 200 ATE 2,0M S/REP | B12: M | C12: 384.35 | D12: 01030104 | E12: 02020104 | F12: 03020104 | G12: 04030104 | H12: 05030104 | I12: 06020104 | J12: 07020104 | K12: 08020104 | L12: 09020104
A13: PRE PVC 200 ATE 2,7M S/REP | B13: M | C13: 500.32 | D13: 01030105 | E13: 02020105 | F13: 03020105 | G13: 04030105 | H13: 05030105 | I13: 06020105 | J13: 07020105 | K13: 08020105 | L13: 09020105
A14: PRE PVC 200 ATE 3,5M S/REP | B14: M | C14: 1017.3 | D14: 01030106 | E14: 02020106 | F14: 03020106 | G14: 04030106 | H14: 05030106 | I14: 06020106 | J14: 07020106 | K14: 08020106 | L14: 09020106
A15: PRE PVC 300 ATE 1,5M S/REP | B15: M | C15: 420.03 | D15: 01030107 | E15: 02020107 | F15: 03020107 | G15: 04030107 | H15: 05030107 | I15: 06020107 | J15: 07020107 | K15: 08020107 | L15: 09020107
... A287: PLANO DE FURO PARA HDD | B287: M | C287: 355.32 | D287: 1140208 | E287: 2140208 | F287: 3140208 | G287: 4140208 | H287: 5140208 | I287: 6140208 | J287: 7140212 | K287: 8140208 | L287: 9140208

Sheet Quantitativos sakura
A4: ITEM | B4: COMPRIMENTO DE EXECUÇÃO EM METROS | C4: UNIDADE | D4: DN (MM) | E4: LARGURA DA VALA | F4: AREA DE LRP PAGO AO ITEM | G4: ÁREA DE LRP EXECUTADO | H4: VALOR DO ITEM | I4: VALOR DO ITEM POR ÁREA | J4: TOTAL | K4: QUANTITATIVO EM METROS | L4: OBSERVAÇÕES
A7: REP DE CAPA ASFÁLTICA TERÇO | B7: ='[2]metragem lrp'!$P$23+'[2]metragem lrp'!$P$24 -> 359.79277 | C7: M | D7: 300 | H7: ='BASE MEDIÇÃO '!$F$78 -> 114.45 | J7: =H7*B7 -> 41178.282
A8: REP DE CAPA ASFÁLTICA EIXO | B8: ='[2]metragem lrp'!$P$23+'[2]metragem lrp'!$P$24 -> 359.79277 | C8: M | D8: 300 | H8: ='BASE MEDIÇÃO '!$F$78 -> 114.45 | J8: =H8*B8 -> 41178.282
A9: REP DE CAPA ASFÁLTICA TERÇO | B9: ='[2]metragem lrp'!$P$23+'[2]metragem lrp'!$P$24 -> 359.79277 | C9: M | D9: 300 | H9: ='BASE MEDIÇÃO '!$F$78 -> 114.45 | J9: =H9*B9 -> 41178.282
A10: LPB TERÇO | B10: ='[2]metragem lrp'!$P$23+'[2]metragem lrp'!$P$24 -> 359.79277 | C10: M | D10: 300 | H10: ='BASE MEDIÇÃO '!F76 -> 118.72 | J10: =H10*B10 -> 42714.598
A11: LPB TERÇO | B11: ='[2]metragem lrp'!$P$23+'[2]metragem lrp'!$P$24 -> 359.79277 | C11: M | D11: 300 | H11: =H10 -> 118.72 | J11: =H11*B11 -> 42714.598
A12: LPB EIXO | B12: ='[2]metragem lrp'!$P$23+'[2]metragem lrp'!$P$24 -> 359.79277 | C12: M | D12: 300 | H12: =H11 -> 118.72 | J12: =H12*B12 -> 42714.598
A21: SUBTOTAL | E21: =SUM(E10:E20) -> 0 | F21: =SUM(F10:F20) -> 0 | G21: =SUM(G10:G20) -> 0 | I21: =SUM(I10:I20) -> 0 | J21: =SUM(J10:J20) -> 128143.79 | K21: =SUM(K10:K20) -> 0 | L21: =SUM(L10:L20) -> 0
A27: SUBTOTAL | E27: =SUM(E23:E26) -> 0 | F27: =SUM(F23:F26) -> 0 | G27: =SUM(G23:G26) -> 0 | I27: =SUM(I23:I26) -> 0 | J27: =SUM(J23:J26) -> 0 | K27: =SUM(K23:K26) -> 0 | L27: =SUM(L23:L26) -> 0
A28: TOTAL GERAL | E28: =E21+E27 -> 0 | F28: =F21+F27 -> 0 | G28: =G21+G27 -> 0 | I28: =I21+I27 -> 0 | J28: =J21+J27 -> 128143.79 | K28: =K21+K27 -> 0 | L28: =L21+L27 -> 0

Sheet Quantitativosredeboi
A1: QUANTITATIVOS EXECUTADOS – FREGUESIA (Comunidade Boi Malhado) – REDE + ELEMENTOS PONTUAIS
A2: Contrato 13.546-25 – Consórcio Saneamento ZN | Medição 10 | Junho/2026 | Fonte: folhas de cadastro Sabesp (FREGUESIA.zip)
A4: FOLHA | B4: LOCAL (LOGRADOURO) | C4: MATERIAL / DN | D4: MÉT. | E4: EXTENSÃO EXECUTADA (m) | F4: EXTENSÃO ABANDONADA (m) | G4: B.A (un) | H4: CONEXÃO (un) | I4: PI NOVO (un) | J4: PV NOVO (un) | K4: INTERLIG. POÇO EXIST. (un) | L4: OBSERVAÇÕES
A5: REDE DE ÁGUA (Fl. 18–27) – PEAD DE 63 MND
A6: Fl. 18 | B6: Tv. Flor de Cajú / Tv. 1º de Abril / Tv. Pingo de Mel | C6: PEAD DE 63 | D6: MND | E6: 90.08 | F6: 109.95 | G6: 6 | H6: 0 | I6: 0 | J6: 0 | K6: 0 | L6: Abandonados 109,95 m de rede 75 mm FF
A7: Fl. 19 | B7: Rua Vaness Atalanta (Terço Terra) | C7: PEAD DE 63 | D7: MND | E7: 137.5 | F7: 0 | G7: 6 | H7: 0 | I7: 0 | J7: 0 | K7: 0
A8: Fl. 20 | B8: Rua Um (Terço Terra) | C8: PEAD DE 63 | D8: MND | E8: 318.66 | F8: 0 | G8: 2 | H8: 0 | I8: 0 | J8: 0 | K8: 0
A9: Fl. 21 | B9: Rua Vaness Atalanta (Terço Terra) | C9: PEAD DE 63 | D9: MND | E9: 48.65 | F9: 0 | G9: 5 | H9: 0 | I9: 0 | J9: 0 | K9: 0
A10: Fl. 22 | B10: Rua Eng. Paulo Sergio / Rua Vaness Atalanta | C10: PEAD DE 63 | D10: MND | E10: 112.68 | F10: 0 | G10: 5 | H10: 0 | I10: 0 | J10: 0 | K10: 0
A11: Fl. 23 | B11: Rua Santa Rosa do Tocantins (Terço Terra) | C11: PEAD DE 63 | D11: MND | E11: 195.6 | F11: 0 | G11: 2 | H11: 0 | I11: 0 | J11: 0 | K11: 0
A12: Fl. 24 | B12: Rua Vitoria da Conquista / Rua Sem Nome | C12: PEAD DE 63 | D12: MND | E12: 141.27 | F12: 0 | G12: 3 | H12: 0 | I12: 0 | J12: 0 | K12: 0
A13: Fl. 25 | B13: Rua Sem Nome (Terço Terra) | C13: PEAD DE 63 | D13: MND | E13: 94.71 | F13: 0 | G13: 2 | H13: 2 | I13: 0 | J13: 0 | K13: 0 | L13: 2 Tê PEAD DN 63 mm (prof. 1,00 m)
A14: Fl. 26 | B14: Rua Sem Nome (Terço Terra) | C14: PEAD DE 63 | D14: MND | E14: 199.83 | F14: 0 | G14: 2 | H14: 1 | I14: 0 | J14: 0 | K14: 0 | L14: 1 Luva PEAD DN 63 mm (prof. 1,00 m)
A15: Fl. 27 | B15: Rua Vitoria da Conquista (Terço Terra) | C15: PEAD DE 63 | D15: MND | E15: 31.33 | F15: 0 | G15: 2 | H15: 0 | I15: 0 | J15: 0 | K15: 0
A16: SUBTOTAL | E16: =SUM(E6:E15) -> 1370.31 | F16: =SUM(F6:F15) -> 109.95 | G16: =SUM(G6:G15) -> 35 | H16: =SUM(H6:H15) -> 3 | I16: =SUM(I6:I15) -> 0 | J16: =SUM(J6:J15) -> 0 | K16: =SUM(K6:K15) -> 0
A17: REDE DE ESGOTO (Fl. 51–54) – PVC DN 200 VCA
A18: Fl. 51 | B18: Tv. Flor de Cajú / Tv. 1º de Abril / Tv. Pingo de Mel | C18: PVC DN 200 | D18: VCA | E18: 101.1 | F18: 101 | G18: 0 | H18: 0 | I18: 3 | J18: 0 | K18: 3 | L18: PIs 132/133/134 (prof 1,50/0,90/0,95); 3 interlig. em PV existente (prof 2,20/2,15/2,20); aband. 101 m de 150 MBV
A19: Fl. 52 | B19: Tv. dos Pioneiros / Rua Tocantins | C19: PVC DN 200 | D19: VCA | E19: 49.92 | F19: 0 | G19: 0 | H19: 0 | I19: 6 | J19: 0 | K19: 1 | L19: PIs 135 a 140 (prof 0,50–0,60); interlig. em PI existente (prof 0,60)
A20: Fl. 53 | B20: Rua Tocantins (Eixo / Leito Terra) | C20: PVC DN 200 | D20: VCA | E20: 138.67 | F20: 0 | G20: 0 | H20: 0 | I20: 4 | J20: 0 | K20: 0 | L20: PIs 141 a 144 (prof 0,50–1,00)
A21: Fl. 54 | B21: Rua Bahia / Tv. Sem Nome (Eixo Terra) | C21: PVC DN 200 | D21: VCA | E21: 106.34 | F21: 0 | G21: 0 | H21: 0 | I21: 2 | J21: 2 | K21: 0 | L21: PIs 145/146 (prof 0,60); PVs 36/37 (prof 0,80/0,70)
A22: SUBTOTAL | E22: =SUM(E18:E21) -> 396.03 | F22: =SUM(F18:F21) -> 101 | G22: =SUM(G18:G21) -> 0 | H22: =SUM(H18:H21) -> 0 | I22: =SUM(I18:I21) -> 15 | J22: =SUM(J18:J21) -> 2 | K22: =SUM(K18:K21) -> 4
A23: TOTAL GERAL | E23: =E16+E22 -> 1766.34 | F23: =F16+F22 -> 210.95 | G23: =G16+G22 -> 35 | H23: =H16+H22 -> 3 | I23: =I16+I22 -> 15 | J23: =J16+J22 -> 2 | K23: =K16+K22 -> 4
A25: LEGENDA: B.A = boca de ataque/recepção do MND (poço de serviço, prof. 1,00 m) – símbolo dos pontos com coordenadas N/E nas folhas de água. PI/PV NOVO = poços executados (círculo vermelho ⊗ = PI; círculo aberto = PV). INTERLIG. = chegada da rede nova em poço EXISTENTE (símbolo quarteado preto).
A26: VÁLVULAS/REGISTROS: não consta nenhuma válvula, registro ou hidrante nas 14 folhas desta medição (rede de água é prolongamento PEAD 63 ponta a ponta, sem aparelhos).
A27: ÁGUA: interligações NÃO executadas – nota em todas as folhas: 'as interligações entrarão na próxima medição'. Conexões executadas: 2 Tês + 1 Luva PEAD DN 63 (Fl. 25/26).
A28: ESGOTO: PIs novos nº 132 a 146 (numeração contínua, 15 un), todos com prof. ≤ 1,60 m → enquadram em CONSTPI ATÉ 1,6M S/REP. PVs novos 36 e 37 (prof. 0,80/0,70 m) → CPV ATÉ 2M S/REP.
A29: Extensões conforme selo de cada folha; somas dos trechos conferidas contra o selo.

Sheet Quantitativos lpb boi
A4: ITEM | B4: COMPRIMENTO DE EXECUÇÃO EM METROS | C4: UNIDADE | D4: DN (MM) | E4: LARGURA DA VALA | F4: AREA DE LRP PAGO AO ITEM | G4: ÁREA DE LRP EXECUTADO | H4: VALOR DO ITEM | I4: VALOR DO ITEM POR ÁREA | J4: TOTAL | K4: QUANTITATIVO EM METROS | L4: OBSERVAÇÕES
A6: LPB TERÇO | B6: 460.64419 | C6: M | D6: 300 | H6: ='BASE MEDIÇÃO '!F75 -> 113.32 | J6: =H6*B6 -> 52200.2
A7: LPB EIXO | B7: 460.64419 | C7: M | D7: 300 | H7: 113.32 | J7: =H7*B7 -> 52200.2
A8: LPB TERÇO | B8: 460.64419 | C8: M | D8: 300 | H8: 113.32 | J8: =H8*B8 -> 52200.2
A17: SUBTOTAL | E17: =SUM(E6:E16) -> 0 | F17: =SUM(F6:F16) -> 0 | G17: =SUM(G6:G16) -> 0 | I17: =SUM(I6:I16) -> 0 | J17: =SUM(J6:J16) -> 156600.6 | K17: =SUM(K6:K16) -> 0 | L17: =SUM(L6:L16) -> 0
A23: SUBTOTAL | E23: =SUM(E19:E22) -> 0 | F23: =SUM(F19:F22) -> 0 | G23: =SUM(G19:G22) -> 0 | I23: =SUM(I19:I22) -> 0 | J23: =SUM(J19:J22) -> 0 | K23: =SUM(K19:K22) -> 0 | L23: =SUM(L19:L22) -> 0
A24: TOTAL GERAL | E24: =E17+E23 -> 0 | F24: =F17+F23 -> 0 | G24: =G17+G23 -> 0 | I24: =I17+I23 -> 0 | J24: =J17+J23 -> 156600.6 | K24: =K17+K23 -> 0 | L24: =L17+L23 -> 0
