Workbook

Sheet LEIA-ME
B2: FLUXO DE CAIXA PROJETADO — BERTIOGA + SANTOS (GLOBAL)
B3: Gerado em 25/08/2026 a partir de: Fluxo Trimestral Obra.xlsx (custos e tickets) · Adiantamento Bertioga.xlsx (mobilização) · tabelas de preços GJ/BT e Santos II · método do modelo Custo_Equipe_Rede_Esgoto (defasagem de recebimento e capital inicial).
B5: COMO USAR
B6: 1. Tudo se controla na aba PREMISSAS: cenário de produção (MÍNIMA / MÉDIA / BOA / ÓTIMA), defasagem de recebimento, imposto da nota (22%), tickets médios e mix água/esgoto de Santos.
B7: 2. Os custos vivem nas abas CUSTOS BERTIOGA e CUSTOS SANTOS. A seção 7 das PREMISSAS define QUEM PAGA cada bloco (consórcio × WCR) e se ele desconta da medição.
B8: 3. FCP SEMANAL e FCP MENSAL = FINANCEIRO (caixa da WCR). ECONÔMICO = margem real do contrato por competência. VIABILIDADE = produção necessária (visão econômica).
B9: 4. VIABILIDADE mostra quantos serviços por dia cada cidade precisa entregar em cada cenário. A aba AUX só faz conta — não precisa mexer.
B10: 5. Toda semana, lance a PRODUÇÃO REALIZADA na seção PLANEJADO × REALIZADO do FCP SEMANAL (células verdes). Medição, recebimento, FCP MENSAL e ECONÔMICO atualizam sozinhos; semana sem lançamento usa o planejado.
B12: LEGENDA DE CORES
B13: AZUL = valor editável (premissa) · PRETO = fórmula · VERDE = puxa de outra aba · FUNDO AMARELO = premissa crítica — confirme antes de decidir.
B15: Custo mensal GLOBAL da operação (todos os custos)
B16: Custos bancados pelo consórcio (descontados da medição) | C16: =PREMISSAS!$C$61 -> 466854.32
B17: Custos pagos pela WCR (caixa próprio) | C17: =PREMISSAS!$C$56 -> 40000
B18: Resultado econômico no horizonte (margem real) | C18: =ECONÔMICO!R17 -> 1172835.2
B19: Pior ponto do trimestre no caixa da WCR (FCP SEMANAL) | C19: ='FCP SEMANAL'!C42 -> -138227.95
B20: CAPITAL RECOMENDADO — WCR (necessidade máxima + contingência) | C20: ='FCP MENSAL'!C44 -> 204962.14
B22: AVISOS IMPORTANTES
B23: • A produção MÍNIMA aqui é maior que na sua planilha anterior: lá o empate não descontava o imposto da nota (22%). Ex.: Bertioga 8,98 → 11,5 serviços/dia. A linha cinza da VIABILIDADE mostra a referência antiga.
B24: • A medição fecha no fim do mês e é paga com a defasagem da PREMISSAS!C9. Até o primeiro recebimento a obra roda no caixa próprio — esse é o número do CAPITAL RECOMENDADO.
B25: • O kit ferramenta (R$ 28.800 por cidade) segue como custo MENSAL, igual à sua planilha. Se for compra única, mova para a mobilização nas PREMISSAS — o custo mensal cai e a viabilidade melhora.
B26: • Os preços de Santos foram transcritos de fotos; itens com dígito cortado estão marcados 'conferir' na aba PREÇOS SANTOS.
B27: • O 1º mês entra proporcional aos dias de obra (início em PREMISSAS!C6). A medição do 1º mês é parcial.
B28: • O pior ponto do caixa e o CAPITAL RECOMENDADO recalculam sozinhos quando você muda a defasagem, o cenário ou os custos nas PREMISSAS.
B29: • ECONÔMICO × FINANCEIRO: o consórcio banca folha, engenheiro e estrutura e DESCONTA da medição; a WCR paga só os indiretos e recebe o saldo. O ECONÔMICO mostra a margem real; o FINANCEIRO mostra o caixa da WCR. No 1º mês o desconto pode superar a medição parcial (líquido negativo = saldo devido ao consórcio, compensa em seguida).
B30: • Base do imposto (PREMISSAS C48): assumi 22% sobre a MEDIÇÃO CHEIA (conservador). Se a nota da WCR for só do valor líquido do desconto, troque para LÍQUIDA DO DESCONTO — entra bem mais caixa. Confirme com o contador.

Sheet PREMISSAS
B2: FLUXO DE CAIXA PROJETADO — BERTIOGA + SANTOS · PREMISSAS
B3: AZUL = valor editável · PRETO = fórmula · VERDE = puxa de outra aba · FUNDO AMARELO = premissa crítica
B5: 1. CALENDÁRIO E CONTRATO
B6: Início da obra / Semana 1 do fluxo | C6: 46258 | D6: data | E6: Segunda-feira. Primeira coluna do FCP SEMANAL.
B7: Fim da operação projetada | C7: 46599 | D7: data | E7: Último dia de obra no FCP MENSAL (~12 meses de operação). Edite para esticar ou encurtar.
B8: Dias por mês (convenção de rateio) | C8: 30 | D8: dias | E8: Mesma convenção da sua planilha: diário = mensal ÷ 30 · semana = 7 dias corridos.
B9: Defasagem de recebimento | C9: 20 | D9: dias | E9: A medição fecha no último dia do mês e é paga N dias depois (ex.: com N=20, agosto fecha 31/08 e paga 20/09).
B10: Imposto da nota | C10: 0.22 | D10: % | E10: Retenções + tributos sobre a medição bruta, pagos na data do recebimento — premissa da sua aba Custos.
B12: 2. CENÁRIO DE PRODUÇÃO
B13: Cenário adotado no fluxo | C13: ÓTIMA | D13: — | E13: Escolha: MÍNIMA, MÉDIA, BOA ou ÓTIMA. Todo o fluxo recalcula. MÍNIMA = empate real (cobre custo + imposto).
A14: MÍNIMA | B14: Margem do cenário MÍNIMA | C14: 0 | D14: % | E14: Empate: receita líquida = custo. Não sobra nada (nem recupera a mobilização).
A15: MÉDIA | B15: Margem do cenário MÉDIA | C15: 0.1 | D15: % | E15: Custo + 10% de margem.
A16: BOA | B16: Margem do cenário BOA | C16: 0.15 | D16: % | E16: Custo + 15% de margem.
A17: ÓTIMA | B17: Margem do cenário ÓTIMA | C17: 0.2 | D17: % | E17: Custo + 20% de margem.
B18: Margem do cenário adotado | C18: =INDEX(C14:C17,MATCH(C13,A14:A17,0)) -> 0.2 | D18: % | E18: Fórmula — não editar.
B20: 3. PREÇOS MÉDIOS POR SERVIÇO (ticket)
B21: Bertioga — ticket médio por serviço | C21: 881.2 | D21: R$/un | E21: Média adotada por você no Fluxo Trimestral (aba Custos). Tabela do contrato: aba PREÇOS BERTIOGA.
B22: Santos — ticket água | C22: 821.25 | D22: R$/un | E22: Idem. Tabela do contrato: aba PREÇOS SANTOS (coluna K50).
B23: Santos — ticket esgoto | C23: 1856.4 | D23: R$/un | E23: Idem.
B24: Santos — % dos serviços que são esgoto | C24: 0.5 | D24: % | E24: Mix da carteira. Muda o ticket ponderado e a produção necessária em unidades.
B25: Santos — ticket médio ponderado | C25: =C23*C24+C22*(1-C24) -> 1338.825 | D25: R$/un | E25: Fórmula — não editar.
B27: 4. CUSTOS MENSAIS (vêm das abas de custos)
B28: Bertioga — custo mensal total | C28: ='CUSTOS BERTIOGA'!F36 -> 237292.84 | D28: R$/mês | E28: Equipe + estrutura + engenheiro + indiretos. Detalhe na aba CUSTOS BERTIOGA.
B29: Santos — custo mensal total | C29: ='CUSTOS SANTOS'!F37 -> 269561.48 | D29: R$/mês | E29: Detalhe na aba CUSTOS SANTOS.
B30: GLOBAL — custo mensal total | C30: =C28+C29 -> 506854.32 | D30: R$/mês
B32: 5. MOBILIZAÇÃO — desembolsos iniciais (coluna “Anterior”)
B33: Bertioga — custos iniciais (Adiantamento) | C33: 13360 | D33: R$ | E33: 50% da mobilização total (carros eng.+empreiteiro 6.800 · alojamento 13.500 · casa 3.000 · alimentação ago+set 3.420 = 26.720), dividida meio a meio entre as cidades — como no FCP SEMANAL.
B34: Santos — custos iniciais | C34: 13360 | D34: R$ | E34: 50% da mobilização total, como no FCP SEMANAL.
B35: Total mobilização | C35: =SUM(C33:C34) -> 26720 | D35: R$
B37: 6. CAPITAL E RISCO
B38: Contingência sobre a necessidade máxima de caixa | C38: 0.15 | D38: % | E38: Atraso de medição, chuva, quebra, retrabalho. 15% é o mínimo prudente (modelo Custo_Equipe).
B39: Fator de custos do 1º mês (fração do custo mensal) | C39: 0.5 | D39: % | E39: Espelha o 0,5 do FCP SEMANAL para agosto (obra começa dia 24). Usado no FCP MENSAL e na sensibilidade.
B41: 7. QUEM PAGA O QUÊ — regime com o consórcio
B42: Folha das equipes — quem paga | C42: CONSÓRCIO | E42: Salários + encargos + benefícios das equipes.
B43: Engenheiro — quem paga | C43: CONSÓRCIO | E43: R$ 13.000/mês por cidade.
B44: Estrutura e locações — quem paga | C44: CONSÓRCIO | E44: Carros, caminhões, HR, alojamento, equipamentos, kit ferramenta.
B45: Custos indiretos — quem paga | C45: WCR | E45: R$ 20.000/mês por cidade — sai do caixa da WCR.
B46: Mobilização — quem paga | C46: CONSÓRCIO | E46: Adiantamento Bertioga (R$ 26.720) foi bancado pelo consórcio.
B47: O consórcio desconta da medição o que ele paga? | C47: SIM | E47: SIM = o que ele banca é abatido do valor que a WCR recebe.
B48: Base do imposto da nota | C48: MEDIÇÃO CHEIA | E48: MEDIÇÃO CHEIA = 22% sobre a medição toda (conservador). LÍQUIDA DO DESCONTO = 22% só sobre o que a WCR efetivamente fatura. Confirme com o contador.
...

Sheet FCP SEMANAL
B2: FCP SEMANAL — FINANCEIRO (CAIXA DA WCR)
B3: Só o que passa pela conta da WCR. Recebimento bruto nas semanas que você definiu (S1→S3, S2–S6→S7, S7–S11→S12); na mesma semana entra o DESCONTO do consórcio (folha, engenheiro, estrutura que ele banca) e o imposto. A WCR paga do bolso só os custos indiretos (dia 20 do mês seguinte). Visão de margem: aba ECONÔMICO.
N4: Cenário: | O4: =PREMISSAS!$C$13 -> ÓTIMA
C5: Anterior | D5: S1 | E5: S2 | F5: S3 | G5: S4 | H5: S5 | I5: S6 | J5: S7 | K5: S8 | L5: S9 | M5: S10 | N5: S11 | O5: S12 | P5: TOTAL
B6: início | D6: =PREMISSAS!$C$6 -> 46258 | E6: =D6+7 -> 46265 | F6: =E6+7 -> 46272 | G6: =F6+7 -> 46279 | H6: =G6+7 -> 46286 | I6: =H6+7 -> 46293 | J6: =I6+7 -> 46300 | K6: =J6+7 -> 46307 | L6: =K6+7 -> 46314 | ... O6: =N6+7 -> 46335
D7: a | E7: a | F7: a | G7: a | H7: a | I7: a | J7: a | K7: a | L7: a | M7: a | N7: a | O7: a
B8: fim | D8: =D6+6 -> 46264 | E8: =E6+6 -> 46271 | F8: =F6+6 -> 46278 | G8: =G6+6 -> 46285 | H8: =H6+6 -> 46292 | I8: =I6+6 -> 46299 | J8: =J6+6 -> 46306 | K8: =K6+6 -> 46313 | ... O8: =O6+6 -> 46341
B10: BERTIOGA
B11: Produção prevista (un) | D11: =PREMISSAS!$C$28*(1+PREMISSAS!$C$18)/(1-PREMISSAS!$C$10)/PREMISSAS!$C$21*7/PREMISSAS!$C$8 -> 96.665961 | E11: =PREMISSAS!$C$28*(1+PREMISSAS!$C$18)/(1-PREMISSAS!$C$10)/PREMISSAS!$C$21*7/PREMISSAS!$C$8 -> 96.665961 | F11: =PREMISSAS!$C$28*(1+PREMISSAS!$C$18)/(1-PREMISSAS!$C$10)/PREMISSAS!$C$21*7/PREMISSAS!$C$8 -> 96.665961 | G11: =PREMISSAS!$C$28*(1+PREMISSAS!$C$18)/(1-PREMISSAS!$C$10)/PREMISSAS!$C$21*7/PREMISSAS!$C$8 -> 96.665961 | H11: =PREMISSAS!$C$28*(1+PREMISSAS!$C$18)/(1-PREMISSAS!$C$10)/PREMISSAS!$C$21*7/PREMISSAS!$C$8 -> 96.665961 | I11: =PREMISSAS!$C$28*(1+PREMISSAS!$C$18)/(1-PREMISSAS!$C$10)/PREMISSAS!$C$21*7/PREMISSAS!$C$8 -> 96.665961 | J11: =PREMISSAS!$C$28*(1+PREMISSAS!$C$18)/(1-PREMISSAS!$C$10)/PREMISSAS!$C$21*7/PREMISSAS!$C$8 -> 96.665961 | K11: =PREMISSAS!$C$28*(1+PREMISSAS!$C$18)/(1-PREMISSAS!$C$10)/PREMISSAS!$C$21*7/PREMISSAS!$C$8 -> 96.665961 | ... O11: =PREMISSAS!$C$28*(1+PREMISSAS!$C$18)/(1-PREMISSAS!$C$10)/PREMISSAS!$C$21*7/PREMISSAS!$C$8 -> 96.665961 | P11: =SUM(C11:O11) -> 1159.9915
B12: Medição do período (REALIZADA se lançada; senão prevista) | D12: =IF(D$45<>"",D$45,D11)*PREMISSAS!$C$21 -> 85182.045 | E12: =IF(E$45<>"",E$45,E11)*PREMISSAS!$C$21 -> 85182.045 | F12: =IF(F$45<>"",F$45,F11)*PREMISSAS!$C$21 -> 85182.045 | G12: =IF(G$45<>"",G$45,G11)*PREMISSAS!$C$21 -> 85182.045 | H12: =IF(H$45<>"",H$45,H11)*PREMISSAS!$C$21 -> 85182.045 | I12: =IF(I$45<>"",I$45,I11)*PREMISSAS!$C$21 -> 85182.045 | J12: =IF(J$45<>"",J$45,J11)*PREMISSAS!$C$21 -> 85182.045 | K12: =IF(K$45<>"",K$45,K11)*PREMISSAS!$C$21 -> 85182.045 | ... O12: =IF(O$45<>"",O$45,O11)*PREMISSAS!$C$21 -> 85182.045 | P12: =SUM(C12:O12) -> 1022184.5
B13: (A) RECEBIMENTO BRUTO | C13: 0 | D13: =SUMPRODUCT((AUX!$C$8:$Q$8>=D$6)*(AUX!$C$8:$Q$8<=D$8)*AUX!$C$5:$Q$5) -> 0 | E13: =SUMPRODUCT((AUX!$C$8:$Q$8>=E$6)*(AUX!$C$8:$Q$8<=E$8)*AUX!$C$5:$Q$5) -> 0 | F13: =D12 -> 85182.045 | J13: =E12+F12+G12+H12+I12 -> 425910.23 | K13: =SUMPRODUCT((AUX!$C$8:$Q$8>=K$6)*(AUX!$C$8:$Q$8<=K$8)*AUX!$C$5:$Q$5) -> 0 | M13: =SUMPRODUCT((AUX!$C$8:$Q$8>=M$6)*(AUX!$C$8:$Q$8<=M$8)*AUX!$C$5:$Q$5) -> 0 | N13: =SUMPRODUCT((AUX!$C$8:$Q$8>=N$6)*(AUX!$C$8:$Q$8<=N$8)*AUX!$C$5:$Q$5) -> 0 | O13: =J12+K12+L12+M12+N12 -> 425910.23 | P13: =SUM(C13:O13) -> 937002.5
B14: (–) Imposto da nota | C14: =IF(PREMISSAS!$C$48="MEDIÇÃO CHEIA",C13,MAX(0,C13-C15))*PREMISSAS!$C$10 -> 0 | D14: =IF(PREMISSAS!$C$48="MEDIÇÃO CHEIA",D13,MAX(0,D13-D15))*PREMISSAS!$C$10 -> 0 | E14: =IF(PREMISSAS!$C$48="MEDIÇÃO CHEIA",E13,MAX(0,E13-E15))*PREMISSAS!$C$10 -> 0 | F14: =IF(PREMISSAS!$C$48="MEDIÇÃO CHEIA",F13,MAX(0,F13-F15))*PREMISSAS!$C$10 -> 18740.05 | G14: =IF(PREMISSAS!$C$48="MEDIÇÃO CHEIA",G13,MAX(0,G13-G15))*PREMISSAS!$C$10 -> 0 | H14: =IF(PREMISSAS!$C$48="MEDIÇÃO CHEIA",H13,MAX(0,H13-H15))*PREMISSAS!$C$10 -> 0 | I14: =IF(PREMISSAS!$C$48="MEDIÇÃO CHEIA",I13,MAX(0,I13-I15))*PREMISSAS!$C$10 -> 0 | J14: =IF(PREMISSAS!$C$48="MEDIÇÃO CHEIA",J13,MAX(0,J13-J15))*PREMISSAS!$C$10 -> 93700.25 | ... O14: =IF(PREMISSAS!$C$48="MEDIÇÃO CHEIA",O13,MAX(0,O13-O15))*PREMISSAS!$C$10 -> 93700.25 | P14: =SUM(C14:O14) -> 206140.55
B15: (–) Desconto do consórcio (custos que ele banca) | C15: 0 | D15: 0 | E15: 0 | F15: =PREMISSAS!$C$59*PREMISSAS!$C$39+PREMISSAS!$C$58*0.5 -> 122006.42 | G15: 0 | H15: 0 | I15: 0 | J15: =PREMISSAS!$C$59 -> 217292.84 | K15: 0 | L15: 0 | M15: 0 | N15: 0 | O15: =PREMISSAS!$C$59 -> 217292.84 | P15: =SUM(C15:O15) -> 556592.1
B16: (–) Custos pagos pela WCR (indiretos) | C16: 0 | D16: 0 | E16: 0 | F16: 0 | G16: =PREMISSAS!$C$54*PREMISSAS!$C$39 -> 10000 | H16: 0 | I16: 0 | J16: 0 | K16: 0 | L16: =PREMISSAS!$C$54 -> 20000 | M16: 0 | N16: 0 | O16: 0 | P16: =SUM(C16:O16) -> 30000
B17: (–) Outros desembolsos da WCR (edite se houver) | C17: 0 | D17: 0 | E17: 0 | F17: 0 | G17: 0 | H17: 0 | I17: 0 | J17: 0 | K17: 0 | L17: 0 | M17: 0 | N17: 0 | O17: 0 | P17: =SUM(C17:O17) -> 0
B18: (–) Mobilização paga pela WCR | C18: =PREMISSAS!$C$57*0.5 -> 0 | D18: 0 | E18: 0 | F18: 0 | G18: 0 | H18: 0 | I18: 0 | J18: 0 | K18: 0 | L18: 0 | M18: 0 | N18: 0 | O18: 0 | P18: =SUM(C18:O18) -> 0
B19: (B) TOTAL DE DESPESAS | C19: =SUM(C14:C18) -> 0 | D19: =SUM(D14:D18) -> 0 | E19: =SUM(E14:E18) -> 0 | F19: =SUM(F14:F18) -> 140746.47 | G19: =SUM(G14:G18) -> 10000 | H19: =SUM(H14:H18) -> 0 | I19: =SUM(I14:I18) -> 0 | J19: =SUM(J14:J18) -> 310993.09 | ... O19: =SUM(O14:O18) -> 310993.09 | P19: =SUM(C19:O19) -> 792732.65
B20: SALDO DO PERÍODO (A–B) | C20: =C13-C19 -> 0 | D20: =D13-D19 -> 0 | E20: =E13-E19 -> 0 | F20: =F13-F19 -> -55564.425 | G20: =G13-G19 -> -10000 | H20: =H13-H19 -> 0 | I20: =I13-I19 -> 0 | J20: =J13-J19 -> 114917.14 | ... O20: =O13-O19 -> 114917.14 | P20: =SUM(C20:O20) -> 144269.85
B21: SALDO ACUMULADO | C21: =C20 -> 0 | D21: =C21+D20 -> 0 | E21: =D21+E20 -> 0 | F21: =E21+F20 -> -55564.425 | G21: =F21+G20 -> -65564.425 | H21: =G21+H20 -> -65564.425 | I21: =H21+I20 -> -65564.425 | J21: =I21+J20 -> 49352.711 | K21: =J21+K20 -> 49352.711 | ... O21: =N21+O20 -> 144269.85 | P21: =O21 -> 144269.85
B23: SANTOS
B24: Produção prevista (un) | D24: =PREMISSAS!$C$29*(1+PREMISSAS!$C$18)/(1-PREMISSAS!$C$10)/PREMISSAS!$C$25*7/PREMISSAS!$C$8 -> 72.276556 | E24: =PREMISSAS!$C$29*(1+PREMISSAS!$C$18)/(1-PREMISSAS!$C$10)/PREMISSAS!$C$25*7/PREMISSAS!$C$8 -> 72.276556 | F24: =PREMISSAS!$C$29*(1+PREMISSAS!$C$18)/(1-PREMISSAS!$C$10)/PREMISSAS!$C$25*7/PREMISSAS!$C$8 -> 72.276556 | G24: =PREMISSAS!$C$29*(1+PREMISSAS!$C$18)/(1-PREMISSAS!$C$10)/PREMISSAS!$C$25*7/PREMISSAS!$C$8 -> 72.276556 | H24: =PREMISSAS!$C$29*(1+PREMISSAS!$C$18)/(1-PREMISSAS!$C$10)/PREMISSAS!$C$25*7/PREMISSAS!$C$8 -> 72.276556 | I24: =PREMISSAS!$C$29*(1+PREMISSAS!$C$18)/(1-PREMISSAS!$C$10)/PREMISSAS!$C$25*7/PREMISSAS!$C$8 -> 72.276556 | J24: =PREMISSAS!$C$29*(1+PREMISSAS!$C$18)/(1-PREMISSAS!$C$10)/PREMISSAS!$C$25*7/PREMISSAS!$C$8 -> 72.276556 | K24: =PREMISSAS!$C$29*(1+PREMISSAS!$C$18)/(1-PREMISSAS!$C$10)/PREMISSAS!$C$25*7/PREMISSAS!$C$8 -> 72.276556 | ... O24: =PREMISSAS!$C$29*(1+PREMISSAS!$C$18)/(1-PREMISSAS!$C$10)/PREMISSAS!$C$25*7/PREMISSAS!$C$8 -> 72.276556 | P24: =SUM(C24:O24) -> 867.31867
B25: Medição do período (REALIZADA se lançada; senão prevista) | D25: =IF(D$47<>"",D$47,D24)*PREMISSAS!$C$25 -> 96765.659 | E25: =IF(E$47<>"",E$47,E24)*PREMISSAS!$C$25 -> 96765.659 | F25: =IF(F$47<>"",F$47,F24)*PREMISSAS!$C$25 -> 96765.659 | G25: =IF(G$47<>"",G$47,G24)*PREMISSAS!$C$25 -> 96765.659 | H25: =IF(H$47<>"",H$47,H24)*PREMISSAS!$C$25 -> 96765.659 | I25: =IF(I$47<>"",I$47,I24)*PREMISSAS!$C$25 -> 96765.659 | J25: =IF(J$47<>"",J$47,J24)*PREMISSAS!$C$25 -> 96765.659 | K25: =IF(K$47<>"",K$47,K24)*PREMISSAS!$C$25 -> 96765.659 | ... O25: =IF(O$47<>"",O$47,O24)*PREMISSAS!$C$25 -> 96765.659 | P25: =SUM(C25:O25) -> 1161187.9
B26: (A) RECEBIMENTO BRUTO | C26: 0 | D26: =SUMPRODUCT((AUX!$C$8:$Q$8>=D$6)*(AUX!$C$8:$Q$8<=D$8)*AUX!$C$6:$Q$6) -> 0 | E26: =SUMPRODUCT((AUX!$C$8:$Q$8>=E$6)*(AUX!$C$8:$Q$8<=E$8)*AUX!$C$6:$Q$6) -> 0 | F26: =D25 -> 96765.659 | H26: =SUMPRODUCT((AUX!$C$8:$Q$8>=H$6)*(AUX!$C$8:$Q$8<=H$8)*AUX!$C$6:$Q$6) -> 0 | I26: {=SUMPRODUCT((AUX!$C$8:$Q$8>=I$6)*(AUX!$C$8:$Q$8<=I$8)*AUX!$C$6:$Q$6)} -> 0 | J26: =E25+F25+G25+H25+I25 -> 483828.3 | K26: {=SUMPRODUCT((AUX!$C$8:$Q$8>=K$6)*(AUX!$C$8:$Q$8<=K$8)*AUX!$C$6:$Q$6)} -> 0 | M26: =SUMPRODUCT((AUX!$C$8:$Q$8>=M$6)*(AUX!$C$8:$Q$8<=M$8)*AUX!$C$6:$Q$6) -> 0 | N26: =SUMPRODUCT((AUX!$C$8:$Q$8>=N$6)*(AUX!$C$8:$Q$8<=N$8)*AUX!$C$6:$Q$6) -> 0 | O26: =J25+K25+L25+M25+N25 -> 483828.3 | P26: =SUM(C26:O26) -> 1064422.3
B27: (–) Imposto da nota | C27: =IF(PREMISSAS!$C$48="MEDIÇÃO CHEIA",C26,MAX(0,C26-C28))*PREMISSAS!$C$10 -> 0 | D27: =IF(PREMISSAS!$C$48="MEDIÇÃO CHEIA",D26,MAX(0,D26-D28))*PREMISSAS!$C$10 -> 0 | E27: =IF(PREMISSAS!$C$48="MEDIÇÃO CHEIA",E26,MAX(0,E26-E28))*PREMISSAS!$C$10 -> 0 | F27: =IF(PREMISSAS!$C$48="MEDIÇÃO CHEIA",F26,MAX(0,F26-F28))*PREMISSAS!$C$10 -> 21288.445 | G27: =IF(PREMISSAS!$C$48="MEDIÇÃO CHEIA",G26,MAX(0,G26-G28))*PREMISSAS!$C$10 -> 0 | H27: =IF(PREMISSAS!$C$48="MEDIÇÃO CHEIA",H26,MAX(0,H26-H28))*PREMISSAS!$C$10 -> 0 | I27: =IF(PREMISSAS!$C$48="MEDIÇÃO CHEIA",I26,MAX(0,I26-I28))*PREMISSAS!$C$10 -> 0 | J27: =IF(PREMISSAS!$C$48="MEDIÇÃO CHEIA",J26,MAX(0,J26-J28))*PREMISSAS!$C$10 -> 106442.23 | ... O27: =IF(PREMISSAS!$C$48="MEDIÇÃO CHEIA",O26,MAX(0,O26-O28))*PREMISSAS!$C$10 -> 106442.23 | P27: =SUM(C27:O27) -> 234172.9
B28: (–) Desconto do consórcio (custos que ele banca) | C28: 0 | D28: 0 | E28: 0 | F28: =PREMISSAS!$C$60*PREMISSAS!$C$39+PREMISSAS!$C$58*0.5 -> 138140.74 | G28: 0 | H28: 0 | I28: 0 | J28: =PREMISSAS!$C$60 -> 249561.48 | K28: 0 | L28: 0 | M28: 0 | N28: 0 | O28: =PREMISSAS!$C$60 -> 249561.48 | P28: =SUM(C28:O28) -> 637263.7
B29: (–) Custos pagos pela WCR (indiretos) | C29: 0 | D29: 0 | E29: 0 | F29: 0 | G29: =PREMISSAS!$C$55*PREMISSAS!$C$39 -> 10000 | H29: 0 | I29: 0 | J29: 0 | K29: 0 | L29: =PREMISSAS!$C$55 -> 20000 | M29: 0 | N29: 0 | O29: 0 | P29: =SUM(C29:O29) -> 30000
B30: (–) Outros desembolsos da WCR (edite se houver) | C30: 0 | D30: 0 | E30: 0 | F30: 0 | G30: 0 | H30: 0 | I30: 0 | J30: 0 | K30: 0 | L30: 0 | M30: 0 | N30: 0 | O30: 0 | P30: =SUM(C30:O30) -> 0
B31: (–) Mobilização paga pela WCR | C31: =PREMISSAS!$C$57*0.5 -> 0 | D31: 0 | E31: 0 | F31: 0 | G31: 0 | H31: 0 | I31: 0 | J31: 0 | K31: 0 | L31: 0 | M31: 0 | N31: 0 | O31: 0 | P31: =SUM(C31:O31) -> 0
B32: (B) TOTAL DE DESPESAS | C32: =SUM(C27:C31) -> 0 | D32: =SUM(D27:D31) -> 0 | E32: =SUM(E27:E31) -> 0 | F32: =SUM(F27:F31) -> 159429.19 | G32: =SUM(G27:G31) -> 10000 | H32: =SUM(H27:H31) -> 0 | I32: =SUM(I27:I31) -> 0 | J32: =SUM(J27:J31) -> 356003.71 | ... O32: =SUM(O27:O31) -> 356003.71 | P32: =SUM(C32:O32) -> 901436.6
B33: SALDO DO PERÍODO (A–B) | C33: =C26-C32 -> 0 | D33: =D26-D32 -> 0 | E33: =E26-E32 -> 0 | F33: =F26-F32 -> -62663.526 | G33: =G26-G32 -> -10000 | H33: =H26-H32 -> 0 | I33: =I26-I32 -> 0 | J33: =J26-J32 -> 127824.59 | ... O33: =O26-O32 -> 127824.59 | P33: =SUM(C33:O33) -> 162985.66
B34: SALDO ACUMULADO | C34: =C33 -> 0 | D34: =C34+D33 -> 0 | E34: =D34+E33 -> 0 | F34: =E34+F33 -> -62663.526 | G34: =F34+G33 -> -72663.526 | H34: =G34+H33 -> -72663.526 | I34: =H34+I33 -> -72663.526 | J34: =I34+J33 -> 55161.066 | K34: =J34+K33 -> 55161.066 | ... O34: =N34+O33 -> 162985.66 | P34: =O34 -> 162985.66
B36: GLOBAL — BERTIOGA + SANTOS
B37: (A) RECEBIMENTO BRUTO | C37: =C13+C26 -> 0 | D37: =D13+D26 -> 0 | E37: =E13+E26 -> 0 | F37: =F13+F26 -> 181947.7 | G37: =G13+G26 -> 0 | H37: =H13+H26 -> 0 | I37: =I13+I26 -> 0 | J37: =J13+J26 -> 909738.52 | ... O37: =O13+O26 -> 909738.52 | P37: =SUM(C37:O37) -> 2001424.8
B38: (B) TOTAL DE DESPESAS | C38: =C19+C32 -> 0 | D38: =D19+D32 -> 0 | E38: =E19+E32 -> 0 | F38: =F19+F32 -> 300175.66 | G38: =G19+G32 -> 20000 | H38: =H19+H32 -> 0 | I38: =I19+I32 -> 0 | J38: =J19+J32 -> 666996.8 | ... O38: =O19+O32 -> 666996.8 | P38: =SUM(C38:O38) -> 1694169.2
B39: SALDO DO PERÍODO (A–B) | C39: =C37-C38 -> 0 | D39: =D37-D38 -> 0 | E39: =E37-E38 -> 0 | F39: =F37-F38 -> -118227.95 | G39: =G37-G38 -> -20000 | H39: =H37-H38 -> 0 | I39: =I37-I38 -> 0 | J39: =J37-J38 -> 242741.73 | ... O39: =O37-O38 -> 242741.73 | P39: =SUM(C39:O39) -> 307255.51
B40: SALDO ACUMULADO | C40: =C39 -> 0 | D40: =C40+D39 -> 0 | E40: =D40+E39 -> 0 | F40: =E40+F39 -> -118227.95 | G40: =F40+G39 -> -138227.95 | H40: =G40+H39 -> -138227.95 | I40: =H40+I39 -> -138227.95 | J40: =I40+J39 -> 104513.78 | K40: =J40+K39 -> 104513.78 | ... O40: =N40+O39 -> 307255.51 | P40: =O40 -> 307255.51
B42: PIOR PONTO DO TRIMESTRE (menor saldo acumulado) | C42: =MIN(C40:O40) -> -138227.95 | G42: É o caixa que a obra consome no trimestre antes de o dinheiro do cliente entrar. Capital de giro: ver FCP MENSAL.
B44: PLANEJADO × REALIZADO — lance aqui a PRODUÇÃO REALIZADA de cada semana (células verdes)
B45: BERTIOGA — produção REALIZADA (un) | P45: =SUM(D45:O45) -> 0
B46: BERTIOGA — % do planejado | D46: =IF(D45="","",D45/D11) | E46: =IF(E45="","",E45/E11) | F46: =IF(F45="","",F45/F11) | G46: =IF(G45="","",G45/G11) | H46: =IF(H45="","",H45/H11) | I46: =IF(I45="","",I45/I11) | J46: =IF(J45="","",J45/J11) | K46: =IF(K45="","",K45/K11) | ... O46: =IF(O45="","",O45/O11) | P46: =IF(P45=0,"",P45/SUM(D11:O11))
...

Sheet FCP MENSAL
B2: FCP MENSAL — FINANCEIRO (CAIXA DA WCR)
B3: Recebimento = medição do mês anterior (defasagem PREMISSAS!C9), menos o desconto do consórcio e o imposto. Desembolso = só o que a WCR paga (indiretos), no mês seguinte à competência. Margem real do contrato: aba ECONÔMICO.
P4: Cenário: | Q4: =PREMISSAS!$C$13 -> ÓTIMA
B5: Mês | C5: =DATE(YEAR(PREMISSAS!$C$6),MONTH(PREMISSAS!$C$6),1) -> 46235 | D5: =EDATE(C5,1) -> 46266 | E5: =EDATE(D5,1) -> 46296 | F5: =EDATE(E5,1) -> 46327 | G5: =EDATE(F5,1) -> 46357 | H5: =EDATE(G5,1) -> 46388 | I5: =EDATE(H5,1) -> 46419 | J5: =EDATE(I5,1) -> 46447 | K5: =EDATE(J5,1) -> 46478 | ... Q5: =EDATE(P5,1) -> 46661 | R5: TOTAL
B6: Dias de obra no mês | C6: =AUX!C4 -> 8 | D6: =AUX!D4 -> 30 | E6: =AUX!E4 -> 31 | F6: =AUX!F4 -> 30 | G6: =AUX!G4 -> 31 | H6: =AUX!H4 -> 31 | I6: =AUX!I4 -> 28 | J6: =AUX!J4 -> 31 | ... Q6: =AUX!Q4 -> 0 | R6: =SUM(C6:Q6) -> 342
B8: BERTIOGA
B9: Medição do mês (ago–out: FCP SEMANAL · depois: projeção) | C9: =AUX!C5 -> 85182.045 | D9: =AUX!D5 -> 425910.23 | E9: =AUX!E5 -> 425910.23 | F9: =AUX!F5 -> 365065.91 | G9: =AUX!G5 -> 377234.77 | H9: =AUX!H5 -> 377234.77 | I9: =AUX!I5 -> 340728.18 | J9: =AUX!J5 -> 377234.77 | ... Q9: =AUX!Q5 -> 0 | R9: =SUM(C9:Q9) -> 4259102.3
B10: Recebimento bruto (medição do mês anterior) | C10: =SUMPRODUCT((AUX!$C$8:$Q$8>=C$5)*(AUX!$C$8:$Q$8<=EOMONTH(C$5,0))*AUX!$C$5:$Q$5) -> 0 | D10: =SUMPRODUCT((AUX!$C$8:$Q$8>=D$5)*(AUX!$C$8:$Q$8<=EOMONTH(D$5,0))*AUX!$C$5:$Q$5) -> 85182.045 | E10: =SUMPRODUCT((AUX!$C$8:$Q$8>=E$5)*(AUX!$C$8:$Q$8<=EOMONTH(E$5,0))*AUX!$C$5:$Q$5) -> 425910.23 | F10: =SUMPRODUCT((AUX!$C$8:$Q$8>=F$5)*(AUX!$C$8:$Q$8<=EOMONTH(F$5,0))*AUX!$C$5:$Q$5) -> 425910.23 | G10: =SUMPRODUCT((AUX!$C$8:$Q$8>=G$5)*(AUX!$C$8:$Q$8<=EOMONTH(G$5,0))*AUX!$C$5:$Q$5) -> 365065.91 | H10: =SUMPRODUCT((AUX!$C$8:$Q$8>=H$5)*(AUX!$C$8:$Q$8<=EOMONTH(H$5,0))*AUX!$C$5:$Q$5) -> 377234.77 | I10: =SUMPRODUCT((AUX!$C$8:$Q$8>=I$5)*(AUX!$C$8:$Q$8<=EOMONTH(I$5,0))*AUX!$C$5:$Q$5) -> 377234.77 | J10: =SUMPRODUCT((AUX!$C$8:$Q$8>=J$5)*(AUX!$C$8:$Q$8<=EOMONTH(J$5,0))*AUX!$C$5:$Q$5) -> 340728.18 | ... Q10: =SUMPRODUCT((AUX!$C$8:$Q$8>=Q$5)*(AUX!$C$8:$Q$8<=EOMONTH(Q$5,0))*AUX!$C$5:$Q$5) -> 0 | R10: =SUM(C10:Q10) -> 4259102.3
B11: (–) Desconto do consórcio (custos bancados) | C11: 0 | D11: =PREMISSAS!$C$59*AUX!C$9/PREMISSAS!$C$8+IF(D$5=EDATE(DATE(YEAR(PREMISSAS!$C$6),MONTH(PREMISSAS!$C$6),1),1),PREMISSAS!$C$58*0.5,0) -> 122006.42 | E11: =PREMISSAS!$C$59*AUX!D$9/PREMISSAS!$C$8+IF(E$5=EDATE(DATE(YEAR(PREMISSAS!$C$6),MONTH(PREMISSAS!$C$6),1),1),PREMISSAS!$C$58*0.5,0) -> 217292.84 | F11: =PREMISSAS!$C$59*AUX!E$9/PREMISSAS!$C$8+IF(F$5=EDATE(DATE(YEAR(PREMISSAS!$C$6),MONTH(PREMISSAS!$C$6),1),1),PREMISSAS!$C$58*0.5,0) -> 224535.93 | G11: =PREMISSAS!$C$59*AUX!F$9/PREMISSAS!$C$8+IF(G$5=EDATE(DATE(YEAR(PREMISSAS!$C$6),MONTH(PREMISSAS!$C$6),1),1),PREMISSAS!$C$58*0.5,0) -> 217292.84 | H11: =PREMISSAS!$C$59*AUX!G$9/PREMISSAS!$C$8+IF(H$5=EDATE(DATE(YEAR(PREMISSAS!$C$6),MONTH(PREMISSAS!$C$6),1),1),PREMISSAS!$C$58*0.5,0) -> 224535.93 | I11: =PREMISSAS!$C$59*AUX!H$9/PREMISSAS!$C$8+IF(I$5=EDATE(DATE(YEAR(PREMISSAS!$C$6),MONTH(PREMISSAS!$C$6),1),1),PREMISSAS!$C$58*0.5,0) -> 224535.93 | J11: =PREMISSAS!$C$59*AUX!I$9/PREMISSAS!$C$8+IF(J$5=EDATE(DATE(YEAR(PREMISSAS!$C$6),MONTH(PREMISSAS!$C$6),1),1),PREMISSAS!$C$58*0.5,0) -> 202806.65 | K11: =PREMISSAS!$C$59*AUX!J$9/PREMISSAS!$C$8+IF(K$5=EDATE(DATE(YEAR(PREMISSAS!$C$6),MONTH(PREMISSAS!$C$6),1),1),PREMISSAS!$C$58*0.5,0) -> 224535.93 | ... Q11: =PREMISSAS!$C$59*AUX!P$9/PREMISSAS!$C$8+IF(Q$5=EDATE(DATE(YEAR(PREMISSAS!$C$6),MONTH(PREMISSAS!$C$6),1),1),PREMISSAS!$C$58*0.5,0) -> 0 | R11: =SUM(C11:Q11) -> 2541200
B12: (–) Imposto da nota | C12: =IF(PREMISSAS!$C$48="MEDIÇÃO CHEIA",C10,MAX(0,C10-C11))*PREMISSAS!$C$10 -> 0 | D12: =IF(PREMISSAS!$C$48="MEDIÇÃO CHEIA",D10,MAX(0,D10-D11))*PREMISSAS!$C$10 -> 18740.05 | E12: =IF(PREMISSAS!$C$48="MEDIÇÃO CHEIA",E10,MAX(0,E10-E11))*PREMISSAS!$C$10 -> 93700.25 | F12: =IF(PREMISSAS!$C$48="MEDIÇÃO CHEIA",F10,MAX(0,F10-F11))*PREMISSAS!$C$10 -> 93700.25 | G12: =IF(PREMISSAS!$C$48="MEDIÇÃO CHEIA",G10,MAX(0,G10-G11))*PREMISSAS!$C$10 -> 80314.5 | H12: =IF(PREMISSAS!$C$48="MEDIÇÃO CHEIA",H10,MAX(0,H10-H11))*PREMISSAS!$C$10 -> 82991.65 | I12: =IF(PREMISSAS!$C$48="MEDIÇÃO CHEIA",I10,MAX(0,I10-I11))*PREMISSAS!$C$10 -> 82991.65 | J12: =IF(PREMISSAS!$C$48="MEDIÇÃO CHEIA",J10,MAX(0,J10-J11))*PREMISSAS!$C$10 -> 74960.2 | ... Q12: =IF(PREMISSAS!$C$48="MEDIÇÃO CHEIA",Q10,MAX(0,Q10-Q11))*PREMISSAS!$C$10 -> 0 | R12: =SUM(C12:Q12) -> 937002.5
B13: ENTRA NO CAIXA DA WCR | C13: =C10-C11-C12 -> 0 | D13: =D10-D11-D12 -> -55564.425 | E13: =E10-E11-E12 -> 114917.14 | F13: =F10-F11-F12 -> 107674.04 | G13: =G10-G11-G12 -> 67458.568 | H13: =H10-H11-H12 -> 69707.187 | I13: =I10-I11-I12 -> 69707.187 | J13: =J10-J11-J12 -> 62961.33 | ... Q13: =Q10-Q11-Q12 -> 0 | R13: =SUM(C13:Q13) -> 780899.72
B14: (–) Sai do caixa da WCR (indiretos do mês ant.) | C14: =IF(C$5=DATE(YEAR(PREMISSAS!$C$6),MONTH(PREMISSAS!$C$6),1),PREMISSAS!$C$57*0.5,0) -> 0 | D14: =PREMISSAS!$C$54*AUX!C$9/PREMISSAS!$C$8 -> 10000 | E14: =PREMISSAS!$C$54*AUX!D$9/PREMISSAS!$C$8 -> 20000 | F14: =PREMISSAS!$C$54*AUX!E$9/PREMISSAS!$C$8 -> 20666.667 | G14: =PREMISSAS!$C$54*AUX!F$9/PREMISSAS!$C$8 -> 20000 | H14: =PREMISSAS!$C$54*AUX!G$9/PREMISSAS!$C$8 -> 20666.667 | I14: =PREMISSAS!$C$54*AUX!H$9/PREMISSAS!$C$8 -> 20666.667 | J14: =PREMISSAS!$C$54*AUX!I$9/PREMISSAS!$C$8 -> 18666.667 | K14: =PREMISSAS!$C$54*AUX!J$9/PREMISSAS!$C$8 -> 20666.667 | ... Q14: =PREMISSAS!$C$54*AUX!P$9/PREMISSAS!$C$8 -> 0 | R14: =SUM(C14:Q14) -> 232666.67
B15: Saldo do mês | C15: =C13-C14 -> 0 | D15: =D13-D14 -> -65564.425 | E15: =E13-E14 -> 94917.136 | F15: =F13-F14 -> 87007.375 | G15: =G13-G14 -> 47458.568 | H15: =H13-H14 -> 49040.52 | I15: =I13-I14 -> 49040.52 | J15: =J13-J14 -> 44294.663 | ... Q15: =Q13-Q14 -> 0 | R15: =SUM(C15:Q15) -> 548233.05
B16: CAIXA ACUMULADO — antes do recebimento | C16: =-C14 -> 0 | D16: =C17-D14 -> -10000 | E16: =D17-E14 -> -85564.425 | F16: =E17-F14 -> 8686.0445 | G16: =F17-G14 -> 96360.086 | H16: =G17-H14 -> 143151.99 | I16: =H17-I14 -> 192192.51 | J16: =I17-J14 -> 243233.03 | K16: =J17-K14 -> 285527.69 | ... Q16: =P17-Q14 -> 548233.05 | R16: =MIN(C16:Q16) -> -85564.425
B17: CAIXA ACUMULADO — após o recebimento | C17: =C16+C13 -> 0 | D17: =D16+D13 -> -65564.425 | E17: =E16+E13 -> 29352.711 | F17: =F16+F13 -> 116360.09 | G17: =G16+G13 -> 163818.65 | H17: =H16+H13 -> 212859.17 | I17: =I16+I13 -> 261899.69 | J17: =J16+J13 -> 306194.36 | ... Q17: =Q16+Q13 -> 548233.05 | R17: =Q17 -> 548233.05
B19: SANTOS
B20: Medição do mês (ago–out: FCP SEMANAL · depois: projeção) | C20: =AUX!C6 -> 96765.659 | D20: =AUX!D6 -> 483828.3 | E20: =AUX!E6 -> 483828.3 | F20: =AUX!F6 -> 414709.97 | G20: =AUX!G6 -> 428533.63 | H20: =AUX!H6 -> 428533.63 | I20: =AUX!I6 -> 387062.64 | J20: =AUX!J6 -> 428533.63 | ... Q20: =AUX!Q6 -> 0 | R20: =SUM(C20:Q20) -> 4838283
B21: Recebimento bruto (medição do mês anterior) | C21: =SUMPRODUCT((AUX!$C$8:$Q$8>=C$5)*(AUX!$C$8:$Q$8<=EOMONTH(C$5,0))*AUX!$C$6:$Q$6) -> 0 | D21: =SUMPRODUCT((AUX!$C$8:$Q$8>=D$5)*(AUX!$C$8:$Q$8<=EOMONTH(D$5,0))*AUX!$C$6:$Q$6) -> 96765.659 | E21: =SUMPRODUCT((AUX!$C$8:$Q$8>=E$5)*(AUX!$C$8:$Q$8<=EOMONTH(E$5,0))*AUX!$C$6:$Q$6) -> 483828.3 | F21: =SUMPRODUCT((AUX!$C$8:$Q$8>=F$5)*(AUX!$C$8:$Q$8<=EOMONTH(F$5,0))*AUX!$C$6:$Q$6) -> 483828.3 | G21: =SUMPRODUCT((AUX!$C$8:$Q$8>=G$5)*(AUX!$C$8:$Q$8<=EOMONTH(G$5,0))*AUX!$C$6:$Q$6) -> 414709.97 | H21: =SUMPRODUCT((AUX!$C$8:$Q$8>=H$5)*(AUX!$C$8:$Q$8<=EOMONTH(H$5,0))*AUX!$C$6:$Q$6) -> 428533.63 | I21: =SUMPRODUCT((AUX!$C$8:$Q$8>=I$5)*(AUX!$C$8:$Q$8<=EOMONTH(I$5,0))*AUX!$C$6:$Q$6) -> 428533.63 | J21: =SUMPRODUCT((AUX!$C$8:$Q$8>=J$5)*(AUX!$C$8:$Q$8<=EOMONTH(J$5,0))*AUX!$C$6:$Q$6) -> 387062.64 | ... Q21: =SUMPRODUCT((AUX!$C$8:$Q$8>=Q$5)*(AUX!$C$8:$Q$8<=EOMONTH(Q$5,0))*AUX!$C$6:$Q$6) -> 0 | R21: =SUM(C21:Q21) -> 4838283
B22: (–) Desconto do consórcio (custos bancados) | C22: 0 | D22: =PREMISSAS!$C$60*AUX!C$9/PREMISSAS!$C$8+IF(D$5=EDATE(DATE(YEAR(PREMISSAS!$C$6),MONTH(PREMISSAS!$C$6),1),1),PREMISSAS!$C$58*0.5,0) -> 138140.74 | E22: =PREMISSAS!$C$60*AUX!D$9/PREMISSAS!$C$8+IF(E$5=EDATE(DATE(YEAR(PREMISSAS!$C$6),MONTH(PREMISSAS!$C$6),1),1),PREMISSAS!$C$58*0.5,0) -> 249561.48 | F22: =PREMISSAS!$C$60*AUX!E$9/PREMISSAS!$C$8+IF(F$5=EDATE(DATE(YEAR(PREMISSAS!$C$6),MONTH(PREMISSAS!$C$6),1),1),PREMISSAS!$C$58*0.5,0) -> 257880.2 | G22: =PREMISSAS!$C$60*AUX!F$9/PREMISSAS!$C$8+IF(G$5=EDATE(DATE(YEAR(PREMISSAS!$C$6),MONTH(PREMISSAS!$C$6),1),1),PREMISSAS!$C$58*0.5,0) -> 249561.48 | H22: =PREMISSAS!$C$60*AUX!G$9/PREMISSAS!$C$8+IF(H$5=EDATE(DATE(YEAR(PREMISSAS!$C$6),MONTH(PREMISSAS!$C$6),1),1),PREMISSAS!$C$58*0.5,0) -> 257880.2 | I22: =PREMISSAS!$C$60*AUX!H$9/PREMISSAS!$C$8+IF(I$5=EDATE(DATE(YEAR(PREMISSAS!$C$6),MONTH(PREMISSAS!$C$6),1),1),PREMISSAS!$C$58*0.5,0) -> 257880.2 | J22: =PREMISSAS!$C$60*AUX!I$9/PREMISSAS!$C$8+IF(J$5=EDATE(DATE(YEAR(PREMISSAS!$C$6),MONTH(PREMISSAS!$C$6),1),1),PREMISSAS!$C$58*0.5,0) -> 232924.05 | K22: =PREMISSAS!$C$60*AUX!J$9/PREMISSAS!$C$8+IF(K$5=EDATE(DATE(YEAR(PREMISSAS!$C$6),MONTH(PREMISSAS!$C$6),1),1),PREMISSAS!$C$58*0.5,0) -> 257880.2 | ... Q22: =PREMISSAS!$C$60*AUX!P$9/PREMISSAS!$C$8+IF(Q$5=EDATE(DATE(YEAR(PREMISSAS!$C$6),MONTH(PREMISSAS!$C$6),1),1),PREMISSAS!$C$58*0.5,0) -> 0 | R22: =SUM(C22:Q22) -> 2916591.9
B23: (–) Imposto da nota | C23: =IF(PREMISSAS!$C$48="MEDIÇÃO CHEIA",C21,MAX(0,C21-C22))*PREMISSAS!$C$10 -> 0 | D23: =IF(PREMISSAS!$C$48="MEDIÇÃO CHEIA",D21,MAX(0,D21-D22))*PREMISSAS!$C$10 -> 21288.445 | E23: =IF(PREMISSAS!$C$48="MEDIÇÃO CHEIA",E21,MAX(0,E21-E22))*PREMISSAS!$C$10 -> 106442.23 | F23: =IF(PREMISSAS!$C$48="MEDIÇÃO CHEIA",F21,MAX(0,F21-F22))*PREMISSAS!$C$10 -> 106442.23 | G23: =IF(PREMISSAS!$C$48="MEDIÇÃO CHEIA",G21,MAX(0,G21-G22))*PREMISSAS!$C$10 -> 91236.193 | H23: =IF(PREMISSAS!$C$48="MEDIÇÃO CHEIA",H21,MAX(0,H21-H22))*PREMISSAS!$C$10 -> 94277.4 | I23: =IF(PREMISSAS!$C$48="MEDIÇÃO CHEIA",I21,MAX(0,I21-I22))*PREMISSAS!$C$10 -> 94277.4 | J23: =IF(PREMISSAS!$C$48="MEDIÇÃO CHEIA",J21,MAX(0,J21-J22))*PREMISSAS!$C$10 -> 85153.78 | ... Q23: =IF(PREMISSAS!$C$48="MEDIÇÃO CHEIA",Q21,MAX(0,Q21-Q22))*PREMISSAS!$C$10 -> 0 | R23: =SUM(C23:Q23) -> 1064422.3
B24: ENTRA NO CAIXA DA WCR | C24: =C21-C22-C23 -> 0 | D24: =D21-D22-D23 -> -62663.526 | E24: =E21-E22-E23 -> 127824.59 | F24: =F21-F22-F23 -> 119505.88 | G24: =G21-G22-G23 -> 73912.296 | H24: =H21-H22-H23 -> 76376.039 | I24: =I21-I22-I23 -> 76376.039 | J24: =J21-J22-J23 -> 68984.81 | ... Q24: =Q21-Q22-Q23 -> 0 | R24: =SUM(C24:Q24) -> 857268.84
B25: (–) Sai do caixa da WCR (indiretos do mês ant.) | C25: =IF(C$5=DATE(YEAR(PREMISSAS!$C$6),MONTH(PREMISSAS!$C$6),1),PREMISSAS!$C$57*0.5,0) -> 0 | D25: =PREMISSAS!$C$55*AUX!C$9/PREMISSAS!$C$8 -> 10000 | E25: =PREMISSAS!$C$55*AUX!D$9/PREMISSAS!$C$8 -> 20000 | F25: =PREMISSAS!$C$55*AUX!E$9/PREMISSAS!$C$8 -> 20666.667 | G25: =PREMISSAS!$C$55*AUX!F$9/PREMISSAS!$C$8 -> 20000 | H25: =PREMISSAS!$C$55*AUX!G$9/PREMISSAS!$C$8 -> 20666.667 | I25: =PREMISSAS!$C$55*AUX!H$9/PREMISSAS!$C$8 -> 20666.667 | J25: =PREMISSAS!$C$55*AUX!I$9/PREMISSAS!$C$8 -> 18666.667 | K25: =PREMISSAS!$C$55*AUX!J$9/PREMISSAS!$C$8 -> 20666.667 | ... Q25: =PREMISSAS!$C$55*AUX!P$9/PREMISSAS!$C$8 -> 0 | R25: =SUM(C25:Q25) -> 232666.67
B26: Saldo do mês | C26: =C24-C25 -> 0 | D26: =D24-D25 -> -72663.526 | E26: =E24-E25 -> 107824.59 | F26: =F24-F25 -> 98839.209 | G26: =G24-G25 -> 53912.296 | H26: =H24-H25 -> 55709.373 | I26: =I24-I25 -> 55709.373 | J26: =J24-J25 -> 50318.143 | ... Q26: =Q24-Q25 -> 0 | R26: =SUM(C26:Q26) -> 624602.17
B27: CAIXA ACUMULADO — antes do recebimento | C27: =-C25 -> 0 | D27: =C28-D25 -> -10000 | E27: =D28-E25 -> -92663.526 | F27: =E28-F25 -> 14494.4 | G27: =F28-G25 -> 114000.28 | H27: =G28-H25 -> 167245.91 | I27: =H28-I25 -> 222955.28 | J27: =I28-J25 -> 280664.65 | K27: =J28-K25 -> 328982.79 | ... Q27: =P28-Q25 -> 624602.17 | R27: =MIN(C27:Q27) -> -92663.526
B28: CAIXA ACUMULADO — após o recebimento | C28: =C27+C24 -> 0 | D28: =D27+D24 -> -72663.526 | E28: =E27+E24 -> 35161.066 | F28: =F27+F24 -> 134000.28 | G28: =G27+G24 -> 187912.57 | H28: =H27+H24 -> 243621.94 | I28: =I27+I24 -> 299331.32 | J28: =J27+J24 -> 349649.46 | ... Q28: =Q27+Q24 -> 624602.17 | R28: =Q28 -> 624602.17
B30: GLOBAL — BERTIOGA + SANTOS
B31: Medição bruta (ago–out: FCP SEMANAL · depois: projeção) | C31: =C9+C20 -> 181947.7 | D31: =D9+D20 -> 909738.52 | E31: =E9+E20 -> 909738.52 | F31: =F9+F20 -> 779775.88 | G31: =G9+G20 -> 805768.41 | H31: =H9+H20 -> 805768.41 | I31: =I9+I20 -> 727790.82 | J31: =J9+J20 -> 805768.41 | ... Q31: =Q9+Q20 -> 0 | R31: =SUM(C31:Q31) -> 9097385.2
B32: Recebimento bruto | C32: =C10+C21 -> 0 | D32: =D10+D21 -> 181947.7 | E32: =E10+E21 -> 909738.52 | F32: =F10+F21 -> 909738.52 | G32: =G10+G21 -> 779775.88 | H32: =H10+H21 -> 805768.41 | I32: =I10+I21 -> 805768.41 | J32: =J10+J21 -> 727790.82 | ... Q32: =Q10+Q21 -> 0 | R32: =SUM(C32:Q32) -> 9097385.2
B33: (–) Desconto do consórcio | C33: =C11+C22 -> 0 | D33: =D11+D22 -> 260147.16 | E33: =E11+E22 -> 466854.32 | F33: =F11+F22 -> 482416.13 | G33: =G11+G22 -> 466854.32 | H33: =H11+H22 -> 482416.13 | I33: =I11+I22 -> 482416.13 | J33: =J11+J22 -> 435730.7 | ... Q33: =Q11+Q22 -> 0 | R33: =SUM(C33:Q33) -> 5457791.9
B34: (–) Imposto da nota | C34: =C12+C23 -> 0 | D34: =D12+D23 -> 40028.495 | E34: =E12+E23 -> 200142.48 | F34: =F12+F23 -> 200142.48 | G34: =G12+G23 -> 171550.69 | H34: =H12+H23 -> 177269.05 | I34: =I12+I23 -> 177269.05 | J34: =J12+J23 -> 160113.98 | ... Q34: =Q12+Q23 -> 0 | R34: =SUM(C34:Q34) -> 2001424.8
B35: ENTRA NO CAIXA DA WCR | C35: =C13+C24 -> 0 | D35: =D13+D24 -> -118227.95 | E35: =E13+E24 -> 242741.73 | F35: =F13+F24 -> 227179.92 | G35: =G13+G24 -> 141370.86 | H35: =H13+H24 -> 146083.23 | I35: =I13+I24 -> 146083.23 | J35: =J13+J24 -> 131946.14 | ... Q35: =Q13+Q24 -> 0 | R35: =SUM(C35:Q35) -> 1638168.6
B36: (–) Sai do caixa da WCR | C36: =C14+C25 -> 0 | D36: =D14+D25 -> 20000 | E36: =E14+E25 -> 40000 | F36: =F14+F25 -> 41333.333 | G36: =G14+G25 -> 40000 | H36: =H14+H25 -> 41333.333 | I36: =I14+I25 -> 41333.333 | J36: =J14+J25 -> 37333.333 | ... Q36: =Q14+Q25 -> 0 | R36: =SUM(C36:Q36) -> 465333.33
B37: Saldo do mês | C37: =C35-C36 -> 0 | D37: =D35-D36 -> -138227.95 | E37: =E35-E36 -> 202741.73 | F37: =F35-F36 -> 185846.58 | G37: =G35-G36 -> 101370.86 | H37: =H35-H36 -> 104749.89 | I37: =I35-I36 -> 104749.89 | J37: =J35-J36 -> 94612.806 | ... Q37: =Q35-Q36 -> 0 | R37: =SUM(C37:Q37) -> 1172835.2
B38: CAIXA ACUMULADO — antes do recebimento | C38: =-C36 -> 0 | D38: =C39-D36 -> -20000 | E38: =D39-E36 -> -178227.95 | F38: =E39-F36 -> 23180.444 | G38: =F39-G36 -> 210360.36 | H38: =G39-H36 -> 310397.89 | I38: =H39-I36 -> 415147.79 | J38: =I39-J36 -> 523897.68 | K38: =J39-K36 -> 614510.48 | ... Q38: =P39-Q36 -> 1172835.2 | R38: =MIN(C38:Q38) -> -178227.95
B39: CAIXA ACUMULADO — após o recebimento | C39: =C38+C35 -> 0 | D39: =D38+D35 -> -138227.95 | E39: =E38+E35 -> 64513.778 | F39: =F38+F35 -> 250360.36 | G39: =G38+G35 -> 351731.23 | H39: =H38+H35 -> 456481.12 | I39: =I38+I35 -> 561231.01 | J39: =J38+J35 -> 655843.82 | ... Q39: =Q38+Q35 -> 1172835.2 | R39: =Q39 -> 1172835.2
B41: CAPITAL NECESSÁRIO E RESULTADO DE CAIXA — cenário adotado
B42: Necessidade máxima de caixa da WCR (pior ponto) | C42: =MAX(0,-MIN(C38:Q38)) -> 178227.95 | F42: Com o consórcio bancando folha, engenheiro e estrutura, a WCR só financia os indiretos e o descasamento do 1º mês. No começo o desconto pode ser maior que a medição parcial (agosto): o líquido fica negativo — é saldo devido ao consórcio, compensa no mês seguinte.
B43: Contingência (premissa) | C43: =C42*PREMISSAS!$C$38 -> 26734.193
B44: CAPITAL RECOMENDADO — WCR | C44: =C42+C43 -> 204962.14
B45: Resultado de caixa no fim do horizonte | C45: =Q39 -> 1172835.2
...

Sheet ECONÔMICO
B2: ECONÔMICO — RESULTADO DO CONTRATO (COMPETÊNCIA)
B3: A margem real da operação, mês a mês, com TODOS os custos — inclusive os que o consórcio banca. Estilo do DRE Se Liga na Rede. O caixa da WCR está no FCP MENSAL / FCP SEMANAL.
P4: Cenário: | Q4: =PREMISSAS!$C$13 -> ÓTIMA
B5: Mês | C5: =DATE(YEAR(PREMISSAS!$C$6),MONTH(PREMISSAS!$C$6),1) -> 46235 | D5: =EDATE(C5,1) -> 46266 | E5: =EDATE(D5,1) -> 46296 | F5: =EDATE(E5,1) -> 46327 | G5: =EDATE(F5,1) -> 46357 | H5: =EDATE(G5,1) -> 46388 | I5: =EDATE(H5,1) -> 46419 | J5: =EDATE(I5,1) -> 46447 | K5: =EDATE(J5,1) -> 46478 | ... Q5: =EDATE(P5,1) -> 46661 | R5: TOTAL
B6: Dias de obra no mês | C6: =AUX!C4 -> 8 | D6: =AUX!D4 -> 30 | E6: =AUX!E4 -> 31 | F6: =AUX!F4 -> 30 | G6: =AUX!G4 -> 31 | H6: =AUX!H4 -> 31 | I6: =AUX!I4 -> 28 | J6: =AUX!J4 -> 31 | ... Q6: =AUX!Q4 -> 0 | R6: =SUM(C6:Q6) -> 342
B9: Medição bruta (ago–out: FCP SEMANAL · depois: projeção) | C9: =AUX!C7 -> 181947.7 | D9: =AUX!D7 -> 909738.52 | E9: =AUX!E7 -> 909738.52 | F9: =AUX!F7 -> 779775.88 | G9: =AUX!G7 -> 805768.41 | H9: =AUX!H7 -> 805768.41 | I9: =AUX!I7 -> 727790.82 | J9: =AUX!J7 -> 805768.41 | ... Q9: =AUX!Q7 -> 0 | R9: =SUM(C9:Q9) -> 9097385.2
B10: (–) Imposto da nota | C10: =IF(PREMISSAS!$C$48="MEDIÇÃO CHEIA",C9,MAX(0,C9-PREMISSAS!$C$61*AUX!C$9/PREMISSAS!$C$8))*PREMISSAS!$C$10 -> 40028.495 | D10: =IF(PREMISSAS!$C$48="MEDIÇÃO CHEIA",D9,MAX(0,D9-PREMISSAS!$C$61*AUX!D$9/PREMISSAS!$C$8))*PREMISSAS!$C$10 -> 200142.48 | E10: =IF(PREMISSAS!$C$48="MEDIÇÃO CHEIA",E9,MAX(0,E9-PREMISSAS!$C$61*AUX!E$9/PREMISSAS!$C$8))*PREMISSAS!$C$10 -> 200142.48 | F10: =IF(PREMISSAS!$C$48="MEDIÇÃO CHEIA",F9,MAX(0,F9-PREMISSAS!$C$61*AUX!F$9/PREMISSAS!$C$8))*PREMISSAS!$C$10 -> 171550.69 | G10: =IF(PREMISSAS!$C$48="MEDIÇÃO CHEIA",G9,MAX(0,G9-PREMISSAS!$C$61*AUX!G$9/PREMISSAS!$C$8))*PREMISSAS!$C$10 -> 177269.05 | H10: =IF(PREMISSAS!$C$48="MEDIÇÃO CHEIA",H9,MAX(0,H9-PREMISSAS!$C$61*AUX!H$9/PREMISSAS!$C$8))*PREMISSAS!$C$10 -> 177269.05 | I10: =IF(PREMISSAS!$C$48="MEDIÇÃO CHEIA",I9,MAX(0,I9-PREMISSAS!$C$61*AUX!I$9/PREMISSAS!$C$8))*PREMISSAS!$C$10 -> 160113.98 | J10: =IF(PREMISSAS!$C$48="MEDIÇÃO CHEIA",J9,MAX(0,J9-PREMISSAS!$C$61*AUX!J$9/PREMISSAS!$C$8))*PREMISSAS!$C$10 -> 177269.05 | ... Q10: =IF(PREMISSAS!$C$48="MEDIÇÃO CHEIA",Q9,MAX(0,Q9-PREMISSAS!$C$61*AUX!Q$9/PREMISSAS!$C$8))*PREMISSAS!$C$10 -> 0 | R10: =SUM(C10:Q10) -> 2001424.8
B11: (=) Medição líquida de imposto | C11: =C9-C10 -> 141919.21 | D11: =D9-D10 -> 709596.05 | E11: =E9-E10 -> 709596.05 | F11: =F9-F10 -> 608225.18 | G11: =G9-G10 -> 628499.36 | H11: =H9-H10 -> 628499.36 | I11: =I9-I10 -> 567676.84 | J11: =J9-J10 -> 628499.36 | ... Q11: =Q9-Q10 -> 0 | R11: =SUM(C11:Q11) -> 7095960.5
B12: (–) Folha das equipes | C12: =('CUSTOS BERTIOGA'!$H$22+'CUSTOS SANTOS'!$H$23)*AUX!C$9/PREMISSAS!$C$8 -> 113377.16 | D12: =('CUSTOS BERTIOGA'!$H$22+'CUSTOS SANTOS'!$H$23)*AUX!D$9/PREMISSAS!$C$8 -> 226754.32 | E12: =('CUSTOS BERTIOGA'!$H$22+'CUSTOS SANTOS'!$H$23)*AUX!E$9/PREMISSAS!$C$8 -> 234312.8 | F12: =('CUSTOS BERTIOGA'!$H$22+'CUSTOS SANTOS'!$H$23)*AUX!F$9/PREMISSAS!$C$8 -> 226754.32 | G12: =('CUSTOS BERTIOGA'!$H$22+'CUSTOS SANTOS'!$H$23)*AUX!G$9/PREMISSAS!$C$8 -> 234312.8 | H12: =('CUSTOS BERTIOGA'!$H$22+'CUSTOS SANTOS'!$H$23)*AUX!H$9/PREMISSAS!$C$8 -> 234312.8 | I12: =('CUSTOS BERTIOGA'!$H$22+'CUSTOS SANTOS'!$H$23)*AUX!I$9/PREMISSAS!$C$8 -> 211637.37 | J12: =('CUSTOS BERTIOGA'!$H$22+'CUSTOS SANTOS'!$H$23)*AUX!J$9/PREMISSAS!$C$8 -> 234312.8 | ... Q12: =('CUSTOS BERTIOGA'!$H$22+'CUSTOS SANTOS'!$H$23)*AUX!Q$9/PREMISSAS!$C$8 -> 0 | R12: =SUM(C12:Q12) -> 2637908.6
B13: (–) Engenheiro | C13: =('CUSTOS BERTIOGA'!$F$26+'CUSTOS SANTOS'!$F$27)*AUX!C$9/PREMISSAS!$C$8 -> 13000 | D13: =('CUSTOS BERTIOGA'!$F$26+'CUSTOS SANTOS'!$F$27)*AUX!D$9/PREMISSAS!$C$8 -> 26000 | E13: =('CUSTOS BERTIOGA'!$F$26+'CUSTOS SANTOS'!$F$27)*AUX!E$9/PREMISSAS!$C$8 -> 26866.667 | F13: =('CUSTOS BERTIOGA'!$F$26+'CUSTOS SANTOS'!$F$27)*AUX!F$9/PREMISSAS!$C$8 -> 26000 | G13: =('CUSTOS BERTIOGA'!$F$26+'CUSTOS SANTOS'!$F$27)*AUX!G$9/PREMISSAS!$C$8 -> 26866.667 | H13: =('CUSTOS BERTIOGA'!$F$26+'CUSTOS SANTOS'!$F$27)*AUX!H$9/PREMISSAS!$C$8 -> 26866.667 | I13: =('CUSTOS BERTIOGA'!$F$26+'CUSTOS SANTOS'!$F$27)*AUX!I$9/PREMISSAS!$C$8 -> 24266.667 | J13: =('CUSTOS BERTIOGA'!$F$26+'CUSTOS SANTOS'!$F$27)*AUX!J$9/PREMISSAS!$C$8 -> 26866.667 | ... Q13: =('CUSTOS BERTIOGA'!$F$26+'CUSTOS SANTOS'!$F$27)*AUX!Q$9/PREMISSAS!$C$8 -> 0 | R13: =SUM(C13:Q13) -> 302466.67
B14: (–) Estrutura e locações | C14: =(PREMISSAS!$C$30-'CUSTOS BERTIOGA'!$H$22-'CUSTOS SANTOS'!$H$23-'CUSTOS BERTIOGA'!$F$26-'CUSTOS SANTOS'!$F$27-'CUSTOS BERTIOGA'!$F$34-'CUSTOS SANTOS'!$F$35)*AUX!C$9/PREMISSAS!$C$8 -> 107050 | D14: =(PREMISSAS!$C$30-'CUSTOS BERTIOGA'!$H$22-'CUSTOS SANTOS'!$H$23-'CUSTOS BERTIOGA'!$F$26-'CUSTOS SANTOS'!$F$27-'CUSTOS BERTIOGA'!$F$34-'CUSTOS SANTOS'!$F$35)*AUX!D$9/PREMISSAS!$C$8 -> 214100 | E14: =(PREMISSAS!$C$30-'CUSTOS BERTIOGA'!$H$22-'CUSTOS SANTOS'!$H$23-'CUSTOS BERTIOGA'!$F$26-'CUSTOS SANTOS'!$F$27-'CUSTOS BERTIOGA'!$F$34-'CUSTOS SANTOS'!$F$35)*AUX!E$9/PREMISSAS!$C$8 -> 221236.67 | F14: =(PREMISSAS!$C$30-'CUSTOS BERTIOGA'!$H$22-'CUSTOS SANTOS'!$H$23-'CUSTOS BERTIOGA'!$F$26-'CUSTOS SANTOS'!$F$27-'CUSTOS BERTIOGA'!$F$34-'CUSTOS SANTOS'!$F$35)*AUX!F$9/PREMISSAS!$C$8 -> 214100 | G14: =(PREMISSAS!$C$30-'CUSTOS BERTIOGA'!$H$22-'CUSTOS SANTOS'!$H$23-'CUSTOS BERTIOGA'!$F$26-'CUSTOS SANTOS'!$F$27-'CUSTOS BERTIOGA'!$F$34-'CUSTOS SANTOS'!$F$35)*AUX!G$9/PREMISSAS!$C$8 -> 221236.67 | H14: =(PREMISSAS!$C$30-'CUSTOS BERTIOGA'!$H$22-'CUSTOS SANTOS'!$H$23-'CUSTOS BERTIOGA'!$F$26-'CUSTOS SANTOS'!$F$27-'CUSTOS BERTIOGA'!$F$34-'CUSTOS SANTOS'!$F$35)*AUX!H$9/PREMISSAS!$C$8 -> 221236.67 | I14: =(PREMISSAS!$C$30-'CUSTOS BERTIOGA'!$H$22-'CUSTOS SANTOS'!$H$23-'CUSTOS BERTIOGA'!$F$26-'CUSTOS SANTOS'!$F$27-'CUSTOS BERTIOGA'!$F$34-'CUSTOS SANTOS'!$F$35)*AUX!I$9/PREMISSAS!$C$8 -> 199826.67 | J14: =(PREMISSAS!$C$30-'CUSTOS BERTIOGA'!$H$22-'CUSTOS SANTOS'!$H$23-'CUSTOS BERTIOGA'!$F$26-'CUSTOS SANTOS'!$F$27-'CUSTOS BERTIOGA'!$F$34-'CUSTOS SANTOS'!$F$35)*AUX!J$9/PREMISSAS!$C$8 -> 221236.67 | ... Q14: =(PREMISSAS!$C$30-'CUSTOS BERTIOGA'!$H$22-'CUSTOS SANTOS'!$H$23-'CUSTOS BERTIOGA'!$F$26-'CUSTOS SANTOS'!$F$27-'CUSTOS BERTIOGA'!$F$34-'CUSTOS SANTOS'!$F$35)*AUX!Q$9/PREMISSAS!$C$8 -> 0 | R14: =SUM(C14:Q14) -> 2490696.7
B15: (–) Custos indiretos | C15: =('CUSTOS BERTIOGA'!$F$34+'CUSTOS SANTOS'!$F$35)*AUX!C$9/PREMISSAS!$C$8 -> 20000 | D15: =('CUSTOS BERTIOGA'!$F$34+'CUSTOS SANTOS'!$F$35)*AUX!D$9/PREMISSAS!$C$8 -> 40000 | E15: =('CUSTOS BERTIOGA'!$F$34+'CUSTOS SANTOS'!$F$35)*AUX!E$9/PREMISSAS!$C$8 -> 41333.333 | F15: =('CUSTOS BERTIOGA'!$F$34+'CUSTOS SANTOS'!$F$35)*AUX!F$9/PREMISSAS!$C$8 -> 40000 | G15: =('CUSTOS BERTIOGA'!$F$34+'CUSTOS SANTOS'!$F$35)*AUX!G$9/PREMISSAS!$C$8 -> 41333.333 | H15: =('CUSTOS BERTIOGA'!$F$34+'CUSTOS SANTOS'!$F$35)*AUX!H$9/PREMISSAS!$C$8 -> 41333.333 | I15: =('CUSTOS BERTIOGA'!$F$34+'CUSTOS SANTOS'!$F$35)*AUX!I$9/PREMISSAS!$C$8 -> 37333.333 | J15: =('CUSTOS BERTIOGA'!$F$34+'CUSTOS SANTOS'!$F$35)*AUX!J$9/PREMISSAS!$C$8 -> 41333.333 | ... Q15: =('CUSTOS BERTIOGA'!$F$34+'CUSTOS SANTOS'!$F$35)*AUX!Q$9/PREMISSAS!$C$8 -> 0 | R15: =SUM(C15:Q15) -> 465333.33
B16: (–) Mobilização / custos iniciais | C16: =IF(C$5=DATE(YEAR(PREMISSAS!$C$6),MONTH(PREMISSAS!$C$6),1),PREMISSAS!$C$35,0) -> 26720 | D16: =IF(D$5=DATE(YEAR(PREMISSAS!$C$6),MONTH(PREMISSAS!$C$6),1),PREMISSAS!$C$35,0) -> 0 | E16: =IF(E$5=DATE(YEAR(PREMISSAS!$C$6),MONTH(PREMISSAS!$C$6),1),PREMISSAS!$C$35,0) -> 0 | F16: =IF(F$5=DATE(YEAR(PREMISSAS!$C$6),MONTH(PREMISSAS!$C$6),1),PREMISSAS!$C$35,0) -> 0 | G16: =IF(G$5=DATE(YEAR(PREMISSAS!$C$6),MONTH(PREMISSAS!$C$6),1),PREMISSAS!$C$35,0) -> 0 | H16: =IF(H$5=DATE(YEAR(PREMISSAS!$C$6),MONTH(PREMISSAS!$C$6),1),PREMISSAS!$C$35,0) -> 0 | I16: =IF(I$5=DATE(YEAR(PREMISSAS!$C$6),MONTH(PREMISSAS!$C$6),1),PREMISSAS!$C$35,0) -> 0 | J16: =IF(J$5=DATE(YEAR(PREMISSAS!$C$6),MONTH(PREMISSAS!$C$6),1),PREMISSAS!$C$35,0) -> 0 | ... Q16: =IF(Q$5=DATE(YEAR(PREMISSAS!$C$6),MONTH(PREMISSAS!$C$6),1),PREMISSAS!$C$35,0) -> 0 | R16: =SUM(C16:Q16) -> 26720
B17: (=) RESULTADO ECONÔMICO DO MÊS | C17: =C11-C12-C13-C14-C15-C16 -> -138227.95 | D17: =D11-D12-D13-D14-D15-D16 -> 202741.73 | E17: =E11-E12-E13-E14-E15-E16 -> 185846.58 | F17: =F11-F12-F13-F14-F15-F16 -> 101370.86 | G17: =G11-G12-G13-G14-G15-G16 -> 104749.89 | H17: =H11-H12-H13-H14-H15-H16 -> 104749.89 | I17: =I11-I12-I13-I14-I15-I16 -> 94612.806 | J17: =J11-J12-J13-J14-J15-J16 -> 104749.89 | ... Q17: =Q11-Q12-Q13-Q14-Q15-Q16 -> 0 | R17: =SUM(C17:Q17) -> 1172835.2
B18: RESULTADO ACUMULADO | C18: =C17 -> -138227.95 | D18: =C18+D17 -> 64513.778 | E18: =D18+E17 -> 250360.36 | F18: =E18+F17 -> 351731.23 | G18: =F18+G17 -> 456481.12 | H18: =G18+H17 -> 561231.01 | I18: =H18+I17 -> 655843.82 | J18: =I18+J17 -> 760593.71 | K18: =J18+K17 -> 861964.57 | ... Q18: =P18+Q17 -> 1172835.2 | R18: =Q18 -> 1172835.2
B19: Margem do mês (% da medição) | C19: =IFERROR(C17/C9,0) -> -0.75971253 | D19: =IFERROR(D17/D9,0) -> 0.22285714 | E19: =IFERROR(E17/E9,0) -> 0.20428571 | F19: =IFERROR(F17/F9,0) -> 0.13 | G19: =IFERROR(G17/G9,0) -> 0.13 | H19: =IFERROR(H17/H9,0) -> 0.13 | I19: =IFERROR(I17/I9,0) -> 0.13 | J19: =IFERROR(J17/J9,0) -> 0.13 | ... R19: =IFERROR(R17/R9,0) -> 0.12892004
B21: RESUMO
B22: Resultado econômico do contrato no horizonte | C22: =R17 -> 1172835.2
B23: Margem sobre a medição | C23: =R19 -> 0.12892004
B24: O resultado econômico e o resultado de caixa do FCP MENSAL fecham no mesmo número no fim do horizonte. No dia a dia eles diferem: o consórcio financia folha/estrutura e desconta da medição; a WCR só gira os indiretos.

Sheet VIABILIDADE
B2: VIABILIDADE — produção necessária por cenário
B3: MÍNIMA = empate real: cobre custo + imposto da nota. Sua planilha anterior não descontava o imposto — a linha cinza mostra aquela referência.
B4: BERTIOGA
B5: Custo mensal: | C5: =PREMISSAS!$C$28 -> 237292.84 | E5: Ticket médio: | F5: =PREMISSAS!$C$21 -> 881.2
B6: CENÁRIO | C6: MARGEM | D6: RECEITA LÍQUIDA /MÊS | E6: MEDIÇÃO BRUTA /MÊS | F6: SERVIÇOS /MÊS | G6: SERVIÇOS /SEMANA | H6: SERVIÇOS /DIA
B7: MÍNIMA | C7: =PREMISSAS!C14 -> 0 | D7: =PREMISSAS!$C$28*(1+C7) -> 237292.84 | E7: =D7/(1-PREMISSAS!$C$10) -> 304221.59 | F7: =E7/PREMISSAS!$C$21 -> 345.23558 | G7: =F7*7/PREMISSAS!$C$8 -> 80.554968 | H7: =F7/PREMISSAS!$C$8 -> 11.507853 | I7: =IF(B7=PREMISSAS!$C$13,"◀ adotado","")
B8: MÉDIA | C8: =PREMISSAS!C15 -> 0.1 | D8: =PREMISSAS!$C$28*(1+C8) -> 261022.12 | E8: =D8/(1-PREMISSAS!$C$10) -> 334643.75 | F8: =E8/PREMISSAS!$C$21 -> 379.75913 | G8: =F8*7/PREMISSAS!$C$8 -> 88.610465 | H8: =F8/PREMISSAS!$C$8 -> 12.658638 | I8: =IF(B8=PREMISSAS!$C$13,"◀ adotado","")
B9: BOA | C9: =PREMISSAS!C16 -> 0.15 | D9: =PREMISSAS!$C$28*(1+C9) -> 272886.77 | E9: =D9/(1-PREMISSAS!$C$10) -> 349854.83 | F9: =E9/PREMISSAS!$C$21 -> 397.02091 | G9: =F9*7/PREMISSAS!$C$8 -> 92.638213 | H9: =F9/PREMISSAS!$C$8 -> 13.23403 | I9: =IF(B9=PREMISSAS!$C$13,"◀ adotado","")
B10: ÓTIMA | C10: =PREMISSAS!C17 -> 0.2 | D10: =PREMISSAS!$C$28*(1+C10) -> 284751.41 | E10: =D10/(1-PREMISSAS!$C$10) -> 365065.91 | F10: =E10/PREMISSAS!$C$21 -> 414.28269 | G10: =F10*7/PREMISSAS!$C$8 -> 96.665961 | H10: =F10/PREMISSAS!$C$8 -> 13.809423 | I10: =IF(B10=PREMISSAS!$C$13,"◀ adotado","") -> ◀ adotado
B11: Referência: mínima da sua planilha anterior (sem imposto) | F11: =PREMISSAS!$C$28/PREMISSAS!$C$21 -> 269.28375 | G11: =F11*7/PREMISSAS!$C$8 -> 62.832875 | H11: =F11/PREMISSAS!$C$8 -> 8.976125
B13: SANTOS (mix água/esgoto da premissa)
B14: Custo mensal: | C14: =PREMISSAS!$C$29 -> 269561.48 | E14: Ticket médio: | F14: =PREMISSAS!$C$25 -> 1338.825
B15: CENÁRIO | C15: MARGEM | D15: RECEITA LÍQUIDA /MÊS | E15: MEDIÇÃO BRUTA /MÊS | F15: SERVIÇOS /MÊS | G15: SERVIÇOS /SEMANA | H15: SERVIÇOS /DIA | J15: ÁGUA /DIA | K15: ESGOTO /DIA
B16: MÍNIMA | C16: =PREMISSAS!C14 -> 0 | D16: =PREMISSAS!$C$29*(1+C16) -> 269561.48 | E16: =D16/(1-PREMISSAS!$C$10) -> 345591.64 | F16: =E16/PREMISSAS!$C$25 -> 258.13056 | G16: =F16*7/PREMISSAS!$C$8 -> 60.230463 | H16: =F16/PREMISSAS!$C$8 -> 8.6043519 | I16: =IF(B16=PREMISSAS!$C$13,"◀ adotado","") | J16: =H16*(1-PREMISSAS!$C$24) -> 4.3021759 | K16: =H16*PREMISSAS!$C$24 -> 4.3021759
B17: MÉDIA | C17: =PREMISSAS!C15 -> 0.1 | D17: =PREMISSAS!$C$29*(1+C17) -> 296517.63 | E17: =D17/(1-PREMISSAS!$C$10) -> 380150.81 | F17: =E17/PREMISSAS!$C$25 -> 283.94361 | G17: =F17*7/PREMISSAS!$C$8 -> 66.253509 | H17: =F17/PREMISSAS!$C$8 -> 9.464787 | I17: =IF(B17=PREMISSAS!$C$13,"◀ adotado","") | J17: =H17*(1-PREMISSAS!$C$24) -> 4.7323935 | K17: =H17*PREMISSAS!$C$24 -> 4.7323935
B18: BOA | C18: =PREMISSAS!C16 -> 0.15 | D18: =PREMISSAS!$C$29*(1+C18) -> 309995.7 | E18: =D18/(1-PREMISSAS!$C$10) -> 397430.39 | F18: =E18/PREMISSAS!$C$25 -> 296.85014 | G18: =F18*7/PREMISSAS!$C$8 -> 69.265032 | H18: =F18/PREMISSAS!$C$8 -> 9.8950046 | I18: =IF(B18=PREMISSAS!$C$13,"◀ adotado","") | J18: =H18*(1-PREMISSAS!$C$24) -> 4.9475023 | K18: =H18*PREMISSAS!$C$24 -> 4.9475023
B19: ÓTIMA | C19: =PREMISSAS!C17 -> 0.2 | D19: =PREMISSAS!$C$29*(1+C19) -> 323473.78 | E19: =D19/(1-PREMISSAS!$C$10) -> 414709.97 | F19: =E19/PREMISSAS!$C$25 -> 309.75667 | G19: =F19*7/PREMISSAS!$C$8 -> 72.276556 | H19: =F19/PREMISSAS!$C$8 -> 10.325222 | I19: =IF(B19=PREMISSAS!$C$13,"◀ adotado","") -> ◀ adotado | J19: =H19*(1-PREMISSAS!$C$24) -> 5.1626111 | K19: =H19*PREMISSAS!$C$24 -> 5.1626111
B20: Referência antiga (sem imposto) — se fosse SÓ ÁGUA | F20: =PREMISSAS!$C$29/PREMISSAS!$C$22 -> 328.23316 | G20: =F20*7/PREMISSAS!$C$8 -> 76.587737 | H20: =F20/PREMISSAS!$C$8 -> 10.941105
B21: Referência antiga (sem imposto) — se fosse SÓ ESGOTO | F21: =PREMISSAS!$C$29/PREMISSAS!$C$23 -> 145.20657 | G21: =F21*7/PREMISSAS!$C$8 -> 33.881533 | H21: =F21/PREMISSAS!$C$8 -> 4.8402191
B22: GLOBAL — BERTIOGA + SANTOS (em R$)
B23: CENÁRIO | C23: MARGEM | D23: RECEITA LÍQUIDA /MÊS | E23: MEDIÇÃO BRUTA /MÊS
B24: MÍNIMA | C24: =PREMISSAS!C14 -> 0 | D24: =PREMISSAS!$C$30*(1+C24) -> 506854.32 | E24: =D24/(1-PREMISSAS!$C$10) -> 649813.23 | F24: =IF(B24=PREMISSAS!$C$13,"◀ adotado","")
B25: MÉDIA | C25: =PREMISSAS!C15 -> 0.1 | D25: =PREMISSAS!$C$30*(1+C25) -> 557539.75 | E25: =D25/(1-PREMISSAS!$C$10) -> 714794.55 | F25: =IF(B25=PREMISSAS!$C$13,"◀ adotado","")
B26: BOA | C26: =PREMISSAS!C16 -> 0.15 | D26: =PREMISSAS!$C$30*(1+C26) -> 582882.47 | E26: =D26/(1-PREMISSAS!$C$10) -> 747285.22 | F26: =IF(B26=PREMISSAS!$C$13,"◀ adotado","")
B27: ÓTIMA | C27: =PREMISSAS!C17 -> 0.2 | D27: =PREMISSAS!$C$30*(1+C27) -> 608225.18 | E27: =D27/(1-PREMISSAS!$C$10) -> 779775.88 | F27: =IF(B27=PREMISSAS!$C$13,"◀ adotado","") -> ◀ adotado
B29: Produção em unidades não soma entre cidades (tickets diferentes) — acompanhe unidades por cidade, R$ no global.

Sheet CUSTOS BERTIOGA
B2: CUSTOS — BERTIOGA
B3: Fonte: Fluxo Trimestral Obra.xlsx · aba Custos (18/08/2026) — edite os valores em azul
B5: EQUIPE — QUADRO NOMINAL
B6: EQUIPE | C6: NOME | D6: CARGO | E6: SALÁRIO | F6: ENCARGOS | G6: BENEFÍCIOS | H6: TOTAL / MÊS
B7: A | C7: Lenildo Lourenco da Silva | D7: Ajudante Geral | E7: 2951 | F7: 1712 | G7: 1679 | H7: =E7+F7+G7 -> 6342
B8: A | C8: Edivan dos Santos | D8: Encanador Motorizado | E8: 3932 | F8: 2281 | G8: 1679 | H8: =E8+F8+G8 -> 7892
B9: A | C9: Marcelo dos Santos Marciano | D9: Ajudante Geral | E9: 2951 | F9: 1712 | G9: 1679 | H9: =E9+F9+G9 -> 6342
B10: B | C10: Junior Sabino | D10: Lider de Equipe | E10: 3908 | F10: 2267 | G10: 1679 | H10: =E10+F10+G10 -> 7854
B11: B | C11: Bruno Carvalho Dias | D11: Ajudante Geral | E11: 2951 | F11: 1712 | G11: 1679 | H11: =E11+F11+G11 -> 6342
B12: B | C12: Jerailson Lourenco Santos da S | D12: Encanador | E12: 3633 | F12: 2107 | G12: 1679 | H12: =E12+F12+G12 -> 7419
B13: C | C13: Egmar de Almeida Pinto | D13: Ajudante Geral | E13: 2951 | F13: 1712 | G13: 1679 | H13: =E13+F13+G13 -> 6342
B14: C | C14: Oziel | D14: Encanador | E14: 3633 | F14: 2107 | G14: 1679 | H14: =E14+F14+G14 -> 7419
B15: C | C15: Rafael Nunes de Godoy | D15: Ajudante Geral | E15: 2951 | F15: 1712 | G15: 1679 | H15: =E15+F15+G15 -> 6342
B16: C | C16: Rafael Santos Cruz | D16: Operador de Retroescavadeira | E16: 3947 | F16: 2289 | G16: 1679 | H16: =E16+F16+G16 -> 7915
B17: D | C17: Jose Henrique | D17: Ajudante Geral | E17: 2951 | F17: 1712 | G17: 1679 | H17: =E17+F17+G17 -> 6342
B18: D | C18: Arnaldo de Araujo Bastos | D18: Encanador Motorizado | E18: 3932 | F18: 2281 | G18: 1679 | H18: =E18+F18+G18 -> 7892
B19: D | C19: Kaique Tavares da Silva | D19: Encanador | E19: 3633 | F19: 2107 | G19: 1679 | H19: =E19+F19+G19 -> 7419
B20: — | D20: Programador | E20: 2548 | F20: 1477.84 | G20: 1679 | H20: =E20+F20+G20 -> 5704.84
B21: — | C21: Sergio Rodrigues da Silva | D21: Encarregado de Obras | E21: 4713 | F21: 2734 | G21: 1679 | H21: =E21+F21+G21 -> 9126
B22: TOTAL | C22: 15 pessoas | E22: =SUM(E7:E21) -> 51585 | F22: =SUM(F7:F21) -> 29922.84 | G22: =SUM(G7:G21) -> 25185 | H22: =SUM(H7:H21) -> 106692.84
B24: CUSTOS GERAIS DA OBRA (R$/MÊS)
B25: ITEM | D25: QNT | E25: VALOR UNIT. | F25: TOTAL MÊS
B26: Salário engenheiro | D26: 1 | E26: 13000 | F26: =D26*E26 -> 13000
B27: Kit ferramenta equipes | D27: 4 | E27: 7200 | F27: =D27*E27 -> 28800 | H27: mantido como custo mensal, igual à sua planilha
B28: Carro engenheiro | D28: 1 | E28: 3400 | F28: =D28*E28 -> 3400
B29: Carro encarregado | D29: 1 | E29: 3500 | F29: =D29*E29 -> 3500
B30: Caminhão 3/4 + munck | D30: 1 | E30: 25000 | F30: =D30*E30 -> 25000
B31: HR CAMINHÃO TIPO HR | D31: 3 | E31: 3500 | F31: =D31*E31 -> 10500
B32: Alojamento | D32: 1 | E32: 13500 | F32: =D32*E32 -> 13500
B33: Equipamentos leves | D33: 1 | E33: 12900 | F33: =D33*E33 -> 12900
B34: Custos indiretos | D34: 1 | E34: 20000 | F34: =D34*E34 -> 20000
B35: Equipe (folha + encargos + benefícios) | D35: 1 | E35: =H22 -> 106692.84 | F35: =D35*E35 -> 106692.84
B36: TOTAL MENSAL — BERTIOGA | F36: =SUM(F26:F35) -> 237292.84
B38: TOTAL SEMANAL (7 dias) | F38: =F36*7/PREMISSAS!$C$8 -> 55368.329
B39: TOTAL QUINZENAL (15 dias) | F39: =F36/2 -> 118646.42
B40: TOTAL DIÁRIO | F40: =F36/PREMISSAS!$C$8 -> 7909.7613

Sheet CUSTOS SANTOS
B2: CUSTOS — SANTOS
B3: Fonte: Fluxo Trimestral Obra.xlsx · aba Custos (18/08/2026) — edite os valores em azul
B5: EQUIPE — QUADRO NOMINAL
B6: EQUIPE | C6: NOME | D6: CARGO | E6: SALÁRIO | F6: ENCARGOS | G6: BENEFÍCIOS | H6: TOTAL / MÊS
B7: A | C7: Ricardo Dantas da Silva Junior | D7: Ajudante Geral | E7: 2951 | F7: 1712 | G7: 1679 | H7: =E7+F7+G7 -> 6342
B8: A | C8: Jean Estevam de Oliveira | D8: Encanador Motorizado | E8: 3932 | F8: 2281 | G8: 1679 | H8: =E8+F8+G8 -> 7892
B9: A | C9: Renato Santos Araujo | D9: Pedreiro | E9: 3633 | F9: 2107 | G9: 1679 | H9: =E9+F9+G9 -> 7419
B10: B | C10: Paulo Alberto da Silva de Paula | D10: Pedreiro | E10: 3633 | F10: 2107 | G10: 1679 | H10: =E10+F10+G10 -> 7419
B11: B | C11: Kaua dos Santos Nunes Rodrigues | D11: Ajudante Geral | E11: 2951 | F11: 1712 | G11: 1679 | H11: =E11+F11+G11 -> 6342
B12: B | C12: Marcelo da Silva Nogueira | D12: Encanador Motorizado | E12: 3932 | F12: 2281 | G12: 1679 | H12: =E12+F12+G12 -> 7892
B13: C | C13: Jeferson Silva de Paiva | D13: Encanador | E13: 3633 | F13: 2107 | G13: 1679 | H13: =E13+F13+G13 -> 7419
B14: C | C14: Danilo Fernando Salgado | D14: Pedreiro Motorizado | E14: 3932 | F14: 2281 | G14: 1679 | H14: =E14+F14+G14 -> 7892
B15: C | C15: Rian Teixeira da Silva | D15: Ajudante Geral | E15: 2951 | F15: 1712 | G15: 1679 | H15: =E15+F15+G15 -> 6342
B16: C | C16: Rogério Soares da Silva | D16: Operador de Retroescavadeira | E16: 4979 | F16: 2887.82 | G16: 1679 | H16: =E16+F16+G16 -> 9545.82
B17: D | C17: Hernandes Araújo de Oliveira | D17: Encanador | E17: 3633 | F17: 2107 | G17: 1679 | H17: =E17+F17+G17 -> 7419
B18: D | C18: Alex | D18: Encanador | E18: 3633 | F18: 2107 | G18: 1679 | H18: =E18+F18+G18 -> 7419
... B22: — | C22: Sidnei Jose dos Santos | D22: Encarregado de Obras | E22: 4713 | F22: 2734 | G22: 1679 | H22: =E22+F22+G22 -> 9126
B23: TOTAL | C23: 16 pessoas | E23: =SUM(E7:E22) -> 58984 | F23: =SUM(F7:F22) -> 34213.48 | G23: =SUM(G7:G22) -> 26864 | H23: =SUM(H7:H22) -> 120061.48
B25: CUSTOS GERAIS DA OBRA (R$/MÊS)
B26: ITEM | D26: QNT | E26: VALOR UNIT. | F26: TOTAL MÊS
B27: Salário engenheiro | D27: 1 | E27: 13000 | F27: =D27*E27 -> 13000
B28: Kit ferramenta equipes | D28: 4 | E28: 7200 | F28: =D28*E28 -> 28800 | H28: mantido como custo mensal, igual à sua planilha
B29: Carro engenheiro | D29: 1 | E29: 3400 | F29: =D29*E29 -> 3400
B30: Carro encarregado | D30: 1 | E30: 3400 | F30: =D30*E30 -> 3400
B31: Caminhão 3/4 + munck | D31: 2 | E31: 25000 | F31: =D31*E31 -> 50000
B32: HR (horas de máquina) | D32: 2 | E32: 6000 | F32: =D32*E32 -> 12000
B33: Alojamento | D33: 1 | E33: 6000 | F33: =D33*E33 -> 6000
B34: Equipamentos leves | D34: 1 | E34: 12900 | F34: =D34*E34 -> 12900
B35: Custos indiretos | D35: 1 | E35: 20000 | F35: =D35*E35 -> 20000
B36: Equipe (folha + encargos + benefícios) | D36: 1 | E36: =H23 -> 120061.48 | F36: =D36*E36 -> 120061.48
B37: TOTAL MENSAL — SANTOS | F37: =SUM(F27:F36) -> 269561.48
B39: TOTAL SEMANAL (7 dias) | F39: =F37*7/PREMISSAS!$C$8 -> 62897.679
B40: TOTAL QUINZENAL (15 dias) | F40: =F37/2 -> 134780.74
B41: TOTAL DIÁRIO | F41: =F37/PREMISSAS!$C$8 -> 8985.3827

Sheet AUX
B2: AUX — medições, datas de pagamento e cenários (cálculo; não precisa editar)
B3: Mês (1º dia) | C3: =DATE(YEAR(PREMISSAS!$C$6),MONTH(PREMISSAS!$C$6),1) -> 46235 | D3: =EDATE(C3,1) -> 46266 | E3: =EDATE(D3,1) -> 46296 | F3: =EDATE(E3,1) -> 46327 | G3: =EDATE(F3,1) -> 46357 | H3: =EDATE(G3,1) -> 46388 | I3: =EDATE(H3,1) -> 46419 | J3: =EDATE(I3,1) -> 46447 | K3: =EDATE(J3,1) -> 46478 | ... Q3: =EDATE(P3,1) -> 46661
B4: Dias de obra no mês | C4: =MAX(0,MIN(EOMONTH(C3,0),PREMISSAS!$C$7)-MAX(C3,PREMISSAS!$C$6)+1) -> 8 | D4: =MAX(0,MIN(EOMONTH(D3,0),PREMISSAS!$C$7)-MAX(D3,PREMISSAS!$C$6)+1) -> 30 | E4: =MAX(0,MIN(EOMONTH(E3,0),PREMISSAS!$C$7)-MAX(E3,PREMISSAS!$C$6)+1) -> 31 | F4: =MAX(0,MIN(EOMONTH(F3,0),PREMISSAS!$C$7)-MAX(F3,PREMISSAS!$C$6)+1) -> 30 | G4: =MAX(0,MIN(EOMONTH(G3,0),PREMISSAS!$C$7)-MAX(G3,PREMISSAS!$C$6)+1) -> 31 | H4: =MAX(0,MIN(EOMONTH(H3,0),PREMISSAS!$C$7)-MAX(H3,PREMISSAS!$C$6)+1) -> 31 | I4: =MAX(0,MIN(EOMONTH(I3,0),PREMISSAS!$C$7)-MAX(I3,PREMISSAS!$C$6)+1) -> 28 | J4: =MAX(0,MIN(EOMONTH(J3,0),PREMISSAS!$C$7)-MAX(J3,PREMISSAS!$C$6)+1) -> 31 | ... Q4: =MAX(0,MIN(EOMONTH(Q3,0),PREMISSAS!$C$7)-MAX(Q3,PREMISSAS!$C$6)+1) -> 0
